{
 "cells": [
  {
   "cell_type": "code",
   "execution_count": 17,
   "metadata": {},
   "outputs": [
    {
     "name": "stdout",
     "output_type": "stream",
     "text": [
      "{   'address': 8081,\n",
      "    'aiohttp_settings': {'client_max_size': 20971520},\n",
      "    'applications': [   'guillotina_swagger',\n",
      "                        'guillotina_cms',\n",
      "                        'guillotina_dbusers',\n",
      "                        'guillotina_elasticsearch',\n",
      "                        'guillotina_rediscache',\n",
      "                        'guillotina_processing'],\n",
      "    'auth_extractors': [   'guillotina.auth.extractors.CookiePolicy',\n",
      "                           'guillotina.auth.extractors.BearerAuthPolicy',\n",
      "                           'guillotina.auth.extractors.BasicAuthPolicy',\n",
      "                           'guillotina.auth.extractors.WSTokenAuthPolicy'],\n",
      "    'auth_token_validators': [   'guillotina.auth.validators.SaltedHashPasswordValidator',\n",
      "                                 'guillotina.auth.validators.JWTValidator'],\n",
      "    'cors': {   'allow_credentials': True,\n",
      "                'allow_headers': ['*'],\n",
      "                'allow_methods': [   'GET',\n",
      "                                     'POST',\n",
      "                                     'DELETE',\n",
      "                                     'HEAD',\n",
      "                                     'PATCH',\n",
      "                                     'OPTIONS'],\n",
      "                'allow_origin': ['*'],\n",
      "                'expose_headers': ['*'],\n",
      "                'max_age': 3660},\n",
      "    'databases': [   {   'db': {   'dsn': 'postgresql://postgres:secret@192.168.130.119:5432/guillotina',\n",
      "                                   'pool_size': 100,\n",
      "                                   'read_only': False,\n",
      "                                   'storage': 'postgresql',\n",
      "                                   'transaction_strategy': 'dbresolve_readcommitted'}}],\n",
      "    'elasticsearch': {   'bulk_size': 20,\n",
      "                         'connection_settings': {   'hosts': [   '192.168.130.119:9200'],\n",
      "                                                    'sniffer_timeout': 0.5},\n",
      "                         'index': {},\n",
      "                         'index_name_prefix': 'plone-',\n",
      "                         'mapping_overrides': {'*': {}}},\n",
      "    'jsapps': {'+admin': 'guillotina:static/executioner'},\n",
      "    'jwt': {'algorithm': 'HS256', 'secret': 'secret'},\n",
      "    'redis': {'host': '192.168.130.119', 'port': 6379},\n",
      "    'root_user': {'password': 'root'},\n",
      "    'static': [{'swagger_static': 'guillotina_swagger:static'}],\n",
      "    'utilities': [   {   'factory': 'guillotina.async_util.QueueUtility',\n",
      "                         'provides': 'guillotina.async_util.IQueueUtility',\n",
      "                         'settings': {}},\n",
      "                     {   'factory': 'guillotina_cms.utilities.workflow.WorkflowUtility',\n",
      "                         'provides': 'guillotina_cms.interfaces.IWorkflowUtility',\n",
      "                         'settings': {}},\n",
      "                     {   'factory': 'guillotina_cms.utilities.pubsub.PubSubUtility',\n",
      "                         'provides': 'guillotina_cms.interfaces.IPubSubUtility',\n",
      "                         'settings': {}}]}\n"
     ]
    }
   ],
   "source": [
    "import yaml\n",
    "import pprint\n",
    "pp = pprint.PrettyPrinter(indent=4)\n",
    "with open('../config.yaml', 'r') as f:\n",
    "    config = yaml.load(f)\n",
    "config['applications'].append('guillotina_processing')\n",
    "pp.pprint(config)"
   ]
  },
  {
   "cell_type": "code",
   "execution_count": 18,
   "metadata": {},
   "outputs": [],
   "source": [
    "from guillotina.factory import make_app\n",
    "\n",
    "app = await make_app(settings=config)"
   ]
  },
  {
   "cell_type": "code",
   "execution_count": 19,
   "metadata": {},
   "outputs": [],
   "source": [
    "root = app.root\n",
    "db = await root.get('db')\n",
    "from guillotina.contentapi import ContentAPI\n",
    "\n",
    "async with ContentAPI(db) as api:\n",
    "    folder = await api.get('cms/articles')"
   ]
  },
  {
   "cell_type": "code",
   "execution_count": 22,
   "metadata": {},
   "outputs": [
    {
     "data": {
      "text/plain": [
       "2579"
      ]
     },
     "execution_count": 22,
     "metadata": {},
     "output_type": "execute_result"
    }
   ],
   "source": [
    "await folder.async_len()"
   ]
  },
  {
   "cell_type": "code",
   "execution_count": 23,
   "metadata": {},
   "outputs": [
    {
     "name": "stdout",
     "output_type": "stream",
     "text": [
      "2579 articles\r"
     ]
    }
   ],
   "source": [
    "import sys\n",
    "i = 0\n",
    "async for article in folder.async_values():\n",
    "    i += 1\n",
    "    print('{} articles'.format(i), end='\\r')\n",
    "    sys.stdout.flush()"
   ]
  },
  {
   "cell_type": "code",
   "execution_count": 24,
   "metadata": {},
   "outputs": [],
   "source": [
    "import tensorflow as tf\n",
    "import tensorflow_hub as hub\n",
    "import matplotlib.pyplot as plt\n",
    "import numpy as np\n",
    "import os\n",
    "import pandas as pd\n",
    "import re\n",
    "import seaborn as sns"
   ]
  },
  {
   "cell_type": "code",
   "execution_count": 25,
   "metadata": {},
   "outputs": [
    {
     "name": "stdout",
     "output_type": "stream",
     "text": [
      "['sports', 'business']\n"
     ]
    }
   ],
   "source": [
    "from guillotina_processing.utils import get_index_values\n",
    "async with ContentAPI(db) as api:\n",
    "    container = await api.get('cms')\n",
    "    labels = await get_index_values('tags', container)\n",
    "    print(labels)\n"
   ]
  },
  {
   "cell_type": "code",
   "execution_count": 26,
   "metadata": {},
   "outputs": [
    {
     "data": {
      "text/plain": [
       "10004"
      ]
     },
     "execution_count": 26,
     "metadata": {},
     "output_type": "execute_result"
    }
   ],
   "source": [
    "# Calculate Vocabulary\n",
    "from guillotina_processing.vocabulary import build_vocabulary\n",
    "\n",
    "search_dict = {'type_name': 'Document', 'path__starts': 'articles'}\n",
    "async with ContentAPI(db) as api:\n",
    "    container = await api.get('cms')\n",
    "    vocabulary = await build_vocabulary('testing', container, container=container, search=search_dict, max_words=10000)\n",
    "len(vocabulary.dictionary)"
   ]
  },
  {
   "cell_type": "code",
   "execution_count": 27,
   "metadata": {},
   "outputs": [],
   "source": [
    "from guillotina_processing.keras.generator import DataTextGenerator\n",
    "from guillotina_processing.interfaces import IIteratorSearch\n",
    "\n",
    "async with ContentAPI(db) as api:\n",
    "    list_ids = []\n",
    "    iterator = IIteratorSearch(container)\n",
    "    iterator.set_container(container)\n",
    "    iterator.set_search(search_dict)\n",
    "    async for id_ in iterator(ids=True):\n",
    "        list_ids.append(id_)\n",
    "\n",
    "# Parameters\n",
    "params = {'dim': 256,\n",
    "          'batch_size': 64,\n",
    "          'n_classes': len(labels),\n",
    "          'shuffle': True}\n",
    "\n",
    "ids = np.array(list_ids)\n",
    "np.random.shuffle(ids)\n",
    "training_count = int(len(ids)*0.9)\n",
    "training, test = ids[:training_count], ids[training_count:]\n",
    "\n",
    "training_generator = DataTextGenerator(training, labels, vocabulary, **params)\n",
    "validation_generator = DataTextGenerator(test, labels, vocabulary, **params)\n"
   ]
  },
  {
   "cell_type": "code",
   "execution_count": 28,
   "metadata": {},
   "outputs": [
    {
     "data": {
      "text/plain": [
       "(258, 2, 2579)"
      ]
     },
     "execution_count": 28,
     "metadata": {},
     "output_type": "execute_result"
    }
   ],
   "source": [
    "len(test), len(labels), len(list_ids)"
   ]
  },
  {
   "cell_type": "code",
   "execution_count": 29,
   "metadata": {},
   "outputs": [
    {
     "name": "stdout",
     "output_type": "stream",
     "text": [
      "_________________________________________________________________\n",
      "Layer (type)                 Output Shape              Param #   \n",
      "=================================================================\n",
      "embedding_1 (Embedding)      (None, None, 8)           80032     \n",
      "_________________________________________________________________\n",
      "global_average_pooling1d_1 ( (None, 8)                 0         \n",
      "_________________________________________________________________\n",
      "dense_2 (Dense)              (None, 16)                144       \n",
      "_________________________________________________________________\n",
      "dense_3 (Dense)              (None, 2)                 34        \n",
      "=================================================================\n",
      "Total params: 80,210\n",
      "Trainable params: 80,210\n",
      "Non-trainable params: 0\n",
      "_________________________________________________________________\n"
     ]
    }
   ],
   "source": [
    "# input shape is the vocabulary count used for the movie reviews (10,000 words)\n",
    "from tensorflow import keras\n",
    "\n",
    "vocab_size = len(vocabulary.dictionary)\n",
    "\n",
    "model = keras.Sequential()\n",
    "model.add(keras.layers.Embedding(vocab_size, 8))\n",
    "model.add(keras.layers.GlobalAveragePooling1D())\n",
    "model.add(keras.layers.Dense(16, activation=tf.nn.relu))\n",
    "model.add(keras.layers.Dense(2, activation=tf.nn.sigmoid))\n",
    "\n",
    "model.summary()\n",
    "    \n",
    "model.compile(optimizer=tf.train.AdamOptimizer(),\n",
    "              loss='binary_crossentropy',\n",
    "              metrics=['accuracy'])\n"
   ]
  },
  {
   "cell_type": "code",
   "execution_count": 30,
   "metadata": {},
   "outputs": [
    {
     "name": "stdout",
     "output_type": "stream",
     "text": [
      "Epoch 1/2\n",
      "4/4 [==============================] - 2s 399ms/steposs: 0.6909 - acc: \n",
      "36/36 [==============================] - 16s 441ms/step - loss: 0.6907 - acc: 0.5297 - val_loss: 0.7015 - val_acc: 0.4238\n",
      "Epoch 2/2\n",
      "4/4 [==============================] - 1s 372ms/steposs: 0.6800 - acc: \n",
      "36/36 [==============================] - 16s 445ms/step - loss: 0.6800 - acc: 0.5729 - val_loss: 0.7223 - val_acc: 0.3750\n"
     ]
    }
   ],
   "source": [
    "# Train model on dataset\n",
    "from guillotina_processing.keras.training_generator import fit_generator\n",
    "async with ContentAPI(db) as api:\n",
    "    tt = await api.get_transaction()\n",
    "    history = await fit_generator(\n",
    "        model, generator=training_generator,\n",
    "        validation_data=validation_generator,\n",
    "        epochs=2)"
   ]
  },
  {
   "cell_type": "code",
   "execution_count": 31,
   "metadata": {},
   "outputs": [
    {
     "data": {
      "image/png": "iVBORw0KGgoAAAANSUhEUgAAAYsAAAEWCAYAAACXGLsWAAAABHNCSVQICAgIfAhkiAAAAAlwSFlzAAALEgAACxIB0t1+/AAAADl0RVh0U29mdHdhcmUAbWF0cGxvdGxpYiB2ZXJzaW9uIDMuMC4xLCBodHRwOi8vbWF0cGxvdGxpYi5vcmcvDW2N/gAAIABJREFUeJzt3WmYVNW59vH/IzLIICBgVKZGQZknO0BEBAQRUCAQNCA4RSV6nKIxR45DVBISNUYRD8cTkhNNIkp8tUFQEI2giAMyREFABBlbkElGQaHheT+s3QMt9O6Grq4e7t919WXVql1Vz+7Gumvttfba5u6IiIjk5YRkFyAiIsWfwkJERGIpLEREJJbCQkREYiksREQklsJCRERiKSykSJhZOTPbY2YNCnPbZDKzxmZW6HPPzaynma3JcX+5mXXJz7bH8F5/MbN7jvX5ebzub83s2cJ+XUmeE5NdgBRPZrYnx93KwHfAwej+z919QkFez90PAlULe9uywN3PKYzXMbPrgeHu3i3Ha19fGK8tpZ/CQo7I3bM+rKNvrte7+7+Otr2ZnejuGUVRm4gUPR2GkmMSHWb4p5m9YGa7geFm9iMz+9DMdpjZRjMba2blo+1PNDM3s5To/nPR49PNbLeZfWBmjQq6bfR4HzP73Mx2mtlTZvaemV1zlLrzU+PPzWylmW03s7E5nlvOzJ4ws21mtgroncfv514zm5irbZyZPR7dvt7MlkX780X0rf9or5VuZt2i25XN7B9RbUuAc3Nte5+ZrYped4mZ9Y/aWwH/DXSJDvFtzfG7fTDH82+M9n2bmU02s9Pz87uJY2YDo3p2mNlMMzsnx2P3mNkGM9tlZp/l2NdOZrYwat9kZn/I7/tJAri7fvST5w+wBuiZq+23wH6gH+FLx0nAD4GOhB7rmcDnwC3R9icCDqRE958DtgKpQHngn8Bzx7DtqcBuYED02J3AAeCao+xLfmp8BagOpABfZ+47cAuwBKgH1AJmh/+Fjvg+ZwJ7gCo5XnszkBrd7xdtY8CFwD6gdfRYT2BNjtdKB7pFtx8D3gZqAg2Bpbm2vRw4PfqbXBHV8IPoseuBt3PV+RzwYHS7V1RjW6AS8D/AzPz8bo6w/78Fno1uN4vquDD6G90DLI9utwDWAqdF2zYCzoxuzwOGRrerAR2T/f9CWf5Rz0KOxxx3n+ruh9x9n7vPc/e57p7h7quA8UDXPJ7/krvPd/cDwATCh1RBt70U+NjdX4kee4IQLEeUzxp/7+473X0N4YM5870uB55w93R33wY8nMf7rAI+JYQYwEXAdnefHz0+1d1XeTATeAs44iB2LpcDv3X37e6+ltBbyPm+L7r7xuhv8jwh6FPz8boAw4C/uPvH7v4tMBLoamb1cmxztN9NXoYAU9x9ZvQ3epgQOB2BDEIwtYgOZa6OfncQQr+JmdVy993uPjef+yEJoLCQ47E+5x0za2pmr5nZV2a2CxgF1M7j+V/luL2XvAe1j7btGTnrcHcnfBM/onzWmK/3InwjzsvzwNDo9hXR/cw6LjWzuWb2tZntIHyrz+t3len0vGows2vM7JPocM8OoGk+XxfC/mW9nrvvArYDdXNsU5C/2dFe9xDhb1TX3ZcDvyT8HTZHhzVPiza9FmgOLDezj8ysbz73QxJAYSHHI/e00T8Rvk03dveTgV8TDrMk0kbCYSEAzMw4/MMtt+OpcSNQP8f9uKm9LwI9zawuoYfxfFTjScBLwO8Jh4hqAG/ks46vjlaDmZ0JPA3cBNSKXvezHK8bN813A+HQVubrVSMc7voyH3UV5HVPIPzNvgRw9+fcvTPhEFQ5wu8Fd1/u7kMIhxr/CLxsZpWOsxY5RgoLKUzVgJ3AN2bWDPh5Ebznq0B7M+tnZicCtwN1ElTji8AvzKyumdUC7s5rY3f/CpgDPAssd/cV0UMVgQrAFuCgmV0K9ChADfeYWQ0L56HckuOxqoRA2ELIzRsIPYtMm4B6mQP6R/ACcJ2ZtTazioQP7Xfd/ag9tQLU3N/MukXv/SvCONNcM2tmZt2j99sX/Rwi7MCVZlY76onsjPbt0HHWIsdIYSGF6ZfA1YQPgj8RBqITyt03AT8FHge2AWcB/yacF1LYNT5NGFtYTBh8fSkfz3meMGCddQjK3XcAdwCTCIPEgwmhlx8PEHo4a4DpwN9zvO4i4Cngo2ibc4Ccx/nfBFYAm8ws5+GkzOe/TjgcNCl6fgPCOMZxcfclhN/504Qg6w30j8YvKgKPEsaZviL0ZO6NntoXWGZhtt1jwE/dff/x1iPHxsIhXpHSwczKEQ57DHb3d5Ndj0hpoZ6FlHhm1js6LFMRuJ8wi+ajJJclUqooLKQ0OB9YRTjEcTEw0N2PdhhKRI6BDkOJiEgs9SxERCRWqVlIsHbt2p6SkpLsMkRESpQFCxZsdfe8ppsDpSgsUlJSmD9/frLLEBEpUcwsbiUCQIehREQkHxQWIiISS2EhIiKxSs2YxZEcOHCA9PR0vv3222SXIvlQqVIl6tWrR/nyR1u6SESSpVSHRXp6OtWqVSMlJYWwGKkUV+7Otm3bSE9Pp1GjRvFPEJEiVaoPQ3377bfUqlVLQVECmBm1atVSL1CkmCrVYQEoKEoQ/a1Eiq9SfRhKRKQ027YNpk6F/fthxIjEvlep71kk07Zt22jbti1t27bltNNOo27duln39+/P37L81157LcuXL89zm3HjxjFhwoTCKJnzzz+fjz/+uFBeS0QK35dfwrhx0KMH/OAHcO218OyziX9f9SxymDAB7r0X1q2DBg1g9GgYdhyXfqlVq1bWB++DDz5I1apVueuuuw7bxt1xd0444ci5/cwzz8S+z80333zsRYpIsbdyJaSlhZ+50eWsmjWDu++GQYOgffvE16CeRWTChNCNW7sW3MN/R4wI7YVt5cqVNG/enGHDhtGiRQs2btzIiBEjSE1NpUWLFowaNSpr28xv+hkZGdSoUYORI0fSpk0bfvSjH7F582YA7rvvPsaMGZO1/ciRI+nQoQPnnHMO77//PgDffPMNP/nJT2jevDmDBw8mNTU1tgfx3HPP0apVK1q2bMk999wDQEZGBldeeWVW+9ixYwF44oknaN68Oa1bt2b48OGF/jsTKUvc4ZNP4IEHoHVraNIkBENGRvgSu3Rp+Bk9Gs49F4piuE89i8i998LevYe37d0b2o+nd3E0n332GX//+99JTU0F4OGHH+aUU04hIyOD7t27M3jwYJo3b37Yc3bu3EnXrl15+OGHufPOO/nrX//KyJEjv/fa7s5HH33ElClTGDVqFK+//jpPPfUUp512Gi+//DKffPIJ7WO+iqSnp3Pfffcxf/58qlevTs+ePXn11VepU6cOW7duZfHixQDs2LEDgEcffZS1a9dSoUKFrDYRyb9Dh0KvIbMHsWpVCIEuXWDMGPjxj6Fhw+TVp55FZN26grUfr7POOisrKABeeOEF2rdvT/v27Vm2bBlLly793nNOOukk+vTpA8C5557LmjVrjvjagwYN+t42c+bMYciQIQC0adOGFi1a5Fnf3LlzufDCC6lduzbly5fniiuuYPbs2TRu3Jjly5dz2223MWPGDKpXrw5AixYtGD58OBMmTNBJdSL5dOAA/Otf8B//AfXqwXnnwZNPwjnnwPjxsHEjvPMO3H57coMCFBZZGjQoWPvxqlKlStbtFStW8OSTTzJz5kwWLVpE7969j3i+QYUKFbJulytXjoyMjCO+dsWKFWO3OVa1atVi0aJFdOnShXHjxvHzn/8cgBkzZnDjjTcyb948OnTowMGDBwv1fUVKi3374JVX4OqrwwD1RRfB3/4WgmLCBNiyBaZNgxtuCI8XFwqLyOjRULny4W2VK4f2RNu1axfVqlXj5JNPZuPGjcyYMaPQ36Nz5868+OKLACxevPiIPZecOnbsyKxZs9i2bRsZGRlMnDiRrl27smXLFtydyy67jFGjRrFw4UIOHjxIeno6F154IY8++ihbt25lb+5jeiJl2M6d8PzzcNllULt2OKQ0ZQr06weTJ8PWrfDSS3DFFRB11osdjVlEMsclCnM2VH61b9+e5s2b07RpUxo2bEjnzp0L/T1uvfVWrrrqKpo3b571Uz2Pf5X16tXjN7/5Dd26dcPd6devH5dccgkLFy7kuuuuw90xMx555BEyMjK44oor2L17N4cOHeKuu+6iWrVqhb4PIiXJ5s0hENLSwqGmAwfgtNNCj2LQIOjaFUrSEduEXoPbzHoDTwLlgL+4+8O5Hn8C6B7drQyc6u41zKwt8DRwMnAQGO3u/8zrvVJTUz33xY+WLVtGs2bNCmVfSrqMjAwyMjKoVKkSK1asoFevXqxYsYITTyxe3xf0N5OSbN06mDQpBMScOWHQ+swzQzgMHAidOsFRZsknjZktcPfUuO0S9klhZuWAccBFQDowz8ymuHvW8Q93vyPH9rcC7aK7e4Gr3H2FmZ0BLDCzGe6uaTbHaM+ePfTo0YOMjAzcnT/96U/FLihESqLPPsuewbRgQWhr2RLuuy+EROvWRTO1NdES+WnRAVjp7qsAzGwiMAA42sHyocADAO7+eWaju28ws81AHUBhcYxq1KjBgsx/ySJyzNxh4cLsHsSyZaG9Y0d45JHQg2jSJLk1JkIiw6IusD7H/XSg45E2NLOGQCNg5hEe6wBUAL44wmMjgBEADRI1bUlEyryDB+H997N7EOvWQblyYdzh5pvDgHXdusmuMrGKy3GIIcBL7n7YfEszOx34B3C1ux/K/SR3Hw+MhzBmURSFikjZsH8/zJwZwuGVV8KAdcWK0KsXPPRQmMlUq1ayqyw6iQyLL4H6Oe7Xi9qOZAhw2AJHZnYy8Bpwr7t/mJAKRURy+OYbeP31EBCvvgq7dkHVqnDJJWH8oU8fKKsT/RIZFvOAJmbWiBASQ4Arcm9kZk2BmsAHOdoqAJOAv7v7SwmsUUTKuO3bwzLfkyaFoPj229BjGDw4BESPHlCpUrKrTL6ETeJy9wzgFmAGsAx40d2XmNkoM+ufY9MhwEQ/fA7v5cAFwDVm9nH00zZRtSZK9+7dv3eC3ZgxY7jpppvyfF7VqlUB2LBhA4MHDz7iNt26dSP3VOHcxowZc9jJcX379i2UdZsefPBBHnvsseN+HZFk2bgR/vd/wyGlU08N5z7MmxfOmp41C776Cv7v/0KPQkERJHTMwt2nAdNytf061/0Hj/C854DnEllbURg6dCgTJ07k4osvzmqbOHEijz76aL6ef8YZZ/DSS8fesRozZgzDhw+ncnRq+rRp02KeIVJ6rVqVPYPpgw/CrKYmTeCuu8IMptTU4ncORHGiX00CDR48mNdeey3rQkdr1qxhw4YNdOnSJeu8h/bt29OqVSteeeWV7z1/zZo1tGzZEoB9+/YxZMgQmjVrxsCBA9m3b1/WdjfddFPW8uYPPPAAAGPHjmXDhg10796d7t3DeY8pKSls3boVgMcff5yWLVvSsmXLrOXN16xZQ7Nmzbjhhhto0aIFvXr1Oux9juTjjz+mU6dOtG7dmoEDB7J9+/as989csjxzAcN33nkn6+JP7dq1Y/fu3cf8uxWJ4w6ffgqjRkG7dnDWWSEY9u0LA9SffgrLl8Pvfw8dOigo4hSX2VAJ94tfQGFfAK5t27B08NGccsopdOjQgenTpzNgwAAmTpzI5ZdfjplRqVIlJk2axMknn8zWrVvp1KkT/fv3P+p1qJ9++mkqV67MsmXLWLRo0WFLjI8ePZpTTjmFgwcP0qNHDxYtWsRtt93G448/zqxZs6hdu/Zhr7VgwQKeeeYZ5s6di7vTsWNHunbtSs2aNVmxYgUvvPACf/7zn7n88st5+eWX87w+xVVXXcVTTz1F165d+fWvf81DDz3EmDFjePjhh1m9ejUVK1bMOvT12GOPMW7cODp37syePXuopP69FLJDh8LhpMwexIoV4YS4886DP/4x9CAaNUp2lSWTsjTBMg9FQTgENXToUCBcc+Kee+6hdevW9OzZky+//JJNmzYd9XVmz56d9aHdunVrWrdunfXYiy++SPv27WnXrh1LliyJXSRwzpw5DBw4kCpVqlC1alUGDRrEu+++C0CjRo1o2zYMD+W1DDqE62vs2LGDrl27AnD11Vcze/bsrBqHDRvGc889l3WmeOfOnbnzzjsZO3YsO3bs0BnkUigyMsI4w623hjXdOnUKwdCoURiX2LAhLL1x550KiuNRZv5vzasHkEgDBgzgjjvuYOHChezdu5dzzz0XgAkTJrBlyxYWLFhA+fLlSUlJOeKy5HFWr17NY489xrx586hZsybXXHPNMb1OpszlzSEscR53GOpoXnvtNWbPns3UqVMZPXo0ixcvZuTIkVxyySVMmzaNzp07M2PGDJo2bXrMtUrZ9e23YXG+tLSwWN+2bXDSSdC7d+g9XHop1KyZ7CpLF/UsEqxq1ap0796dn/3sZ1m9Cgjfyk899VTKly/PrFmzWLt2bZ6vc8EFF/D8888D8Omnn7Jo0SIgLG9epUoVqlevzqZNm5g+fXrWc6pVq3bEcYEuXbowefJk9u7dyzfffMOkSZPo0qVLgfetevXq1KxZM6tX8o9//IOuXbty6NAh1q9fT/fu3XnkkUfYuXMne/bs4YsvvqBVq1bcfffd/PCHP+Szzz4r8HtK2bV7N/zznzBkCNSpE06KS0sLAfHyy+E6EGlpcOWVCopEKDM9i2QaOnQoAwcOzDocBTBs2DD69etHq1atSE1Njf2GfdNNN3HttdfSrFkzmjVrltVDadOmDe3ataNp06bUr1//sOXNR4wYQe/evTnjjDOYNWtWVnv79u255ppr6NChAwDXX3897dq1y/OQ09H87W9/48Ybb2Tv3r2ceeaZPPPMMxw8eJDhw4ezc+dO3J3bbruNGjVqcP/99zNr1ixOOOEEWrRokXXVP5Gj2bo1nAORlgZvvgnffRemul5xRTgHont3yHFNMEmghC5RXpS0RHnpoL+ZpKeHCwKlpYVLih46FC4pmrnM93nnhXWZpHAkfYlyEZH8WrEihMOkSTB3bmhr3hzuuScERLt2pWOZ75JMYSEiRc4dPvkkOyA+/TS0p6bC734XAkJzH4qXUh8WmZf/lOKvtBwSlSM7dAg+/DB7me/Vq8OJcF26wJNPhmW+daWB4qtUh0WlSpXYtm0btWrVUmAUc+7Otm3bdKJeKXPgALz9dgiHyZPDmkvly8NFF4Xr3ffvH2Y2SfFXqsOiXr16pKens2XLlmSXIvlQqVIl6tWrl+wy5Djt3QtvvBECYupU2LEDqlSBvn3D4aW+faF69WRXKQVVqsOifPnyNNIpmyIJt2MHvPZaGH+YPj0ERs2aMGBAmMV00UXhpDkpuUp1WIhI4mzeHK4gl5YGb70VDjmdfjpcc00IiAsuCIecpHRQWIhIvq1dm71I35w5YVbTmWeGhToHDdLqraWZwkJE8rRsWfYU1wULQlvr1vDrX4eAaNVK50CUBQoLETmMewiFzB5E5hJenTrBo4+GQerGjZNboxQ9hYWIcPAgvPdedg9i3bqwpEa3bmHp7wEDoG7dZFcpyaSwECmjvvsOZs4MAfHKK2HV1ooV4eKLw9XlLr0UatVKdpVSXCgsRMqQPXvg9ddDQLz2GuzaBdWqhWAYOBD69IGqVZNdpRRHCguRUu7rr+HVV0NAzJgRLhxUuzZcdlkYoO7RI/QoRPKisBAphTZuzF7me9asMCZRrx6MGBEConNn0FVtpSD0z0WklPjii+wZTB9+GGY1nX02/Od/hkNMqama4irHTmEhUkK5h6W9M2cwffJJaG/fPgxQDxoEzZopIKRwKCxESpBDh+Cjj7J7ECtXhjDo3Bkefzz0IFJSkl2llEYKC5FiLiMDZs/O7kFs2BDGG3r0gF/9KpwD8YMfJLtKKe0UFiLF0LffwptvhoCYMiXMaDrppDC1deDAMNW1Ro1kVyllicJCpJjYtQumTQu9h2nTwjkR1atDv35h/OHii6Fy5WRXKWWVwkIkibZuDT2HtLTQk9i/PxxSGjYsBES3blChQrKrFFFYiBS59euzz4GYPTsMWqekwC23hIDo1CmsyyRSnCgsRIrA559nD1B/9FFoa9EiXId60CBo00ZTXKV4U1iIJIA7fPxxdkAsWRLaO3SA3/8+DFKfc05yaxQpCIWFSCE5dAg++CAERFoarFkTrhp3wQUwdiz8+MdQv36yqxQ5NgoLkeOwfz+8/XYIh8mTYdOmMCB90UVw//1hJlOdOsmuUuT4KSxECmjv3rB6a1paWM11xw6oUgUuuSSMP/TpAyefnOwqRQqXwkIkH3bsCMEwaRJMnw779sEpp4RDS4MGQc+e4aQ5kdJKYSFyFJs2hSvIpaXBW2+FZTfOOAN+9rMQEBdcoGW+pexI6D91M+sNPAmUA/7i7g/nevwJoHt0tzJwqrvXiB57HegEzHH3SxNZp0imNWuyF+l7770wq6lxY7jzzjCDqUOHMGgtUtYkLCzMrBwwDrgISAfmmdkUd1+auY2735Fj+1uBdjle4g+EAPl5omoUcYdly7KnuC5cGNrbtIEHHwwB0bKlzoEQSWTPogOw0t1XAZjZRGAAsPQo2w8FHsi84+5vmVm3BNYnZZQ7zJ+f3YNYvjy0/+hH8Ic/hIA466zk1ihS3CQyLOoC63PcTwc6HmlDM2sINAJmJrAeKcMOHoQ5c7J7EOvXhyU1uneH228Py3yfcUayqxQpvorL8NwQ4CV3P1iQJ5nZCGAEQIMGDRJRl5Rg330XBqYzl/nesgUqVQqrt/72t2GZ71NOSXaVIiVDIsPiSyDn+ar1orYjGQLcXNA3cPfxwHiA1NRUL+jzpfTZsydMbZ00KUx13b07nPNw6aXh8FLv3lC1arKrFCl5EhkW84AmZtaIEBJDgCtyb2RmTYGawAcJrEVKsa+/hqlTQw9ixozQo6hTB3760zDF9cILoWLFZFcpUrIlLCzcPcPMbgFmEKbO/tXdl5jZKGC+u0+JNh0CTHT3w3oGZvYu0BSoambpwHXuPiNR9UrJsmFD9jLfb78dxiTq14cbbwwB0bmzlvkWKUyW6zO6xEpNTfX58+cnuwxJoJUrs2cwffhhaDvnHPjJT0JAtG+vKa4iBWVmC9w9NW674jLALfI97rB4cXZALFoU2s89NwxQDxoEzZolt0aRskJhIcXKoUMwd252QHzxRegtnH8+PPFEGKRu2DDZVYqUPQoLSboDB8LlRTPPgdi4EcqXhx494O67oX//cF1qEUkehYUkxb598OabISCmTg0zmipXDst7DxoUlvuuXj3ZVYpIJoWFFJldu2DatBAQ06bBN99AjRqh5zBwIPTqFQJDRIofhYUk1JYt4ezptDT417/CleVOOw2uvDL0ILp1C4ecRKR4U1hIoVu/PnuA+t13w6B1o0Zw660hIDp10jLfIiWNwkIKxfLl2QPU8+aFtpYt4b77wiGmNm10DoRISaawkGPiDv/+d3ZALI0Wnu/YER55JAREkybJrVFECo/CQvLt4EH44IMQEGlpsHZtWFLjggvgppvC9ajr1Ut2lSKSCAoLydP+/TBrVgiHyZNh82aoUCHMXHrgAejXD2rXTnaVIpJoCgv5nm++Cau3pqWFZb537gzLel9ySRig7tMHqlVLdpUiUpQUFgLA9u0hGCZNgtdfDyfN1aoVFukbOBB69gwXDhKRsklhUYZ99RW88kroQcycCRkZULcuXHdd6EF06QIn6l+IiKCwKHNWr84+B+L998OspsaN4Ze/DAGRmqpzIETk+xQWpZx7mNaaOcX13/8O7W3bwkMPhUNMLVroHAgRyZvCohRyDyfGZfYgPv88hMF558Fjj4WAOPPMZFcpIiWJwqKUyMiAOXOyexDp6WG8oXt3uOMOGDAATj892VWKSEmlsCjBvvsuLM6XlhYW69u6NcxY6t0bfvc7uPRSqFkz2VWKSGmgsChhdu+G6dND7+G118L9k08OJ8cNGgQXXwxVqiS7ShEpbRQWJcC2beECQWlp8MYboUdx6qkwdGgYf7jwwnBWtYhIoigsiqkvvwzLa6SlwTvvhHWZGjQIazANGhQGq8uVS3aVIlJWKCyKkZUrsxfpmzs3tDVrBiNHhoBo105TXEUkORQWSeQOixZlT3FdvDi0p6aGAeqBA6Fp0+TWKCICCosid+hQ6DVk9iBWrQpnTHfpAmPGhGW+GzZMdpUiIodTWBSBAwfCuEPmMt8bN4brTvfsCf/1X9C/fxiwFhEprhQWCbJvX5i5lJYWZjJt3w6VK0PfvmH8oW9fqF492VWKiOSPwqIQ7dwJ06aFgJg2DfbuDSfF9e8fxh969YKTTkp2lSIiBZevsDCzs4B0d//OzLoBrYG/u/uORBZXEmzeHM6eTksLZ1MfOBCW1bj66tCD6No1HHISESnJ8tuzeBlINbPGwHjgFeB5oG+iCivO1q3LnsE0Z04YtD7zTLj99hAQHTtqmW8RKV3yGxaH3D3DzAYCT7n7U2b270QWVtx89ln2In3z54e2Vq3g/vtDQLRqpXMgRKT0ym9YHDCzocDVQL+orVQfXHGHhQuzexDLloX2Tp3g0UfDGETjxsmtUUSkqOQ3LK4FbgRGu/tqM2sE/CNxZSXHwYPh6nGZ50CsWxeW1OjWDW6+OZwDUbdusqsUESl6+QoLd18K3AZgZjWBau7+SCILKyr794frT6elhetRb94MFSuGmUsPPRRWc61VK9lViogkV35nQ70N9I+2XwBsNrP33P3OBNZWJDZtgj59oGrVcP2HQYPC9SCqVUt2ZSIixUd+D0NVd/ddZnY9YcrsA2a2KJGFFZX69cPZ1R06hAsHiYjI9+V3gueJZnY6cDnwagLrSYoLLlBQiIjkJb9hMQqYAXzh7vPM7ExgReLKEhGR4iRfYeHu/8/dW7v7TdH9Ve7+k7jnmVlvM1tuZivNbOQRHn/CzD6Ofj43sx05HrvazFZEP1cXZKdERKRw5XeAux7wFNA5anoXuN3d0/N4TjlgHHARkA7MM7Mp0cwqANz9jhzb3wq0i26fAjwApAIOLIieu70A+yYiIoUkv4ehngGmAGdEP1Ojtrx0AFZGvZD9wERgQB7bDwVfJMqAAAAMY0lEQVReiG5fDLzp7l9HAfEm0DuftYqISCHLb1jUcfdn3D0j+nkWqBPznLrA+hz306O27zGzhkAjYGZBnmtmI8xsvpnN37JlS/72RERECiy/YbHNzIabWbnoZziwrRDrGAK85O4HC/Ikdx/v7qnunlqnTlx2iYjIscpvWPyMMG32K2AjMBi4JuY5XwL1c9yvF7UdyRCyD0EV9LkiIpJg+Z0Ntdbd+7t7HXc/1d1/DMTNhpoHNDGzRmZWgRAIU3JvZGZNgZrABzmaZwC9zKxmtLxIr6hNRESS4HiuupDnUh/ungHcQviQXwa86O5LzGyUmfXPsekQYKK7e47nfg38hhA484BRUZuIiCSB5fiMLtgTzda7e/34LYtGamqqz8+80ISIiOSLmS1w99S47Y6nZ3FsKSMiIiVOniflmdlujhwKBpyUkIpERKTYyTMs3F0LdYuIyHEdhhIRkTJCYSEiIrEUFiIiEkthISIisRQWIiISS2EhIiKxFBYiIhJLYSEiIrEUFiIiEkthISIisRQWIiISS2EhIiKxFBYiIhJLYSEiIrEUFiIiEkthISIisRQWIiISS2EhIiKxFBYiIhJLYSEiIrEUFiIiEkthISIisRQWIiISS2EhIiKxFBYiIhJLYSEiIrEUFiIiEkthISIisRQWIiISS2EhIiKxFBYiIhJLYSEiIrHKfFhMmAApKXDCCeG/EyYkuyIRkeLnxGQXkEwTJsCIEbB3b7i/dm24DzBsWPLqEhEpbsp0z+Lee7ODItPevaFdRESyJTQszKy3mS03s5VmNvIo21xuZkvNbImZPZ+j/REz+zT6+Wki6lu3rmDtIiJlVcIOQ5lZOWAccBGQDswzsynuvjTHNk2A/wI6u/t2Mzs1ar8EaA+0BSoCb5vZdHffVZg1NmgQDj0dqV1ERLIlsmfRAVjp7qvcfT8wERiQa5sbgHHuvh3A3TdH7c2B2e6e4e7fAIuA3oVd4OjRULny4W2VK4d2ERHJlsiwqAusz3E/PWrL6WzgbDN7z8w+NLPMQPgE6G1mlc2sNtAdqJ/7DcxshJnNN7P5W7ZsKXCBw4bB+PHQsCGYhf+OH6/BbRGR3JI9G+pEoAnQDagHzDazVu7+hpn9EHgf2AJ8ABzM/WR3Hw+MB0hNTfVjKWDYMIWDiEicRPYsvuTw3kC9qC2ndGCKux9w99XA54TwwN1Hu3tbd78IsOgxERFJgkSGxTygiZk1MrMKwBBgSq5tJhN6FUSHm84GVplZOTOrFbW3BloDbySwVhERyUPCDkO5e4aZ3QLMAMoBf3X3JWY2Cpjv7lOix3qZ2VLCYaZfufs2M6sEvGtmALuA4e6ekahaRUQkb+Z+TIf6i53U1FSfP39+sssQESlRzGyBu6fGbVemz+AWEZH8UViIiEgshYWIiMRSWIiISCyFhYiIxFJYiIhILIWFiIjEUliIiEgshYWIiMRSWIiISCyFhYiIxFJYiIhILIWFiIjEUliIiEgshYWIiMRSWIiISCyFhYiIxFJYiIhILIWFiIjEUliIiEgshYWIiMRSWIiISCyFhYiIxFJYiIhILIWFiIjEUliIiEgshYWIiMRSWIiISCyFhYiIxFJYiIhILIWFiIjEUliIiEgshYWIiMRSWIiISCyFhYiIxFJYiIhILIWFiIjEUliIiEishIaFmfU2s+VmttLMRh5lm8vNbKmZLTGz53O0Pxq1LTOzsWZmiaxVRKSkmTABUlLghBPCfydMSNx7nZioFzazcsA44CIgHZhnZlPcfWmObZoA/wV0dvftZnZq1H4e0BloHW06B+gKvJ2oekVESpIJE2DECNi7N9xfuzbcBxg2rPDfL5E9iw7ASndf5e77gYnAgFzb3ACMc/ftAO6+OWp3oBJQAagIlAc2JbBWEZES5d57s4Mi0969oT0REhkWdYH1Oe6nR205nQ2cbWbvmdmHZtYbwN0/AGYBG6OfGe6+LPcbmNkIM5tvZvO3bNmSkJ0QESmO1q0rWPvxSvYA94lAE6AbMBT4s5nVMLPGQDOgHiFgLjSzLrmf7O7j3T3V3VPr1KlThGWLiCRXgwYFaz9eiQyLL4H6Oe7Xi9pySgemuPsBd18NfE4Ij4HAh+6+x933ANOBHyWwVhGREmX0aKhc+fC2ypVDeyIkMizmAU3MrJGZVQCGAFNybTOZ0KvAzGoTDkutAtYBXc3sRDMrTxjc/t5hKBGRsmrYMBg/Hho2BLPw3/HjEzO4DQmcDeXuGWZ2CzADKAf81d2XmNkoYL67T4ke62VmS4GDwK/cfZuZvQRcCCwmDHa/7u5TE1WriEhJNGxY4sIhN3P3onmnBEtNTfX58+cnuwwRkRLFzBa4e2rcdske4BYRkRJAYSEiIrEUFiIiEkthISIisUrNALeZbQHWHsdL1Aa2FlI5JUVZ2+eytr+gfS4rjmefG7p77FnNpSYsjpeZzc/PjIDSpKztc1nbX9A+lxVFsc86DCUiIrEUFiIiEkthkW18sgtIgrK2z2Vtf0H7XFYkfJ81ZiEiIrHUsxARkVgKCxERiVWmwsLM/mpmm83s06M8bmY21sxWmtkiM2tf1DUWtnzs87BoXxeb2ftm1qaoayxscfucY7sfmlmGmQ0uqtoSIT/7a2bdzOxjM1tiZu8UZX2JkI9/19XNbKqZfRLt87VFXWNhM7P6ZjbLzJZG+3T7EbZJ2GdYmQoL4Fmgdx6P9yFcfKkJMAJ4ughqSrRnyXufVwNd3b0V8BtKx+Dgs+S9z5hZOeAR4I2iKCjBniWP/TWzGsD/AP3dvQVwWRHVlUjPkvff+GZgqbu3IVwz54/RdXVKsgzgl+7eHOgE3GxmzXNtk7DPsDIVFu4+G/g6j00GAH/34EOghpmdXjTVJUbcPrv7++6+Pbr7IeGKhiVaPv7OALcCLwObE19RYuVjf68A0tx9XbR9WdhnB6qZmQFVo20ziqK2RHH3je6+MLq9m3BBuLq5NkvYZ1iZCot8qAusz3E/ne//MUqz6wiXsC3VzKwu4dK9paHnmB9nAzXN7G0zW2BmVyW7oCLw30AzYAPhImq3u/uh5JZUeMwsBWgHzM31UMI+wxJ2pTwpWcysOyEszk92LUVgDHC3ux8KXzxLvROBc4EewEnAB2b2obt/ntyyEupi4GPCFTfPAt40s3fdfVdyyzp+ZlaV0Cv+RVHuj8LicF8C9XPcrxe1lWpm1hr4C9DH3bclu54ikApMjIKiNtDXzDLcfXJyy0qYdGCbu38DfGNms4E2QGkOi2uBhz2cSLbSzFYDTYGPklvW8TGz8oSgmODuaUfYJGGfYToMdbgpwFXRjIJOwE5335jsohLJzBoAacCVpfybZhZ3b+TuKe6eArwE/EcpDgqAV4DzzexEM6sMdCQc7y7N1hF6UpjZD4BzgFVJreg4ReMv/wcsc/fHj7JZwj7DylTPwsxeIMyMqG1m6cADQHkAd/9fYBrQF1gJ7CV8OynR8rHPvwZqAf8TfdPOKOkrduZjn0uVuP1192Vm9jqwCDgE/MXd85xWXNzl42/8G+BZM1sMGOGwY0lftrwzcCWw2Mw+jtruARpA4j/DtNyHiIjE0mEoERGJpbAQEZFYCgsREYmlsBARkVgKCxERiaWwEIlhZgejFVszf0YW4munxK2OK1IclKnzLESO0T53b5vsIkSSST0LkWNkZmvM7NHoWiAfmVnjqD3FzGZG1xN4KzpLHjP7gZlNiq6x8ImZnRe9VDkz+3N0jYI3zOykaPvbomsXLDKziUnaTRFAYSGSHyflOgz10xyP7YyuBfLfhAUKAZ4C/uburYEJwNiofSzwTnSNhfbAkqi9CTAuutbEDuAnUftIoF30OjcmaudE8kNncIvEMLM97l71CO1rgAvdfVW0wNtX7l7LzLYCp7v7gah9o7vXNrMtQD13/y7Ha6QAb7p7k+j+3UB5d/9ttETHHmAyMNnd9yR4V0WOSj0LkePjR7ldEN/luH2Q7LHES4BxhF7IPDPTGKMkjcJC5Pj8NMd/P4huvw8MiW4PA96Nbr8F3AThsq5mVv1oL2pmJwD13X0WcDdQnXDFN5Gk0DcVkXgn5VjlE+B1d8+cPlvTzBYRegdDo7ZbgWfM7FfAFrJX/rwdGG9m1xF6EDcBR1s+uhzwXBQoBox19x2FtkciBaQxC5FjFI1ZpJaCpa9FYukwlIiIxFLPQkREYqlnISIisRQWIiISS2EhIiKxFBYiIhJLYSEiIrH+P0tXKzKZXT6KAAAAAElFTkSuQmCC\n",
      "text/plain": [
       "<Figure size 432x288 with 1 Axes>"
      ]
     },
     "metadata": {
      "needs_background": "light"
     },
     "output_type": "display_data"
    }
   ],
   "source": [
    "import matplotlib.pyplot as plt\n",
    "\n",
    "acc = history.history['acc']\n",
    "val_acc = history.history['val_acc']\n",
    "loss = history.history['loss']\n",
    "val_loss = history.history['val_loss']\n",
    "\n",
    "epochs = range(1, len(acc) + 1)\n",
    "\n",
    "# \"bo\" is for \"blue dot\"\n",
    "plt.plot(epochs, loss, 'bo', label='Training loss')\n",
    "# b is for \"solid blue line\"\n",
    "plt.plot(epochs, val_loss, 'b', label='Validation loss')\n",
    "plt.title('Training and validation loss')\n",
    "plt.xlabel('Epochs')\n",
    "plt.ylabel('Loss')\n",
    "plt.legend()\n",
    "\n",
    "plt.show()\n"
   ]
  },
  {
   "cell_type": "code",
   "execution_count": 32,
   "metadata": {},
   "outputs": [
    {
     "data": {
      "image/png": "iVBORw0KGgoAAAANSUhEUgAAAZIAAAEWCAYAAABMoxE0AAAABHNCSVQICAgIfAhkiAAAAAlwSFlzAAALEgAACxIB0t1+/AAAADl0RVh0U29mdHdhcmUAbWF0cGxvdGxpYiB2ZXJzaW9uIDMuMC4xLCBodHRwOi8vbWF0cGxvdGxpYi5vcmcvDW2N/gAAIABJREFUeJzt3XmYVNWd//H3hxZk31GRxUZFBdlsWnBG3PdEMVGjKIkhiRKNRJNMFif6iz4as48xThwnaNwiShyNijHGiUajTqKhiagBohBEbUQFRGVxoeH7++Pe6q7uru4uuqguGj6v57lP1z333FvnVEN9+5xz7zmKCMzMzFqrQ6kLYGZm7ZsDiZmZFcSBxMzMCuJAYmZmBXEgMTOzgjiQmJlZQRxIrGCSyiStkzR0a+YtJUl7S9rq98ZLOlrSsqz9FyUdkk/eVrzXjZK+3drzzfK1U6kLYG1P0rqs3a7Ah8CmdP+LETFrS64XEZuA7ls7744gIvbdGteRdA7w6Yg4POva52yNa5u1xIFkBxQRtV/k6V+850TEI03ll7RTRNS0RdnMWuJ/j9sed21ZI5K+K+nXku6UtBb4tKR/kfS0pHckrZB0raSOaf6dJIWk8nT/9vT4Q5LWSvqLpGFbmjc9foKklyS9K+k/Jf2fpGlNlDufMn5R0hJJayRdm3VumaSfSlotaSlwfDOfzyWSZjdIu07S1enrcyQtSuvzz7S10NS1qiUdnr7uKulXadkWAOMb5L1U0tL0ugskTU7TRwM/Bw5Juw1XZX22l2edf15a99WS7pM0MJ/PZks+50x5JD0i6W1Jb0j6Ztb7/L/0M3lPUpWk3XN1I0p6KvN7Tj/PJ9L3eRu4VNJwSY+l77Eq/dx6ZZ2/R1rHlenxn0nqnJZ5RFa+gZI2SOrXVH0tDxHhbQfegGXA0Q3Svgt8BJxE8sdGF+BAYCJJK3ZP4CVgRpp/JyCA8nT/dmAVUAl0BH4N3N6KvLsAa4GT02NfAzYC05qoSz5lvB/oBZQDb2fqDswAFgCDgX7AE8l/j5zvsyewDuiWde23gMp0/6Q0j4AjgfeBMemxo4FlWdeqBg5PX/8EeBzoA+wBLGyQ93RgYPo7OSstw67psXOAxxuU83bg8vT1sWkZxwGdgf8C/pjPZ7OFn3Mv4E3gImBnoCcwIT3278BzwPC0DuOAvsDeDT9r4KnM7zmtWw1wPlBG8u9xH+AooFP67+T/gJ9k1efv6efZLc1/cHpsJnBV1vv8G3Bvqf8ftvet5AXwVuJ/AE0Hkj+2cN7Xgf9JX+cKDv+dlXcy8PdW5P088GTWMQEraCKQ5FnGg7KO/wb4evr6CZIuvsyxjzX8cmtw7aeBs9LXJwAvNpP3t8AF6evmAsmr2b8L4EvZeXNc9+/Ax9PXLQWSW4HvZR3rSTIuNrilz2YLP+fPAHObyPfPTHkbpOcTSJa2UIbTMu8LHAK8AZTlyHcw8DKgdH8+cMrW/n+1o23u2rKmvJa9I2k/SQ+mXRXvAVcA/Zs5/42s1xtofoC9qby7Z5cjkv/51U1dJM8y5vVewCvNlBfgDuDM9PVZ6X6mHCdKeibtdnmHpDXQ3GeVMbC5MkiaJum5tHvmHWC/PK8LSf1qrxcR7wFrgEFZefL6nbXwOQ8hCRi5NHesJQ3/Pe4m6S5Jy9My3NKgDMsiubGjnoj4P5LWzSRJo4ChwIOtLJOlHEisKQ1vff0FyV/Ae0dET+A7JC2EYlpB8hczAJJE/S++hgop4wqSL6CMlm5Pvgs4WtIgkq63O9IydgHuBr5P0u3UG/jfPMvxRlNlkLQncD1J906/9Lr/yLpuS7cqv07SXZa5Xg+SLrTleZSroeY+59eAvZo4r6lj69Mydc1K261Bnob1+yHJ3Yaj0zJMa1CGPSSVNVGO24BPk7Se7oqID5vIZ3lyILF89QDeBdang5VfbIP3/C1QIekkSTuR9LsPKFIZ7wK+ImlQOvD6reYyR8QbJN0vt5B0ay1OD+1M0m+/Etgk6USSvvx8y/BtSb2VPGczI+tYd5Iv05UkMfVckhZJxpvA4OxB7wbuBL4gaYyknUkC3ZMR0WQLrxnNfc5zgKGSZkjaWVJPSRPSYzcC35W0lxLjJPUlCaBvkNzUUSZpOllBr5kyrAfelTSEpHst4y/AauB7Sm5g6CLp4KzjvyLpCjuLJKhYgRxILF//BnyWZPD7FySD4kUVEW8CZwBXk3wx7AU8S/KX6NYu4/XAo8ALwFySVkVL7iAZ86jt1oqId4CvAveSDFifRhIQ83EZSctoGfAQWV9yEfE88J/AX9M8+wLPZJ37B2Ax8Kak7C6qzPm/J+mCujc9fygwNc9yNdTk5xwR7wLHAKeSBLeXgMPSwz8G7iP5nN8jGfjunHZZngt8m+TGi70b1C2Xy4AJJAFtDnBPVhlqgBOBESStk1dJfg+Z48tIfs8fRsSft7DulkNmwMlsm5d2VbwOnBYRT5a6PNZ+SbqNZAD/8lKXZXvgBxJtmybpeJI7pN4nuX10I8lf5Watko43nQyMLnVZthfu2rJt3SRgKcnYwHHAJz04aq0l6fskz7J8LyJeLXV5thfu2jIzs4K4RWJmZgXZIcZI+vfvH+Xl5aUuhplZuzJv3rxVEdHcLffADhJIysvLqaqqKnUxzMzaFUktzfAAuGvLzMwK5EBiZmYFcSAxM7OCFHWMJH2Y7GckawjcGBE/aHB8Gsm0CZmJ434eETdKOgL4aVbW/YApEXGfpFtIplx4Nz02LSLmb2nZNm7cSHV1NR988MGWnmptpHPnzgwePJiOHZuaPsrMtgVFCyTpdBbXkcy7Uw3MlTQnIhY2yPrriMienI6IeIxk0RvSSd2WkMygmvGNiMhnLqQmVVdX06NHD8rLy0kmlbVtSUSwevVqqqurGTZsWMsnmFnJFLNrawKwJCKWRsRHwGySaQm21GnAQxGxYWsW7oMPPqBfv34OItsoSfTr188tRrNWmDULysuhQ4fk56xZxX2/YgaSQdRfjKaa3GtJnCrpeUl3p9NBNzSFZArsbFel5/w0nRK7EUnT0zWhq1auXJmzgA4i2zb/fsy23KxZMH06vPIKRCQ/p08vbjAp9WD7AyRLro4hmQb71uyDkgaSTKz2cFbyv5OMmRxIst5zznUjImJmRFRGROWAAS0+T2Nmtl245BLY0KD/ZsOGJL1YihlIllN/tbfBNFiNLSJWZ03AdyMwvsE1TgfujYiNWeesiMSHwM0kXWjtzurVqxk3bhzjxo1jt912Y9CgQbX7H330UV7X+NznPseLL77YbJ7rrruOWcVu15rZNuPVJqaibCp9ayjmXVtzgeGShpEEkCkkK5LVkjQwIlaku5OBRQ2ucSZJC6TROemyq58gWfKz6GbNSiL6q6/C0KFw1VUwtbXLAgH9+vVj/vzkZrPLL7+c7t278/Wvf71enoggIujQIXe8v/nmm1t8nwsuuKD1hTSzdmfo0KQ7K1d6sRStRZKuUjaDpFtqEcnayAskXSFpcprtQkkLJD0HXEiy7jIAkspJWjR/anDpWZJeIFnhrD/w3WLVofYN27DPccmSJYwcOZKpU6ey//77s2LFCqZPn05lZSX7778/V1xxRW3eSZMmMX/+fGpqaujduzcXX3wxY8eO5V/+5V946623ALj00ku55ppravNffPHFTJgwgX333Zc//zlZHG79+vWceuqpjBw5ktNOO43KysraIJftsssu48ADD2TUqFGcd955ZGaOfumllzjyyCMZO3YsFRUVLFu2DIDvfe97jB49mrFjx3JJMdvVZlbrqquga9f6aV27JulFk/mrd3vexo8fHw0tXLiwUVpT9tgjIgkh9bc99sj7Es267LLL4sc//nFERCxevDgkxdy5c2uPr169OiIiNm7cGJMmTYoFCxZERMTBBx8czz77bGzcuDGA+N3vfhcREV/96lfj+9//fkREXHLJJfHTn/60Nv83v/nNiIi4//7747jjjouIiO9///vxpS99KSIi5s+fHx06dIhnn322UTkz5di8eXNMmTKl9v0qKipizpw5ERHx/vvvx/r162POnDkxadKk2LBhQ71zt9SW/J7MLHH77cn3k5T8vP321l0HqIo8vmNLPdjeLrR1n+Nee+1FZWVl7f6dd95JRUUFFRUVLFq0iIULGz6KA126dOGEE04AYPz48bWtgoZOOeWURnmeeuoppkyZAsDYsWPZf//9c5776KOPMmHCBMaOHcuf/vQnFixYwJo1a1i1ahUnnXQSkDxE2LVrVx555BE+//nP06VLFwD69u275R+EmbXK1KmwbBls3pz8LKQbPh87xOy/hWrrPsdu3brVvl68eDE/+9nP+Otf/0rv3r359Kc/nfPZik6dOtW+Lisro6amJue1d9555xbz5LJhwwZmzJjB3/72NwYNGsSll17qZzzMDCj97b/tQkn6HFPvvfcePXr0oGfPnqxYsYKHH3645ZO20MEHH8xdd90FwAsvvJCzxfP+++/ToUMH+vfvz9q1a7nnnnsA6NOnDwMGDOCBBx4Akgc9N2zYwDHHHMNNN93E+++/D8Dbb7+91cttZtsGt0jykGkWbs27tvJVUVHByJEj2W+//dhjjz04+OCDt/p7fPnLX+bss89m5MiRtVuvXr3q5enXrx+f/exnGTlyJAMHDmTixIm1x2bNmsUXv/hFLrnkEjp16sQ999zDiSeeyHPPPUdlZSUdO3bkpJNO4sorr9zqZTez0tsh1myvrKyMhgtbLVq0iBEjRpSoRNuWmpoaampq6Ny5M4sXL+bYY49l8eLF7LRT6f/O8O/JrHQkzYuIypbylf6bwkpu3bp1HHXUUdTU1BAR/OIXv9gmgoiZtQ/+tjB69+7NvHnzSl0MM2unPNhuZmYFcSAxM7OCOJCYmVlBHEjMzKwgDiQlcsQRRzR6uPCaa67h/PPPb/a87t27A/D6669z2mmn5cxz+OGH0/B254auueYaNmQtWvCxj32Md955J5+im5nV40BSImeeeSazZ8+ulzZ79mzOPPPMvM7ffffdufvu1i9b3zCQ/O53v6N3796tvp6Z7bgcSErktNNO48EHH6xdxGrZsmW8/vrrHHLIIbXPdVRUVDB69Gjuv//+RucvW7aMUaNGAcn0JVOmTGHEiBF88pOfrJ2WBOD888+vnYL+sssuA+Daa6/l9ddf54gjjuCII44AoLy8nFWrVgFw9dVXM2rUKEaNGlU7Bf2yZcsYMWIE5557Lvvvvz/HHntsvffJeOCBB5g4cSIHHHAARx99NG+++SaQPKvyuc99jtGjRzNmzJjaKVZ+//vfU1FRwdixYznqqKO2ymdrZm3Lz5EAX/kK5Fh+oyDjxkH6HZxT3759mTBhAg899BAnn3wys2fP5vTTT0cSnTt35t5776Vnz56sWrWKgw46iMmTJze5hvn1119P165dWbRoEc8//zwVFRW1x6666ir69u3Lpk2bOOqoo3j++ee58MILufrqq3nsscfo379/vWvNmzePm2++mWeeeYaIYOLEiRx22GH06dOHxYsXc+edd3LDDTdw+umnc8899/DpT3+63vmTJk3i6aefRhI33ngjP/rRj/iP//gPrrzySnr16sULL7wAwJo1a1i5ciXnnnsuTzzxBMOGDfN8XGbtlFskJZTdvZXdrRURfPvb32bMmDEcffTRLF++vPYv+1yeeOKJ2i/0MWPGMGbMmNpjd911FxUVFRxwwAEsWLAg54SM2Z566ik++clP0q1bN7p3784pp5zCk08+CcCwYcMYN24c0PRU9dXV1Rx33HGMHj2aH//4xyxYsACARx55pN5qjX369OHpp5/m0EMPZdiwYYCnmjdrr4raIpF0PPAzoAy4MSJ+0OD4NODH1K3l/vOIuDE9tolkFUSAVyNicpo+DJgN9APmAZ+JiPwWOW9Ccy2HYjr55JP56le/yt/+9jc2bNjA+PHJkvWzZs1i5cqVzJs3j44dO1JeXt6qKdtffvllfvKTnzB37lz69OnDtGnTCpr6PTMFPSTT0Ofq2vryl7/M1772NSZPnszjjz/O5Zdf3ur3M7P2oWgtEkllwHXACcBI4ExJI3Nk/XVEjEu3G7PS389Kn5yV/kPgpxGxN7AG+EKx6lBs3bt354gjjuDzn/98vUH2d999l1122YWOHTvy2GOP8UquxVCyHHroodxxxx0A/P3vf+f5558Hkinou3XrRq9evXjzzTd56KGHas/p0aMHa9eubXStQw45hPvuu48NGzawfv167r33Xg455JC86/Tuu+8yaNAgAG699dba9GOOOYbrrruudn/NmjUcdNBBPPHEE7z88suAp5o3a6+K2bU1AVgSEUvTFsNs4ORCLqhkkOBIIHO70q3AJwoqZYmdeeaZPPfcc/UCydSpU6mqqmL06NHcdttt7Lfffs1e4/zzz2fdunWMGDGC73znO7Utm7Fjx3LAAQew3377cdZZZ9Wbgn769Okcf/zxtYPtGRUVFUybNo0JEyYwceJEzjnnHA444IC863P55ZfzqU99ivHjx9cbf7n00ktZs2YNo0aNYuzYsTz22GMMGDCAmTNncsoppzB27FjOOOOMvN/HzLYdRZtGXtJpwPERcU66/xlgYkTMyMozDfg+sBJ4CfhqRLyWHqsB5gM1wA8i4j5J/YGn09YIkoYAD0XEqBzvPx2YDjB06NDxDf+q9/Tk7YN/T2alk+808qUebH8AKI+IMcAfSFoYGXukFTgLuEbSXlty4YiYGRGVEVE5YMCArVdiMzOrp5iBZDkwJGt/MHWD6gBExOqI+DDdvREYn3VsefpzKfA4cACwGugtKXOTQKNrmplZ2ypmIJkLDJc0TFInYAowJzuDpIFZu5OBRWl6H0k7p6/7AwcDCyPph3sMyMwN8lmg8dN6edoRVodsz/z7MWsfihZIIqIGmAE8TBIg7oqIBZKukJS5C+tCSQskPQdcCExL00cAVWn6YyRjJJkHIL4FfE3SEpJbgH/ZmvJ17tyZ1atX+8tqGxURrF69ms6dO5e6KGbWgh12zfaNGzdSXV1d0HMVVlydO3dm8ODBdOzYsdRFMdshec32FnTs2LH2iWozM2u9Ut+1ZWZm7ZwDiZmZFcSBxMzMCuJAYmZmBXEgMTOzgjiQmJlZQRxIzMysIA4kZmZWEAcSMzMriAOJmZkVxIGkCbNmQXk5dOiQ/Jw1q9QlMjPbNu2wc201Z9YsmD4dNmxI9l95JdkHmDq1dOUyM9sWuUWSwyWX1AWRjA0bknQzM6vPgSSHV1/dsnQzsx2ZA0kOQ4duWbqZ2Y6sqIFE0vGSXpS0RNLFOY5Pk7RS0vx0OydNHyfpL+nqic9LOiPrnFskvZx1zritXe6rroKuXeunde2apJuZWX1FG2yXVAZcBxwDVANzJc3JWjI349cRMaNB2gbg7IhYLGl3YJ6khyPinfT4NyLi7mKVPTOgfsklSXfW0KFJEPFAu5lZY8W8a2sCsCQilgJImg2cDDQMJI1ExEtZr1+X9BYwAHin6bO2rqlTHTjMzPJRzK6tQcBrWfvVaVpDp6bdV3dLGtLwoKQJQCfgn1nJV6Xn/FTSzrneXNJ0SVWSqlauXFlANczMrDmlHmx/ACiPiDHAH4Bbsw9KGgj8CvhcRGxOk/8d2A84EOgLfCvXhSNiZkRURkTlgAEDilV+M7MdXjEDyXIgu4UxOE2rFRGrI+LDdPdGYHzmmKSewIPAJRHxdNY5KyLxIXAzSReamZmVSDEDyVxguKRhkjoBU4A52RnSFkfGZGBRmt4JuBe4reGgeuYcSQI+Afy9aDUwM7MWFW2wPSJqJM0AHgbKgJsiYoGkK4CqiJgDXChpMlADvA1MS08/HTgU6CcpkzYtIuYDsyQNAATMB84rVh3MzKxliohSl6HoKisro6qqqtTFMDNrVyTNi4jKlvKVerDdzMzaOQcSMzMriAOJmZkVxIHEzMwK4kBiZmYFcSAxM7OCOJCYmVlBHEjMzKwgDiRmZlYQBxIzMyuIA4mZmRXEgcTMzAriQGJmZgVxIDEzs4I4kJiZWUEcSMzMrCBFDSSSjpf0oqQlki7OcXyapJWS5qfbOVnHPitpcbp9Nit9vKQX0mtemy65a2ZmJVK0QCKpDLgOOAEYCZwpaWSOrL+OiHHpdmN6bl/gMmAiMAG4TFKfNP/1wLnA8HQ7vlh1MDOzlhWzRTIBWBIRSyPiI2A2cHKe5x4H/CEi3o6INcAfgOMlDQR6RsTTkawRfBvwiWIU3szM8lPMQDIIeC1rvzpNa+hUSc9LulvSkBbOHZS+bumaSJouqUpS1cqVK1tbBzMza0GpB9sfAMojYgxJq+PWrXXhiJgZEZURUTlgwICtdVkzM2ugmIFkOTAka39wmlYrIlZHxIfp7o3A+BbOXZ6+bvKaZmbWtooZSOYCwyUNk9QJmALMyc6QjnlkTAYWpa8fBo6V1CcdZD8WeDgiVgDvSToovVvrbOD+ItbBzMxasFOxLhwRNZJmkASFMuCmiFgg6QqgKiLmABdKmgzUAG8D09Jz35Z0JUkwArgiIt5OX38JuAXoAjyUbmZmViJKbn7avlVWVkZVVVWpi2Fm1q5ImhcRlS3la7FrS9KXs57hMDMzqyefMZJdgbmS7kqfVPeT5GZmVqvFQBIRl5I8Qf5LkjGMxZK+J2mvIpfNzMzagbzu2kqfIn8j3WqAPsDdkn5UxLKZmVk70OJdW5IuIrnNdhXJsx7fiIiNkjoAi4FvFreIZma2Lcvn9t++wCkR8Up2YkRslnRicYplZmbtRT5dWw+RPOMBgKSekiYCRMSiJs8yM7MdQj6B5HpgXdb+ujTNzMwsr0CiyHpqMSI2U8Qn4s3MrH3JJ5AslXShpI7pdhGwtNgFMzOz9iGfQHIe8K8ks+xWk6xaOL2YhTIzs/ajxS6qiHiLZOZeMzOzRvJ5jqQz8AVgf6BzJj0iPl/EcpmZWTuRT9fWr4DdSNZR/xPJYlJri1koMzNrP/IJJHtHxP8D1kfErcDHScZJzMzM8gokG9Of70gaBfQCdilekczMrD3JJ5DMTNcjuZRkqdyFwA/zuXg67fyLkpZIuriZfKdKCkmV6f5USfOzts2SxqXHHk+vmTnmoGZmVkLNDranEzO+FxFrgCeAPfO9sKQy4DrgGJLbhudKmhMRCxvk6wFcBDyTSYuIWcCs9Pho4L6ImJ912tSI8JKHZmbbgGZbJOlT7K2d3XcCsCQilkbER8Bs4OQc+a4kaeF80MR1zkzPNTOzbVA+XVuPSPq6pCGS+ma2PM4bBLyWtV+dptWSVAEMiYgHm7nOGcCdDdJuTru1/l9TKzZKmi6pSlLVypUr8yiumZm1Rj5zZp2R/rwgKy3Ygm6uXNJus6tJVl1sKs9EYENE/D0reWpELE+7xO4BPgPc1vDciJgJzASorKyMhsfNzGzryOfJ9mGtvPZyYEjW/uA0LaMHMAp4PG1U7AbMkTQ5a/xjCg1aIxGxPP25VtIdJF1ojQKJmZm1jXyebD87V3pEtPTlPRcYLmkYSQCZApyVdf67QP+s93kc+HomiKQtltOBQ7Ly7AT0johVkjoCJwKPtFQHMzMrnny6tg7Met0ZOAr4Gy20AiKiRtIM4GGgDLgpIhZIugKoiog5LbzvocBrEZE90/DOwMNpECkjCSI35FEHMzMrEmUtNZLfCVJvYHZEHF+cIm19lZWVUVXlu4XNzLaEpHkRUdlSvnzu2mpoPdDacRMzM9vO5DNG8gDJXVqQBJ6RwF3FLJSZmbUf+YyR/CTrdQ3wSkRUF6k8ZmbWzuQTSF4FVkTEBwCSukgqj4hlRS2ZmZm1C/mMkfwPsDlrf1OaZmZmllcg2SmdKwuA9HWn4hXJzMzak3wCyUpJkzM7kk4GVhWvSGZm1p7kM0ZyHjBL0s/T/Wog59PuZma248lnrq1/AgdJ6p7uryt6qczMrN1osWtL0vck9Y6IdRGxTlIfSd9ti8KZmdm2L58xkhMi4p3MTrpa4seKVyQzM2tP8gkkZZJ2zuxI6kIyeaKZmVleg+2zgEcl3QyIZCGqW4tZKDMzaz/yGWz/oaTngKNJ5tx6GNij2AUzM7P2Id/Zf98kCSKfAo4EFhWtRGZm1q402SKRtA9wZrqtAn5Nsn7JEW1UNjMzaweaa5H8g6T1cWJETIqI/ySZZytvko6X9KKkJZIubibfqZJCUmW6Xy7pfUnz0+2/s/KOl/RCes1rlS74bmZmpdFcIDkFWAE8JukGSUeRDLbnRVIZcB1wAskaJmdKGpkjXw/gIuCZBof+GRHj0u28rPTrgXOB4enWblZqNDPbHjUZSCLivoiYAuwHPAZ8BdhF0vWSjs3j2hOAJRGxNJ3ocTZwco58VwI/BD5o6YKSBgI9I+LpSNYIvg34RB5lMTOzImlxsD0i1kfEHRFxEjAYeBb4Vh7XHgS8lrVfnabVklQBDImIB3OcP0zSs5L+JOmQrGtmL6rV6JpZ154uqUpS1cqVK/MorpmZtcYWrdkeEWsiYmZEHFXoG0vqAFwN/FuOwyuAoRFxAPA14A5JPbewrDMjojIiKgcMGFBocc3MrAn5PJDYWsuBIVn7g9O0jB7AKODxdLx8N2COpMkRUQV8CBAR8yT9E9gnPX9wM9c0M7M2tkUtki00FxguaZikTsAUYE7mYES8GxH9I6I8IsqBp4HJEVElaUA6WI+kPUkG1ZdGxArgPUkHpXdrnQ3cX8Q6mJlZC4rWIomIGkkzSJ6ELwNuiogFkq4AqiJiTjOnHwpcIWkjyTK/50XE2+mxLwG3AF2Ah9LNzMxKRMnNT9u3ysrKqKqqKnUxzMzaFUnzIqKypXzF7NoyM7MdgAOJmZkVxIHEzMwK4kBiZmYFcSAxM7OCOJCYmVlBHEjMzKwgDiRmZlYQBxIzMyuIA4mZmRXEgcTMzAriQGJmZgVxIDEzs4I4kJiZWUEcSMzMrCAOJGZmVpCiBhJJx0t6UdISSRc3k+9USSGpMt0/RtI8SS+kP4/Myvt4es356bZLMetgZmbNK9pSu+ma69cBxwDVwFxJcyJiYYN8PYCLgGeyklcBJ0XE65JGkSzXOyjr+NSI8JKHZmbbgGK2SCYASyJiaUR8BMyByO1xAAAQ30lEQVQGTs6R70rgh8AHmYSIeDYiXk93FwBdJO1cxLKamVkrFa1FQtKCeC1rvxqYmJ1BUgUwJCIelPSNJq5zKvC3iPgwK+1mSZuAe4DvRo6F5yVNB6YDDB06tFUVuPZaeO01GDGibuvdu1WXMjPbbhUzkDRLUgfgamBaM3n2J2mtHJuVPDUilqddYvcAnwFua3huRMwEZgJUVlY2CjT5mDsX/ud/4MOsELbbbvUDS2YbOBCk1ryLmVn7VsxAshwYkrU/OE3L6AGMAh5X8g28GzBH0uSIqJI0GLgXODsi/pk5KSKWpz/XSrqDpAutUSDZGn71K7jlFnj5ZVi0qP52++3w3nt1eXv1yh1gysuhrKwYpTMz2zYUM5DMBYZLGkYSQKYAZ2UORsS7QP/MvqTHga+nQaQ38CBwcUT8X1aenYDeEbFKUkfgROCRItaBsjLYe+9kO+mkuvQIWLGicYB56CG4+ea6fDvvDPvu2zjA7LNPcszMrL0rWiCJiBpJM0juuCoDboqIBZKuAKoiYk4zp88A9ga+I+k7adqxwHrg4TSIlJEEkRuKVYfmSLD77sl21FH1j61ZA//4R/0AM3cu3HVXEoAAOnSAPffM3Yrp2bPt62Nm1lrKMU693amsrIyqqtLfLfz++/DSS0lgWbiwLsi89BJs3FiXb/fdcweYXXf1OIyZtR1J8yKisqV8JRts3xF16QJjxyZbtpoaWLq0cTfZrbfC2rV1+Xr3bnocpoPnKDCzEnGLZBsWAcuXNw4wixbBW2/V5evcOfc4zPDhHocxs9Zzi2Q7IMHgwcl2zDH1j739duPg8vTTMHt2XZ6ysqbHYXr0aNu6mNn2y4GknerbFw4+ONmybdgAL76Y+26y7HGYQYNyB5hddvE4jJltGQeS7UzXrnDAAcmWbePG3OMwN90E69fX5evTJ3eA2WMPj8OYWW4eI9nBRUB1de5xmJUr6/J16VJ/HGbkyOTn3ntDp06lK7+ZFY/HSCwvEgwZkmzHHlv/2OrVjYPLn/8Md95ZlyfzwGbDFsx++0H37m1bFzMrDQcSa1K/fjBpUrJlW78+GYfJfhZm0SL47W+TW5kzhgzJ3U02YEDb1sPMisuBxLZYt25QUZFs2TZuhCVLGrdibrghuQkgo1+/3AFmyBCPw5i1Rw4kttV07FgXFLJt3pxMx98wwPzmN0n3WUbXrkmXWMMAs/feybXNbNvkwXYrqZUrcw/0v5a1ks1OOzU9DtOtW+nKbra982C7tQsDBiTboYfWT1+3rvHElwsXwpw5sGlTXb6hQ3N3k/Xvj5m1EQcS2yZ17w6VlcmW7aOPco/DPPFEMilmRv/+TY/D+IFLs63LgcTalU6dkmdYRo6sn755M7z6auMAc/fdyXQyGd265R6H2Wsvj8OYtZbHSGy7FtH0OEx1dV2+jh3rxmEyD1uOGJE8hNm1a+nKb1ZKHiMxI+nG2mWXZDvssPrH3nuv8TjMCy/AffclLZzM+XvskbubrG/ftq+P2baoqIFE0vHAz0hWM7wxIn7QRL5TgbuBAyOiKk37d+ALwCbgwoh4eEuuadaSnj1hwoRky/bhh7B4ceMWzGOPwQcf1OXbZZfcAWbQII/D2I6laIFEUhlwHXAMUA3MlTQnIhY2yNcDuAh4JittJMka7/sDuwOPSNonPdziNc0KsfPOMGpUsmXbtAleeaVxgJk9G955py5fjx65x2H23DO5ldlse1PMf9YTgCURsRRA0mzgZKDhl/6VwA+Bb2SlnQzMjogPgZclLUmvR57XNNvqMuu77LknfPzjdekR8OabjQPMI4/AbbfV5evUKVlsrGGA2XffZFJMs/aqmIFkEJD1WBnVwMTsDJIqgCER8aCkbzQ49+kG5w5KXzd7zaxrTwemAwwdOrQ15TfLiwS77ZZsRxxR/9i77zYeh5k/P3mqP3scprw8dzdZnz5tXh2zLVayhrakDsDVwLRiXD8iZgIzIblrqxjvYdaSXr1g4sRky/bBB7nHYR59NBmjydh119wBZvfdPQ5j245iBpLlwJCs/cFpWkYPYBTwuJL/EbsBcyRNbuHc5q5p1i507gyjRydbtk2bYNmyxgHmjjuS1k1Gz55Nj8OUlbVpVcyK9xyJpJ2Al4CjSL7s5wJnRcSCJvI/Dnw9Iqok7Q/cQTIusjvwKDAc0JZcM8PPkVh7FwFvvFF/upjM6zfeqMvXqRPss0/ucZjOnUtXfmufSv4cSUTUSJoBPExyq+5NEbFA0hVAVUTMaebcBZLuIhlErwEuiIhNALmuWaw6mG0rJBg4MNmOPLL+sXfeadyCmTcveao/83dihw4wbFjubrJevdq+PrZ98ZPtZtup99+Hl15qHGReeimZsyxj4MDcAWa33TwOs6MreYvEzEqrSxcYOzbZstXUwMsvNw4wt90Ga9fW5evVK3eAKS/3OIzV5xaJmQFJN9jrr+eel+zNN+vy7bxzMubSMMDss09yzLYfbpGY2RaRkuldBg2Co4+uf2zNmsbB5a9/hbvuqj8Os+eeuVsxPXu2fX2s7TiQmFmL+vSBf/3XZMu2YUPucZjf/x42bqzLt/vuuQPMrrt6HGZ74EBiZq3WtSuMG5ds2WpqYOnSxgHmlluS1S8zevduehymQ4e2rIkVwmMkZtZmIpJ1YHKNw6xcWZevc+fc4zDDh3scpi15jMTMtjlSstzxkCFw7LH1j61e3Ti4/OUvyezKGZmJM3O1Ynr0aNu6WB0HEjPbJvTrB5MmJVu29evhxRcbB5nf/S7pQssYNKjxCpcjRsCAAR6HKTYHEjPbpnXrBhUVyZZt40b45z8bB5hf/jIJPhl9++ZuwQwd6nGYrcVjJGa2Xdm8uelxmFWr6vJ17Zp7HGbvvZM5y8xjJGa2g+rQIWltDB0Kxx1X/9iqVY2Dy1NPJbMrZ5SVJcGkYYDZbz/o3r1t69JeOJCY2Q6jf3845JBky7ZuXe5xmN/+tv44zJAhubvJBgxo23psaxxIzGyH1707jB+fbNk++qhuHCZ76v4nn0wmxczo1y93gBkyZMcYh3EgMTNrQqdOdUHhlFPq0jdvhldfbdyCueceePvtunxdu+ZegGzvvaFjx7avT7F4sN3MbCuJSB6szDXQX11dl2+nnZoeh+nWrXTlb8iD7WZmbUyCXXZJtsMOq39s7Vr4xz/qB5cFC2DOnGSJ5YyhQ3N3k/Xv37Z12RJFDSSSjgd+RrKa4Y0R8YMGx88DLgA2AeuA6RGxUNJU4BtZWccAFRExP12SdyCQ6aE8NiLeKmY9zMwK1aMHHHhgsmX78ENYsqRxC+aJJ+qPw/Tv3/Q4TKkfuCzmmu1lJOurHwNUk6yvfmZELMzK0zMi3ktfTwa+FBHHN7jOaOC+iNgr3X+cdG33fMviri0za282b4ZXXsndTbZmTV2+7t1zj8PstVfShVaIbaFrawKwJCKWpgWaDZxMsg47AJkgkuoG5IpqZwKzc6SbmW23OnSAYcOS7WMfq0uPgLfeahxc/vhH+NWv6vJ17JhMcvmb3yQPXhZTMQPJIOC1rP1qYGLDTJIuAL4GdAKOzHGdM0gCULabJW0C7gG+GzmaVZKmA9MBhg4d2prym5ltc6RkHZddd4XDD69/7L33Go/DtMUzLiUfbI+I64DrJJ0FXAp8NnNM0kRgQ0T8PeuUqRGxXFIPkkDyGeC2HNedCcyEpGuriFUwM9sm9OwJEyYkW1sq5qMyy4EhWfuD07SmzAY+0SBtCnBndkJELE9/rgXuIOlCMzOzEilmIJkLDJc0TFInkqAwJzuDpOFZux8HFmcd6wCcTtb4iKSdJPVPX3cETgSyWytmZtbGita1FRE1kmYAD5Pc/ntTRCyQdAVQFRFzgBmSjgY2AmvI6tYCDgVeywzWp3YGHk6DSBnwCHBDsepgZmYt85PtZmaWU763/+4A04mZmVkxOZCYmVlBHEjMzKwgDiRmZlaQHWKwXdJK4JVWnt4fWNViru2L67xjcJ23f4XWd4+IaPHZ+B0ikBRCUlU+dy1sT1znHYPrvP1rq/q6a8vMzAriQGJmZgVxIGnZzFIXoARc5x2D67z9a5P6eozEzMwK4haJmZkVxIHEzMwK4kACSLpJ0luSck5Jr8S1kpZIel5SRVuXcWvLo85T07q+IOnPksa2dRm3tpbqnJXvQEk1kk5rq7IVSz51lnS4pPmSFkj6U1uWrxjy+LfdS9IDkp5L6/y5ti7j1iRpiKTHJC1M63NRjjxF/Q5zIEncAhzfzPETgOHpNh24vg3KVGy30HydXwYOi4jRwJVsH4OUt9B8nZFUBvwQ+N+2KFAbuIVm6iypN/BfwOSI2B/4VBuVq5huofnf8wXAwogYCxwO/Ee6ZlJ7VQP8W0SMBA4CLpA0skGeon6HOZAAEfEE8HYzWU4GbovE00BvSQPbpnTF0VKdI+LPEbEm3X2aZIXLdi2P3zPAl0mWcH6r+CUqvjzqfBbwm4h4Nc3f7uudR50D6CFJQPc0b01blK0YImJFRPwtfb0WWAQMapCtqN9hDiT5GQS8lrVfTeNf1PbsC8BDpS5EsUkaBHyS7aPFma99gD6SHpc0T9LZpS5QG/g5MAJ4HXgBuCgiNpe2SFuHpHLgAOCZBoeK+h1WtBUSbfsg6QiSQDKp1GVpA9cA34qIzckfqzuEnYDxwFFAF+Avkp6OiJdKW6yiOg6YDxwJ7AX8QdKTEfFeaYtVGEndSVrTX2nrujiQ5Gc5MCRrf3Catl2TNAa4ETghIlaXujxtoBKYnQaR/sDHJNVExH2lLVZRVQOrI2I9sF7SE8BYYHsOJJ8DfhDJQ3RLJL0M7Af8tbTFar10+fF7gFkR8ZscWYr6HeaurfzMAc5O73w4CHg3IlaUulDFJGko8BvgM9v5X6e1ImJYRJRHRDlwN/Cl7TyIANwPTJK0k6SuwESSPvbt2askLTAk7QrsCywtaYkKkI71/BJYFBFXN5GtqN9hbpEAku4kuXujv6Rq4DKgI0BE/DfwO+BjwBJgA8lfNO1aHnX+DtAP+K/0L/Sa9j5rah513u60VOeIWCTp98DzwGbgxoho9vbobV0ev+crgVskvQCIpDuzPU8tfzDwGeAFSfPTtG8DQ6FtvsM8RYqZmRXEXVtmZlYQBxIzMyuIA4mZmRXEgcTMzAriQGJmZgVxIDFrJUmb0llzM9vFW/Ha5S3NUmy2rfBzJGat935EjCt1IcxKzS0Ss61M0jJJP0rXcvmrpL3T9HJJf0zXg3g0nT0ASbtKujddH+M5Sf+aXqpM0g3pGhP/K6lLmv/CdO2J5yXNLlE1zWo5kJi1XpcGXVtnZB17N13L5eckk0EC/Cdwa0SMAWYB16bp1wJ/StfHqAAWpOnDgevSdULeAU5N0y8GDkivc16xKmeWLz/ZbtZKktZFRPcc6cuAIyNiaTqZ3hsR0U/SKmBgRGxM01dERH9JK4HBEfFh1jXKgT9ExPB0/1tAx4j4bjqlyTrgPuC+iFhX5KqaNcstErPiiCZeb4kPs15vom5M8+PAdSStl7mSPNZpJeVAYlYcZ2T9/Ev6+s/AlPT1VODJ9PWjwPmQLPUrqVdTF5XUARgSEY8B3wJ6kazyZ1Yy/kvGrPW6ZM22CvD7iMjcAtxH0vMkrYoz07QvAzdL+gawkroZWC8CZkr6AknL43ygqSm+y4Db02Aj4NqIeGer1cisFTxGYraVpWMkle18anKzvLlry8zMCuIWiZmZFcQtEjMzK4gDiZmZFcSBxMzMCuJAYmZmBXEgMTOzgvx/vJeO/0HTw7oAAAAASUVORK5CYII=\n",
      "text/plain": [
       "<Figure size 432x288 with 1 Axes>"
      ]
     },
     "metadata": {
      "needs_background": "light"
     },
     "output_type": "display_data"
    }
   ],
   "source": [
    "plt.clf()   # clear figure\n",
    "acc_values = history.history['acc']\n",
    "val_acc_values = history.history['val_acc']\n",
    "\n",
    "plt.plot(epochs, acc, 'bo', label='Training acc')\n",
    "plt.plot(epochs, val_acc, 'b', label='Validation acc')\n",
    "plt.title('Training and validation accuracy')\n",
    "plt.xlabel('Epochs')\n",
    "plt.ylabel('Accuracy')\n",
    "plt.legend()\n",
    "\n",
    "plt.show()"
   ]
  },
  {
   "cell_type": "code",
   "execution_count": 33,
   "metadata": {},
   "outputs": [],
   "source": [
    "news_content = \"\"\"HONG KONG: Asian markets started 2015 on an upswing in limited trading on Friday, with mainland Chinese business stocks surging in Hong Kong on speculation Beijing may ease monetary policy to boost slowing growth.Hong Kong rose 1.07 percent, closing 252.78 points higher at 23857.82.Seoul closed up 0.57 percent, rising 10.85 points to 1,926.44, while Sydney gained 0.46 percent, or 24.89 points, to close at 5,435.9.Singapore edged up 0.19 percent, gaining 6.39 points to 3,371.54.Markets in mainland China, Japan, Taiwan, New Zealand, the Philippines, and Thailand remained closed for holidays.With mainland bourses shut until January 5, shares in Chinese developers and financial companies surged in Hong Kong, stoked by hopes that Beijing could ease monetary policy to support lagging growth in the world´s second-largest economy.China Vanke, the country´s biggest developer by sales, leapt 10.8 percent and the People´s Insurance Company (Group) of China Ltd. was up 5.51 percent in afternoon trading.Train-builders CSR Corp. and China CNR Corp. soared -- CSR by 16.5 percent and China CNR by 16.0 percent -- extending gains on December 31 after they announced a merger agreement.China´s manufacturing growth dropped in December to its lowest level of 2014, an official survey showed Thursday, as the sector struggles with weak domestic demand.China´s official Purchasing Managers´ Index (PMI) released by the National Bureau of Statistics (NBS) came in at 50.1 last month, down from 50.3 recorded in November.The index, which tracks activity in factories and workshops, is considered a key indicator of the health of China´s economy, a major driver of global growth. A figure above 50 signals expansion, while anything below indicates contraction.\"\"Growth momentum is still insufficient,\"\" NBS said in a statement. - Investors eye US factory data -On forex markets the dollar extended gains ahead of the release of American factory data due later on Friday and following a steady stream of good news from the world´s biggest economy.The dollar bought 120.44 yen, compared to 119.44 yen in final 2014 trading on Wednesday.Wall Street toasted a banner year in 2014, with US equity markets finishing near all-time highs.The euro meanwhile slipped amid growing expectations that the European Central Bank, which meets on January 22, will start buying sovereign bonds. The single currency bought $1.2061 compared to $1.2160 in pre-holiday trade.The ECB has already used several tools to push inflation in member nations back up to the 2.0 percent annual rate it regards as healthy, including asset purchases and making cheap loans available to banks.It is also examining the possibility of large-scale purchases of sovereign debt -- so-called quantitative easing (QE) -- to help jump-start the European Union´s moribund economy.Oil prices rose on Friday, with US benchmark West Texas Intermediate for February delivery rising 44 cents to $54.07 and Brent crude for February gaining 18 cents to $57.51.\"\"The gains in Asian trading are likely because of the positive US crude stockpiles data released on Wednesday,\"\" Daniel Ang, investment analyst at Phillip Futures in Singapore, told AFP.US crude reserves fell by 1.8 million barrels in the week to December 26, the US Energy Information Administration said in its last petroleum report for 2014 released on Wednesday, boosting prices that lost nearly half their value in the second half of the year.There is growing speculation that the slide in global oil prices -- the biggest since the financial crisis in 2008 -- may have been excessive.\"\"If we do see some supply-side responses, or even if they´re anticipated over the course of this first quarter of the year, we might find that oil has in fact bottomed,\"\" Michael McCarthy, a chief strategist at CMC Markets in Sydney, told Bloomberg.Gold was at $1,182.36 an ounce, compared with $1,199.00 in end-of-year trading on Wednesday.In other markets:-- Jakarta ended up 0.30 percent, or 15.82 points, at 5,242.77.Coal firm Indo Tambangraya Megah gained 3.41 percent to 15,900 rupiah, while miner Aneka Tambang slipped 1.88 percent to 1,045 rupiah.-- Malaysia´s main stock index shed 0.48 percent, or 8.48 points, to close at 1,752.77.Malayan Banking lost 0.55 percent to 9.12 ringgit, Public Bank slipped 0.44 percent to 18.22 while Top Globe added 1.77 percent 4.60 ringgit.-- Singapore rose 0.16 percent, or 5.44 points, to 3,370.59.Agribusiness company Wilmar International gained 0.93 percent to Sg$3.27 while real estate developer Capitaland dipped 0.30 percent to Sg$3.30.-- Mumbai gained 1.38 percent, or 380.36 points, to end at 27,887.90.Housing Development Finance Corp rose 4.30 percent to 1,171.80 rupees, while Mahindra & Mahindra fell 0.92 percent to 1,224.80 rupees. (AFP) \"\"\"\n",
    "\n",
    "news2_content = \"\"\"A strong Q3 performance has boosted expectations of the SAR taking the top spot. In defiance of the subdued market environment that has seen better days, Hong Kong is well-positioned to claim the spot as the highest performing global stock exchange by end-2018 on the back of blockbuster listings and an IPO pipeline that’s fit to burst. KPMG China has revised its IPO fundraising forecast for Hong Kong from $250b to over $300b by end-2018 after a strong performance in Q3 that bucked the increasingly bearish tone of global market rattled by trade jitters. Also read: Hong Kong raises record US$19.2b in summer IPO haul The Main Board hauled $190b in proceeds from 40 new listings in Q3 alone, smashing the full-year 2017 record of $122.6b thanks to China Tower’s mega $54.3b IPO. The GEM also booked a healthy performance after raising $4.6b from 67 new listings in the first three quarters of the year. Also read: Meituan Dianping raises US$4.2b in IPO priced at high end Moving forward, IPO proceeds in the Main Board are expected to hit $238.2b in the first nine months of 2018, almost triple the amount raised a year ago, according to KPMG. The number of IPOs is forecasted to balloon by 73% to 88, whilst the average deal size will also increase to $2.71b. The buoyant forecast is boosted by sweeping bourse reforms implemented by the stock exchange operator which paved the way for new economy firms and biotech firms with no record of profitability to list. “Three pre-revenue biotech companies and two with weighted voting right structures completed their IPOs by the end of Q3. We expect to see six to ten pre-revenue biotech companies list by the end of 2018 as the trend continues,” Maggie Lee, Head of Capital Markets Development Group, Hong Kong, KPMG China said in a statement. Also read: US biotech firms seeking higher valuations rush to Hong Kong The high-end manufacturing and high-tech companies are expected to retain the lead in terms of total transactions and proceeds alongside the financial services sector which is expected to eat up market share by Q4, added Louis Lau, partner, capital markets advisory group at KPMG China.\"\"\"\n",
    "\n",
    "sports_content = \"\"\"A spectator struck by a golf ball at last weekend's Ryder Cup said she has lost the sight in her right eye and is planning to sue organisers. Corine Remande, 49, had travelled to France from Egypt with her husband Raphael to watch the biennial showdown between Europe and the United States, held at Le Golf National club in Saint-Quentin-en-Yvelines just outside Paris. But the avid golf fan's holiday ended abruptly when a tee shot from American Brooks Koepka veered left, landed among a crowd of spectators on the sixth hole and hit her in the right eye. US Open champion Koepka swiftly apologised to Remande following the incident. Remande however told AFP on Monday she planned to seek legal action, claiming there was no warning from officials before the ball hurtled into the gallery.\"\"\"\n",
    "\n"
   ]
  },
  {
   "cell_type": "code",
   "execution_count": 34,
   "metadata": {},
   "outputs": [
    {
     "name": "stdout",
     "output_type": "stream",
     "text": [
      "sports_content is: sports\n",
      "news_content is: sports\n",
      "news2_content is: sports\n"
     ]
    },
    {
     "name": "stderr",
     "output_type": "stream",
     "text": [
      "Error subscribing to redis changes. Waiting before trying again\n",
      "Traceback (most recent call last):\n",
      "  File \"/usr/local/lib/python3.6/site-packages/guillotina_rediscache/utility.py\", line 34, in initialize\n",
      "    res = await self._redis.subscribe(settings['updates_channel'])\n",
      "  File \"/usr/local/lib/python3.6/site-packages/aioredis/commands/pubsub.py\", line 107, in wait_return_channels\n",
      "    res = await fut\n",
      "  File \"/usr/local/lib/python3.6/site-packages/aioredis/pool.py\", line 276, in _wait_execute_pubsub\n",
      "    conn = await self._create_new_connection(address)\n",
      "  File \"/usr/local/lib/python3.6/site-packages/aioredis/connection.py\", line 108, in create_connection\n",
      "    timeout, loop=loop)\n",
      "  File \"/usr/local/lib/python3.6/asyncio/tasks.py\", line 339, in wait_for\n",
      "    return (yield from fut)\n",
      "  File \"/usr/local/lib/python3.6/site-packages/aioredis/stream.py\", line 19, in open_connection\n",
      "    lambda: protocol, host, port, **kwds)\n",
      "  File \"/usr/local/lib/python3.6/asyncio/base_events.py\", line 778, in create_connection\n",
      "    raise exceptions[0]\n",
      "  File \"/usr/local/lib/python3.6/asyncio/base_events.py\", line 765, in create_connection\n",
      "    yield from self.sock_connect(sock, address)\n",
      "  File \"/usr/local/lib/python3.6/asyncio/selector_events.py\", line 450, in sock_connect\n",
      "    return (yield from fut)\n",
      "  File \"/usr/local/lib/python3.6/asyncio/selector_events.py\", line 480, in _sock_connect_cb\n",
      "    raise OSError(err, 'Connect call failed %s' % (address,))\n",
      "ConnectionRefusedError: [Errno 111] Connect call failed ('192.168.130.119', 6379)\n",
      "Error subscribing to redis changes. Waiting before trying again\n",
      "Traceback (most recent call last):\n",
      "  File \"/usr/local/lib/python3.6/site-packages/guillotina_rediscache/utility.py\", line 34, in initialize\n",
      "    res = await self._redis.subscribe(settings['updates_channel'])\n",
      "  File \"/usr/local/lib/python3.6/site-packages/aioredis/commands/pubsub.py\", line 107, in wait_return_channels\n",
      "    res = await fut\n",
      "  File \"/usr/local/lib/python3.6/site-packages/aioredis/pool.py\", line 276, in _wait_execute_pubsub\n",
      "    conn = await self._create_new_connection(address)\n",
      "  File \"/usr/local/lib/python3.6/site-packages/aioredis/connection.py\", line 108, in create_connection\n",
      "    timeout, loop=loop)\n",
      "  File \"/usr/local/lib/python3.6/asyncio/tasks.py\", line 339, in wait_for\n",
      "    return (yield from fut)\n",
      "  File \"/usr/local/lib/python3.6/site-packages/aioredis/stream.py\", line 19, in open_connection\n",
      "    lambda: protocol, host, port, **kwds)\n",
      "  File \"/usr/local/lib/python3.6/asyncio/base_events.py\", line 778, in create_connection\n",
      "    raise exceptions[0]\n",
      "  File \"/usr/local/lib/python3.6/asyncio/base_events.py\", line 765, in create_connection\n",
      "    yield from self.sock_connect(sock, address)\n",
      "  File \"/usr/local/lib/python3.6/asyncio/selector_events.py\", line 450, in sock_connect\n",
      "    return (yield from fut)\n",
      "  File \"/usr/local/lib/python3.6/asyncio/selector_events.py\", line 480, in _sock_connect_cb\n",
      "    raise OSError(err, 'Connect call failed %s' % (address,))\n",
      "ConnectionRefusedError: [Errno 111] Connect call failed ('192.168.130.119', 6379)\n",
      "Error subscribing to redis changes. Waiting before trying again\n",
      "Traceback (most recent call last):\n",
      "  File \"/usr/local/lib/python3.6/site-packages/guillotina_rediscache/utility.py\", line 34, in initialize\n",
      "    res = await self._redis.subscribe(settings['updates_channel'])\n",
      "  File \"/usr/local/lib/python3.6/site-packages/aioredis/commands/pubsub.py\", line 107, in wait_return_channels\n",
      "    res = await fut\n",
      "  File \"/usr/local/lib/python3.6/site-packages/aioredis/pool.py\", line 276, in _wait_execute_pubsub\n",
      "    conn = await self._create_new_connection(address)\n",
      "  File \"/usr/local/lib/python3.6/site-packages/aioredis/connection.py\", line 108, in create_connection\n",
      "    timeout, loop=loop)\n",
      "  File \"/usr/local/lib/python3.6/asyncio/tasks.py\", line 339, in wait_for\n",
      "    return (yield from fut)\n",
      "  File \"/usr/local/lib/python3.6/site-packages/aioredis/stream.py\", line 19, in open_connection\n",
      "    lambda: protocol, host, port, **kwds)\n",
      "  File \"/usr/local/lib/python3.6/asyncio/base_events.py\", line 778, in create_connection\n",
      "    raise exceptions[0]\n",
      "  File \"/usr/local/lib/python3.6/asyncio/base_events.py\", line 765, in create_connection\n",
      "    yield from self.sock_connect(sock, address)\n",
      "  File \"/usr/local/lib/python3.6/asyncio/selector_events.py\", line 450, in sock_connect\n",
      "    return (yield from fut)\n",
      "  File \"/usr/local/lib/python3.6/asyncio/selector_events.py\", line 480, in _sock_connect_cb\n",
      "    raise OSError(err, 'Connect call failed %s' % (address,))\n",
      "ConnectionRefusedError: [Errno 111] Connect call failed ('192.168.130.119', 6379)\n",
      "Error subscribing to redis changes. Waiting before trying again\n",
      "Traceback (most recent call last):\n",
      "  File \"/usr/local/lib/python3.6/site-packages/guillotina_rediscache/utility.py\", line 34, in initialize\n",
      "    res = await self._redis.subscribe(settings['updates_channel'])\n",
      "  File \"/usr/local/lib/python3.6/site-packages/aioredis/commands/pubsub.py\", line 107, in wait_return_channels\n",
      "    res = await fut\n",
      "  File \"/usr/local/lib/python3.6/site-packages/aioredis/pool.py\", line 276, in _wait_execute_pubsub\n",
      "    conn = await self._create_new_connection(address)\n",
      "  File \"/usr/local/lib/python3.6/site-packages/aioredis/connection.py\", line 108, in create_connection\n",
      "    timeout, loop=loop)\n",
      "  File \"/usr/local/lib/python3.6/asyncio/tasks.py\", line 339, in wait_for\n",
      "    return (yield from fut)\n",
      "  File \"/usr/local/lib/python3.6/site-packages/aioredis/stream.py\", line 19, in open_connection\n",
      "    lambda: protocol, host, port, **kwds)\n",
      "  File \"/usr/local/lib/python3.6/asyncio/base_events.py\", line 778, in create_connection\n",
      "    raise exceptions[0]\n",
      "  File \"/usr/local/lib/python3.6/asyncio/base_events.py\", line 765, in create_connection\n",
      "    yield from self.sock_connect(sock, address)\n",
      "  File \"/usr/local/lib/python3.6/asyncio/selector_events.py\", line 450, in sock_connect\n",
      "    return (yield from fut)\n",
      "  File \"/usr/local/lib/python3.6/asyncio/selector_events.py\", line 480, in _sock_connect_cb\n",
      "    raise OSError(err, 'Connect call failed %s' % (address,))\n",
      "ConnectionRefusedError: [Errno 111] Connect call failed ('192.168.130.119', 6379)\n",
      "Error subscribing to redis changes. Waiting before trying again\n",
      "Traceback (most recent call last):\n",
      "  File \"/usr/local/lib/python3.6/site-packages/guillotina_rediscache/utility.py\", line 34, in initialize\n",
      "    res = await self._redis.subscribe(settings['updates_channel'])\n",
      "  File \"/usr/local/lib/python3.6/site-packages/aioredis/commands/pubsub.py\", line 107, in wait_return_channels\n",
      "    res = await fut\n",
      "  File \"/usr/local/lib/python3.6/site-packages/aioredis/pool.py\", line 276, in _wait_execute_pubsub\n",
      "    conn = await self._create_new_connection(address)\n",
      "  File \"/usr/local/lib/python3.6/site-packages/aioredis/connection.py\", line 108, in create_connection\n",
      "    timeout, loop=loop)\n",
      "  File \"/usr/local/lib/python3.6/asyncio/tasks.py\", line 339, in wait_for\n",
      "    return (yield from fut)\n",
      "  File \"/usr/local/lib/python3.6/site-packages/aioredis/stream.py\", line 19, in open_connection\n",
      "    lambda: protocol, host, port, **kwds)\n",
      "  File \"/usr/local/lib/python3.6/asyncio/base_events.py\", line 778, in create_connection\n",
      "    raise exceptions[0]\n",
      "  File \"/usr/local/lib/python3.6/asyncio/base_events.py\", line 765, in create_connection\n",
      "    yield from self.sock_connect(sock, address)\n",
      "  File \"/usr/local/lib/python3.6/asyncio/selector_events.py\", line 450, in sock_connect\n",
      "    return (yield from fut)\n",
      "  File \"/usr/local/lib/python3.6/asyncio/selector_events.py\", line 480, in _sock_connect_cb\n",
      "    raise OSError(err, 'Connect call failed %s' % (address,))\n",
      "ConnectionRefusedError: [Errno 111] Connect call failed ('192.168.130.119', 6379)\n",
      "Error subscribing to redis changes. Waiting before trying again\n",
      "Traceback (most recent call last):\n",
      "  File \"/usr/local/lib/python3.6/site-packages/guillotina_rediscache/utility.py\", line 34, in initialize\n",
      "    res = await self._redis.subscribe(settings['updates_channel'])\n",
      "  File \"/usr/local/lib/python3.6/site-packages/aioredis/commands/pubsub.py\", line 107, in wait_return_channels\n",
      "    res = await fut\n",
      "  File \"/usr/local/lib/python3.6/site-packages/aioredis/pool.py\", line 276, in _wait_execute_pubsub\n",
      "    conn = await self._create_new_connection(address)\n",
      "  File \"/usr/local/lib/python3.6/site-packages/aioredis/connection.py\", line 108, in create_connection\n",
      "    timeout, loop=loop)\n",
      "  File \"/usr/local/lib/python3.6/asyncio/tasks.py\", line 339, in wait_for\n",
      "    return (yield from fut)\n",
      "  File \"/usr/local/lib/python3.6/site-packages/aioredis/stream.py\", line 19, in open_connection\n",
      "    lambda: protocol, host, port, **kwds)\n",
      "  File \"/usr/local/lib/python3.6/asyncio/base_events.py\", line 778, in create_connection\n",
      "    raise exceptions[0]\n",
      "  File \"/usr/local/lib/python3.6/asyncio/base_events.py\", line 765, in create_connection\n",
      "    yield from self.sock_connect(sock, address)\n",
      "  File \"/usr/local/lib/python3.6/asyncio/selector_events.py\", line 450, in sock_connect\n",
      "    return (yield from fut)\n",
      "  File \"/usr/local/lib/python3.6/asyncio/selector_events.py\", line 480, in _sock_connect_cb\n",
      "    raise OSError(err, 'Connect call failed %s' % (address,))\n",
      "ConnectionRefusedError: [Errno 111] Connect call failed ('192.168.130.119', 6379)\n"
     ]
    },
    {
     "name": "stderr",
     "output_type": "stream",
     "text": [
      "Error subscribing to redis changes. Waiting before trying again\n",
      "Traceback (most recent call last):\n",
      "  File \"/usr/local/lib/python3.6/site-packages/guillotina_rediscache/utility.py\", line 34, in initialize\n",
      "    res = await self._redis.subscribe(settings['updates_channel'])\n",
      "  File \"/usr/local/lib/python3.6/site-packages/aioredis/commands/pubsub.py\", line 107, in wait_return_channels\n",
      "    res = await fut\n",
      "  File \"/usr/local/lib/python3.6/site-packages/aioredis/pool.py\", line 276, in _wait_execute_pubsub\n",
      "    conn = await self._create_new_connection(address)\n",
      "  File \"/usr/local/lib/python3.6/site-packages/aioredis/connection.py\", line 108, in create_connection\n",
      "    timeout, loop=loop)\n",
      "  File \"/usr/local/lib/python3.6/asyncio/tasks.py\", line 339, in wait_for\n",
      "    return (yield from fut)\n",
      "  File \"/usr/local/lib/python3.6/site-packages/aioredis/stream.py\", line 19, in open_connection\n",
      "    lambda: protocol, host, port, **kwds)\n",
      "  File \"/usr/local/lib/python3.6/asyncio/base_events.py\", line 778, in create_connection\n",
      "    raise exceptions[0]\n",
      "  File \"/usr/local/lib/python3.6/asyncio/base_events.py\", line 765, in create_connection\n",
      "    yield from self.sock_connect(sock, address)\n",
      "  File \"/usr/local/lib/python3.6/asyncio/selector_events.py\", line 450, in sock_connect\n",
      "    return (yield from fut)\n",
      "  File \"/usr/local/lib/python3.6/asyncio/selector_events.py\", line 480, in _sock_connect_cb\n",
      "    raise OSError(err, 'Connect call failed %s' % (address,))\n",
      "ConnectionRefusedError: [Errno 111] Connect call failed ('192.168.130.119', 6379)\n",
      "Error subscribing to redis changes. Waiting before trying again\n",
      "Traceback (most recent call last):\n",
      "  File \"/usr/local/lib/python3.6/site-packages/guillotina_rediscache/utility.py\", line 34, in initialize\n",
      "    res = await self._redis.subscribe(settings['updates_channel'])\n",
      "  File \"/usr/local/lib/python3.6/site-packages/aioredis/commands/pubsub.py\", line 107, in wait_return_channels\n",
      "    res = await fut\n",
      "  File \"/usr/local/lib/python3.6/site-packages/aioredis/pool.py\", line 276, in _wait_execute_pubsub\n",
      "    conn = await self._create_new_connection(address)\n",
      "  File \"/usr/local/lib/python3.6/site-packages/aioredis/connection.py\", line 108, in create_connection\n",
      "    timeout, loop=loop)\n",
      "  File \"/usr/local/lib/python3.6/asyncio/tasks.py\", line 339, in wait_for\n",
      "    return (yield from fut)\n",
      "  File \"/usr/local/lib/python3.6/site-packages/aioredis/stream.py\", line 19, in open_connection\n",
      "    lambda: protocol, host, port, **kwds)\n",
      "  File \"/usr/local/lib/python3.6/asyncio/base_events.py\", line 778, in create_connection\n",
      "    raise exceptions[0]\n",
      "  File \"/usr/local/lib/python3.6/asyncio/base_events.py\", line 765, in create_connection\n",
      "    yield from self.sock_connect(sock, address)\n",
      "  File \"/usr/local/lib/python3.6/asyncio/selector_events.py\", line 450, in sock_connect\n",
      "    return (yield from fut)\n",
      "  File \"/usr/local/lib/python3.6/asyncio/selector_events.py\", line 480, in _sock_connect_cb\n",
      "    raise OSError(err, 'Connect call failed %s' % (address,))\n",
      "ConnectionRefusedError: [Errno 111] Connect call failed ('192.168.130.119', 6379)\n",
      "Error subscribing to redis changes. Waiting before trying again\n",
      "Traceback (most recent call last):\n",
      "  File \"/usr/local/lib/python3.6/site-packages/guillotina_rediscache/utility.py\", line 34, in initialize\n",
      "    res = await self._redis.subscribe(settings['updates_channel'])\n",
      "  File \"/usr/local/lib/python3.6/site-packages/aioredis/commands/pubsub.py\", line 107, in wait_return_channels\n",
      "    res = await fut\n",
      "  File \"/usr/local/lib/python3.6/site-packages/aioredis/pool.py\", line 276, in _wait_execute_pubsub\n",
      "    conn = await self._create_new_connection(address)\n",
      "  File \"/usr/local/lib/python3.6/site-packages/aioredis/connection.py\", line 108, in create_connection\n",
      "    timeout, loop=loop)\n",
      "  File \"/usr/local/lib/python3.6/asyncio/tasks.py\", line 339, in wait_for\n",
      "    return (yield from fut)\n",
      "  File \"/usr/local/lib/python3.6/site-packages/aioredis/stream.py\", line 19, in open_connection\n",
      "    lambda: protocol, host, port, **kwds)\n",
      "  File \"/usr/local/lib/python3.6/asyncio/base_events.py\", line 778, in create_connection\n",
      "    raise exceptions[0]\n",
      "  File \"/usr/local/lib/python3.6/asyncio/base_events.py\", line 765, in create_connection\n",
      "    yield from self.sock_connect(sock, address)\n",
      "  File \"/usr/local/lib/python3.6/asyncio/selector_events.py\", line 450, in sock_connect\n",
      "    return (yield from fut)\n",
      "  File \"/usr/local/lib/python3.6/asyncio/selector_events.py\", line 480, in _sock_connect_cb\n",
      "    raise OSError(err, 'Connect call failed %s' % (address,))\n",
      "ConnectionRefusedError: [Errno 111] Connect call failed ('192.168.130.119', 6379)\n",
      "Error subscribing to redis changes. Waiting before trying again\n",
      "Traceback (most recent call last):\n",
      "  File \"/usr/local/lib/python3.6/site-packages/guillotina_rediscache/utility.py\", line 34, in initialize\n",
      "    res = await self._redis.subscribe(settings['updates_channel'])\n",
      "  File \"/usr/local/lib/python3.6/site-packages/aioredis/commands/pubsub.py\", line 107, in wait_return_channels\n",
      "    res = await fut\n",
      "  File \"/usr/local/lib/python3.6/site-packages/aioredis/pool.py\", line 276, in _wait_execute_pubsub\n",
      "    conn = await self._create_new_connection(address)\n",
      "  File \"/usr/local/lib/python3.6/site-packages/aioredis/connection.py\", line 108, in create_connection\n",
      "    timeout, loop=loop)\n",
      "  File \"/usr/local/lib/python3.6/asyncio/tasks.py\", line 339, in wait_for\n",
      "    return (yield from fut)\n",
      "  File \"/usr/local/lib/python3.6/site-packages/aioredis/stream.py\", line 19, in open_connection\n",
      "    lambda: protocol, host, port, **kwds)\n",
      "  File \"/usr/local/lib/python3.6/asyncio/base_events.py\", line 778, in create_connection\n",
      "    raise exceptions[0]\n",
      "  File \"/usr/local/lib/python3.6/asyncio/base_events.py\", line 765, in create_connection\n",
      "    yield from self.sock_connect(sock, address)\n",
      "  File \"/usr/local/lib/python3.6/asyncio/selector_events.py\", line 450, in sock_connect\n",
      "    return (yield from fut)\n",
      "  File \"/usr/local/lib/python3.6/asyncio/selector_events.py\", line 480, in _sock_connect_cb\n",
      "    raise OSError(err, 'Connect call failed %s' % (address,))\n",
      "ConnectionRefusedError: [Errno 111] Connect call failed ('192.168.130.119', 6379)\n",
      "Error subscribing to redis changes. Waiting before trying again\n",
      "Traceback (most recent call last):\n",
      "  File \"/usr/local/lib/python3.6/site-packages/guillotina_rediscache/utility.py\", line 34, in initialize\n",
      "    res = await self._redis.subscribe(settings['updates_channel'])\n",
      "  File \"/usr/local/lib/python3.6/site-packages/aioredis/commands/pubsub.py\", line 107, in wait_return_channels\n",
      "    res = await fut\n",
      "  File \"/usr/local/lib/python3.6/site-packages/aioredis/pool.py\", line 276, in _wait_execute_pubsub\n",
      "    conn = await self._create_new_connection(address)\n",
      "  File \"/usr/local/lib/python3.6/site-packages/aioredis/connection.py\", line 108, in create_connection\n",
      "    timeout, loop=loop)\n",
      "  File \"/usr/local/lib/python3.6/asyncio/tasks.py\", line 339, in wait_for\n",
      "    return (yield from fut)\n",
      "  File \"/usr/local/lib/python3.6/site-packages/aioredis/stream.py\", line 19, in open_connection\n",
      "    lambda: protocol, host, port, **kwds)\n",
      "  File \"/usr/local/lib/python3.6/asyncio/base_events.py\", line 778, in create_connection\n",
      "    raise exceptions[0]\n",
      "  File \"/usr/local/lib/python3.6/asyncio/base_events.py\", line 765, in create_connection\n",
      "    yield from self.sock_connect(sock, address)\n",
      "  File \"/usr/local/lib/python3.6/asyncio/selector_events.py\", line 450, in sock_connect\n",
      "    return (yield from fut)\n",
      "  File \"/usr/local/lib/python3.6/asyncio/selector_events.py\", line 480, in _sock_connect_cb\n",
      "    raise OSError(err, 'Connect call failed %s' % (address,))\n",
      "ConnectionRefusedError: [Errno 111] Connect call failed ('192.168.130.119', 6379)\n",
      "Error subscribing to redis changes. Waiting before trying again\n",
      "Traceback (most recent call last):\n",
      "  File \"/usr/local/lib/python3.6/site-packages/guillotina_rediscache/utility.py\", line 34, in initialize\n",
      "    res = await self._redis.subscribe(settings['updates_channel'])\n",
      "  File \"/usr/local/lib/python3.6/site-packages/aioredis/commands/pubsub.py\", line 107, in wait_return_channels\n",
      "    res = await fut\n",
      "  File \"/usr/local/lib/python3.6/site-packages/aioredis/pool.py\", line 276, in _wait_execute_pubsub\n",
      "    conn = await self._create_new_connection(address)\n",
      "  File \"/usr/local/lib/python3.6/site-packages/aioredis/connection.py\", line 108, in create_connection\n",
      "    timeout, loop=loop)\n",
      "  File \"/usr/local/lib/python3.6/asyncio/tasks.py\", line 339, in wait_for\n",
      "    return (yield from fut)\n",
      "  File \"/usr/local/lib/python3.6/site-packages/aioredis/stream.py\", line 19, in open_connection\n",
      "    lambda: protocol, host, port, **kwds)\n",
      "  File \"/usr/local/lib/python3.6/asyncio/base_events.py\", line 778, in create_connection\n",
      "    raise exceptions[0]\n",
      "  File \"/usr/local/lib/python3.6/asyncio/base_events.py\", line 765, in create_connection\n",
      "    yield from self.sock_connect(sock, address)\n",
      "  File \"/usr/local/lib/python3.6/asyncio/selector_events.py\", line 450, in sock_connect\n",
      "    return (yield from fut)\n",
      "  File \"/usr/local/lib/python3.6/asyncio/selector_events.py\", line 480, in _sock_connect_cb\n",
      "    raise OSError(err, 'Connect call failed %s' % (address,))\n",
      "ConnectionRefusedError: [Errno 111] Connect call failed ('192.168.130.119', 6379)\n"
     ]
    },
    {
     "name": "stderr",
     "output_type": "stream",
     "text": [
      "Error subscribing to redis changes. Waiting before trying again\n",
      "Traceback (most recent call last):\n",
      "  File \"/usr/local/lib/python3.6/site-packages/guillotina_rediscache/utility.py\", line 34, in initialize\n",
      "    res = await self._redis.subscribe(settings['updates_channel'])\n",
      "  File \"/usr/local/lib/python3.6/site-packages/aioredis/commands/pubsub.py\", line 107, in wait_return_channels\n",
      "    res = await fut\n",
      "  File \"/usr/local/lib/python3.6/site-packages/aioredis/pool.py\", line 276, in _wait_execute_pubsub\n",
      "    conn = await self._create_new_connection(address)\n",
      "  File \"/usr/local/lib/python3.6/site-packages/aioredis/connection.py\", line 108, in create_connection\n",
      "    timeout, loop=loop)\n",
      "  File \"/usr/local/lib/python3.6/asyncio/tasks.py\", line 339, in wait_for\n",
      "    return (yield from fut)\n",
      "  File \"/usr/local/lib/python3.6/site-packages/aioredis/stream.py\", line 19, in open_connection\n",
      "    lambda: protocol, host, port, **kwds)\n",
      "  File \"/usr/local/lib/python3.6/asyncio/base_events.py\", line 778, in create_connection\n",
      "    raise exceptions[0]\n",
      "  File \"/usr/local/lib/python3.6/asyncio/base_events.py\", line 765, in create_connection\n",
      "    yield from self.sock_connect(sock, address)\n",
      "  File \"/usr/local/lib/python3.6/asyncio/selector_events.py\", line 450, in sock_connect\n",
      "    return (yield from fut)\n",
      "  File \"/usr/local/lib/python3.6/asyncio/selector_events.py\", line 480, in _sock_connect_cb\n",
      "    raise OSError(err, 'Connect call failed %s' % (address,))\n",
      "ConnectionRefusedError: [Errno 111] Connect call failed ('192.168.130.119', 6379)\n",
      "Error subscribing to redis changes. Waiting before trying again\n",
      "Traceback (most recent call last):\n",
      "  File \"/usr/local/lib/python3.6/site-packages/guillotina_rediscache/utility.py\", line 34, in initialize\n",
      "    res = await self._redis.subscribe(settings['updates_channel'])\n",
      "  File \"/usr/local/lib/python3.6/site-packages/aioredis/commands/pubsub.py\", line 107, in wait_return_channels\n",
      "    res = await fut\n",
      "  File \"/usr/local/lib/python3.6/site-packages/aioredis/pool.py\", line 276, in _wait_execute_pubsub\n",
      "    conn = await self._create_new_connection(address)\n",
      "  File \"/usr/local/lib/python3.6/site-packages/aioredis/connection.py\", line 108, in create_connection\n",
      "    timeout, loop=loop)\n",
      "  File \"/usr/local/lib/python3.6/asyncio/tasks.py\", line 339, in wait_for\n",
      "    return (yield from fut)\n",
      "  File \"/usr/local/lib/python3.6/site-packages/aioredis/stream.py\", line 19, in open_connection\n",
      "    lambda: protocol, host, port, **kwds)\n",
      "  File \"/usr/local/lib/python3.6/asyncio/base_events.py\", line 778, in create_connection\n",
      "    raise exceptions[0]\n",
      "  File \"/usr/local/lib/python3.6/asyncio/base_events.py\", line 765, in create_connection\n",
      "    yield from self.sock_connect(sock, address)\n",
      "  File \"/usr/local/lib/python3.6/asyncio/selector_events.py\", line 450, in sock_connect\n",
      "    return (yield from fut)\n",
      "  File \"/usr/local/lib/python3.6/asyncio/selector_events.py\", line 480, in _sock_connect_cb\n",
      "    raise OSError(err, 'Connect call failed %s' % (address,))\n",
      "ConnectionRefusedError: [Errno 111] Connect call failed ('192.168.130.119', 6379)\n",
      "Error subscribing to redis changes. Waiting before trying again\n",
      "Traceback (most recent call last):\n",
      "  File \"/usr/local/lib/python3.6/site-packages/guillotina_rediscache/utility.py\", line 34, in initialize\n",
      "    res = await self._redis.subscribe(settings['updates_channel'])\n",
      "  File \"/usr/local/lib/python3.6/site-packages/aioredis/commands/pubsub.py\", line 107, in wait_return_channels\n",
      "    res = await fut\n",
      "  File \"/usr/local/lib/python3.6/site-packages/aioredis/pool.py\", line 276, in _wait_execute_pubsub\n",
      "    conn = await self._create_new_connection(address)\n",
      "  File \"/usr/local/lib/python3.6/site-packages/aioredis/connection.py\", line 108, in create_connection\n",
      "    timeout, loop=loop)\n",
      "  File \"/usr/local/lib/python3.6/asyncio/tasks.py\", line 339, in wait_for\n",
      "    return (yield from fut)\n",
      "  File \"/usr/local/lib/python3.6/site-packages/aioredis/stream.py\", line 19, in open_connection\n",
      "    lambda: protocol, host, port, **kwds)\n",
      "  File \"/usr/local/lib/python3.6/asyncio/base_events.py\", line 778, in create_connection\n",
      "    raise exceptions[0]\n",
      "  File \"/usr/local/lib/python3.6/asyncio/base_events.py\", line 765, in create_connection\n",
      "    yield from self.sock_connect(sock, address)\n",
      "  File \"/usr/local/lib/python3.6/asyncio/selector_events.py\", line 450, in sock_connect\n",
      "    return (yield from fut)\n",
      "  File \"/usr/local/lib/python3.6/asyncio/selector_events.py\", line 480, in _sock_connect_cb\n",
      "    raise OSError(err, 'Connect call failed %s' % (address,))\n",
      "ConnectionRefusedError: [Errno 111] Connect call failed ('192.168.130.119', 6379)\n",
      "Error subscribing to redis changes. Waiting before trying again\n",
      "Traceback (most recent call last):\n",
      "  File \"/usr/local/lib/python3.6/site-packages/guillotina_rediscache/utility.py\", line 34, in initialize\n",
      "    res = await self._redis.subscribe(settings['updates_channel'])\n",
      "  File \"/usr/local/lib/python3.6/site-packages/aioredis/commands/pubsub.py\", line 107, in wait_return_channels\n",
      "    res = await fut\n",
      "  File \"/usr/local/lib/python3.6/site-packages/aioredis/pool.py\", line 276, in _wait_execute_pubsub\n",
      "    conn = await self._create_new_connection(address)\n",
      "  File \"/usr/local/lib/python3.6/site-packages/aioredis/connection.py\", line 108, in create_connection\n",
      "    timeout, loop=loop)\n",
      "  File \"/usr/local/lib/python3.6/asyncio/tasks.py\", line 339, in wait_for\n",
      "    return (yield from fut)\n",
      "  File \"/usr/local/lib/python3.6/site-packages/aioredis/stream.py\", line 19, in open_connection\n",
      "    lambda: protocol, host, port, **kwds)\n",
      "  File \"/usr/local/lib/python3.6/asyncio/base_events.py\", line 778, in create_connection\n",
      "    raise exceptions[0]\n",
      "  File \"/usr/local/lib/python3.6/asyncio/base_events.py\", line 765, in create_connection\n",
      "    yield from self.sock_connect(sock, address)\n",
      "  File \"/usr/local/lib/python3.6/asyncio/selector_events.py\", line 450, in sock_connect\n",
      "    return (yield from fut)\n",
      "  File \"/usr/local/lib/python3.6/asyncio/selector_events.py\", line 480, in _sock_connect_cb\n",
      "    raise OSError(err, 'Connect call failed %s' % (address,))\n",
      "ConnectionRefusedError: [Errno 111] Connect call failed ('192.168.130.119', 6379)\n",
      "Error subscribing to redis changes. Waiting before trying again\n",
      "Traceback (most recent call last):\n",
      "  File \"/usr/local/lib/python3.6/site-packages/guillotina_rediscache/utility.py\", line 34, in initialize\n",
      "    res = await self._redis.subscribe(settings['updates_channel'])\n",
      "  File \"/usr/local/lib/python3.6/site-packages/aioredis/commands/pubsub.py\", line 107, in wait_return_channels\n",
      "    res = await fut\n",
      "  File \"/usr/local/lib/python3.6/site-packages/aioredis/pool.py\", line 276, in _wait_execute_pubsub\n",
      "    conn = await self._create_new_connection(address)\n",
      "  File \"/usr/local/lib/python3.6/site-packages/aioredis/connection.py\", line 108, in create_connection\n",
      "    timeout, loop=loop)\n",
      "  File \"/usr/local/lib/python3.6/asyncio/tasks.py\", line 339, in wait_for\n",
      "    return (yield from fut)\n",
      "  File \"/usr/local/lib/python3.6/site-packages/aioredis/stream.py\", line 19, in open_connection\n",
      "    lambda: protocol, host, port, **kwds)\n",
      "  File \"/usr/local/lib/python3.6/asyncio/base_events.py\", line 778, in create_connection\n",
      "    raise exceptions[0]\n",
      "  File \"/usr/local/lib/python3.6/asyncio/base_events.py\", line 765, in create_connection\n",
      "    yield from self.sock_connect(sock, address)\n",
      "  File \"/usr/local/lib/python3.6/asyncio/selector_events.py\", line 450, in sock_connect\n",
      "    return (yield from fut)\n",
      "  File \"/usr/local/lib/python3.6/asyncio/selector_events.py\", line 480, in _sock_connect_cb\n",
      "    raise OSError(err, 'Connect call failed %s' % (address,))\n",
      "ConnectionRefusedError: [Errno 111] Connect call failed ('192.168.130.119', 6379)\n",
      "Error subscribing to redis changes. Waiting before trying again\n",
      "Traceback (most recent call last):\n",
      "  File \"/usr/local/lib/python3.6/site-packages/guillotina_rediscache/utility.py\", line 34, in initialize\n",
      "    res = await self._redis.subscribe(settings['updates_channel'])\n",
      "  File \"/usr/local/lib/python3.6/site-packages/aioredis/commands/pubsub.py\", line 107, in wait_return_channels\n",
      "    res = await fut\n",
      "  File \"/usr/local/lib/python3.6/site-packages/aioredis/pool.py\", line 276, in _wait_execute_pubsub\n",
      "    conn = await self._create_new_connection(address)\n",
      "  File \"/usr/local/lib/python3.6/site-packages/aioredis/connection.py\", line 108, in create_connection\n",
      "    timeout, loop=loop)\n",
      "  File \"/usr/local/lib/python3.6/asyncio/tasks.py\", line 339, in wait_for\n",
      "    return (yield from fut)\n",
      "  File \"/usr/local/lib/python3.6/site-packages/aioredis/stream.py\", line 19, in open_connection\n",
      "    lambda: protocol, host, port, **kwds)\n",
      "  File \"/usr/local/lib/python3.6/asyncio/base_events.py\", line 778, in create_connection\n",
      "    raise exceptions[0]\n",
      "  File \"/usr/local/lib/python3.6/asyncio/base_events.py\", line 765, in create_connection\n",
      "    yield from self.sock_connect(sock, address)\n",
      "  File \"/usr/local/lib/python3.6/asyncio/selector_events.py\", line 450, in sock_connect\n",
      "    return (yield from fut)\n",
      "  File \"/usr/local/lib/python3.6/asyncio/selector_events.py\", line 480, in _sock_connect_cb\n",
      "    raise OSError(err, 'Connect call failed %s' % (address,))\n",
      "ConnectionRefusedError: [Errno 111] Connect call failed ('192.168.130.119', 6379)\n"
     ]
    },
    {
     "name": "stderr",
     "output_type": "stream",
     "text": [
      "Error subscribing to redis changes. Waiting before trying again\n",
      "Traceback (most recent call last):\n",
      "  File \"/usr/local/lib/python3.6/site-packages/guillotina_rediscache/utility.py\", line 34, in initialize\n",
      "    res = await self._redis.subscribe(settings['updates_channel'])\n",
      "  File \"/usr/local/lib/python3.6/site-packages/aioredis/commands/pubsub.py\", line 107, in wait_return_channels\n",
      "    res = await fut\n",
      "  File \"/usr/local/lib/python3.6/site-packages/aioredis/pool.py\", line 276, in _wait_execute_pubsub\n",
      "    conn = await self._create_new_connection(address)\n",
      "  File \"/usr/local/lib/python3.6/site-packages/aioredis/connection.py\", line 108, in create_connection\n",
      "    timeout, loop=loop)\n",
      "  File \"/usr/local/lib/python3.6/asyncio/tasks.py\", line 339, in wait_for\n",
      "    return (yield from fut)\n",
      "  File \"/usr/local/lib/python3.6/site-packages/aioredis/stream.py\", line 19, in open_connection\n",
      "    lambda: protocol, host, port, **kwds)\n",
      "  File \"/usr/local/lib/python3.6/asyncio/base_events.py\", line 778, in create_connection\n",
      "    raise exceptions[0]\n",
      "  File \"/usr/local/lib/python3.6/asyncio/base_events.py\", line 765, in create_connection\n",
      "    yield from self.sock_connect(sock, address)\n",
      "  File \"/usr/local/lib/python3.6/asyncio/selector_events.py\", line 450, in sock_connect\n",
      "    return (yield from fut)\n",
      "  File \"/usr/local/lib/python3.6/asyncio/selector_events.py\", line 480, in _sock_connect_cb\n",
      "    raise OSError(err, 'Connect call failed %s' % (address,))\n",
      "ConnectionRefusedError: [Errno 111] Connect call failed ('192.168.130.119', 6379)\n",
      "Error subscribing to redis changes. Waiting before trying again\n",
      "Traceback (most recent call last):\n",
      "  File \"/usr/local/lib/python3.6/site-packages/guillotina_rediscache/utility.py\", line 34, in initialize\n",
      "    res = await self._redis.subscribe(settings['updates_channel'])\n",
      "  File \"/usr/local/lib/python3.6/site-packages/aioredis/commands/pubsub.py\", line 107, in wait_return_channels\n",
      "    res = await fut\n",
      "  File \"/usr/local/lib/python3.6/site-packages/aioredis/pool.py\", line 276, in _wait_execute_pubsub\n",
      "    conn = await self._create_new_connection(address)\n",
      "  File \"/usr/local/lib/python3.6/site-packages/aioredis/connection.py\", line 108, in create_connection\n",
      "    timeout, loop=loop)\n",
      "  File \"/usr/local/lib/python3.6/asyncio/tasks.py\", line 339, in wait_for\n",
      "    return (yield from fut)\n",
      "  File \"/usr/local/lib/python3.6/site-packages/aioredis/stream.py\", line 19, in open_connection\n",
      "    lambda: protocol, host, port, **kwds)\n",
      "  File \"/usr/local/lib/python3.6/asyncio/base_events.py\", line 778, in create_connection\n",
      "    raise exceptions[0]\n",
      "  File \"/usr/local/lib/python3.6/asyncio/base_events.py\", line 765, in create_connection\n",
      "    yield from self.sock_connect(sock, address)\n",
      "  File \"/usr/local/lib/python3.6/asyncio/selector_events.py\", line 450, in sock_connect\n",
      "    return (yield from fut)\n",
      "  File \"/usr/local/lib/python3.6/asyncio/selector_events.py\", line 480, in _sock_connect_cb\n",
      "    raise OSError(err, 'Connect call failed %s' % (address,))\n",
      "ConnectionRefusedError: [Errno 111] Connect call failed ('192.168.130.119', 6379)\n",
      "Error subscribing to redis changes. Waiting before trying again\n",
      "Traceback (most recent call last):\n",
      "  File \"/usr/local/lib/python3.6/site-packages/guillotina_rediscache/utility.py\", line 34, in initialize\n",
      "    res = await self._redis.subscribe(settings['updates_channel'])\n",
      "  File \"/usr/local/lib/python3.6/site-packages/aioredis/commands/pubsub.py\", line 107, in wait_return_channels\n",
      "    res = await fut\n",
      "  File \"/usr/local/lib/python3.6/site-packages/aioredis/pool.py\", line 276, in _wait_execute_pubsub\n",
      "    conn = await self._create_new_connection(address)\n",
      "  File \"/usr/local/lib/python3.6/site-packages/aioredis/connection.py\", line 108, in create_connection\n",
      "    timeout, loop=loop)\n",
      "  File \"/usr/local/lib/python3.6/asyncio/tasks.py\", line 339, in wait_for\n",
      "    return (yield from fut)\n",
      "  File \"/usr/local/lib/python3.6/site-packages/aioredis/stream.py\", line 19, in open_connection\n",
      "    lambda: protocol, host, port, **kwds)\n",
      "  File \"/usr/local/lib/python3.6/asyncio/base_events.py\", line 778, in create_connection\n",
      "    raise exceptions[0]\n",
      "  File \"/usr/local/lib/python3.6/asyncio/base_events.py\", line 765, in create_connection\n",
      "    yield from self.sock_connect(sock, address)\n",
      "  File \"/usr/local/lib/python3.6/asyncio/selector_events.py\", line 450, in sock_connect\n",
      "    return (yield from fut)\n",
      "  File \"/usr/local/lib/python3.6/asyncio/selector_events.py\", line 480, in _sock_connect_cb\n",
      "    raise OSError(err, 'Connect call failed %s' % (address,))\n",
      "ConnectionRefusedError: [Errno 111] Connect call failed ('192.168.130.119', 6379)\n",
      "Error subscribing to redis changes. Waiting before trying again\n",
      "Traceback (most recent call last):\n",
      "  File \"/usr/local/lib/python3.6/site-packages/guillotina_rediscache/utility.py\", line 34, in initialize\n",
      "    res = await self._redis.subscribe(settings['updates_channel'])\n",
      "  File \"/usr/local/lib/python3.6/site-packages/aioredis/commands/pubsub.py\", line 107, in wait_return_channels\n",
      "    res = await fut\n",
      "  File \"/usr/local/lib/python3.6/site-packages/aioredis/pool.py\", line 276, in _wait_execute_pubsub\n",
      "    conn = await self._create_new_connection(address)\n",
      "  File \"/usr/local/lib/python3.6/site-packages/aioredis/connection.py\", line 108, in create_connection\n",
      "    timeout, loop=loop)\n",
      "  File \"/usr/local/lib/python3.6/asyncio/tasks.py\", line 339, in wait_for\n",
      "    return (yield from fut)\n",
      "  File \"/usr/local/lib/python3.6/site-packages/aioredis/stream.py\", line 19, in open_connection\n",
      "    lambda: protocol, host, port, **kwds)\n",
      "  File \"/usr/local/lib/python3.6/asyncio/base_events.py\", line 778, in create_connection\n",
      "    raise exceptions[0]\n",
      "  File \"/usr/local/lib/python3.6/asyncio/base_events.py\", line 765, in create_connection\n",
      "    yield from self.sock_connect(sock, address)\n",
      "  File \"/usr/local/lib/python3.6/asyncio/selector_events.py\", line 450, in sock_connect\n",
      "    return (yield from fut)\n",
      "  File \"/usr/local/lib/python3.6/asyncio/selector_events.py\", line 480, in _sock_connect_cb\n",
      "    raise OSError(err, 'Connect call failed %s' % (address,))\n",
      "ConnectionRefusedError: [Errno 111] Connect call failed ('192.168.130.119', 6379)\n",
      "Error subscribing to redis changes. Waiting before trying again\n",
      "Traceback (most recent call last):\n",
      "  File \"/usr/local/lib/python3.6/site-packages/guillotina_rediscache/utility.py\", line 34, in initialize\n",
      "    res = await self._redis.subscribe(settings['updates_channel'])\n",
      "  File \"/usr/local/lib/python3.6/site-packages/aioredis/commands/pubsub.py\", line 107, in wait_return_channels\n",
      "    res = await fut\n",
      "  File \"/usr/local/lib/python3.6/site-packages/aioredis/pool.py\", line 276, in _wait_execute_pubsub\n",
      "    conn = await self._create_new_connection(address)\n",
      "  File \"/usr/local/lib/python3.6/site-packages/aioredis/connection.py\", line 108, in create_connection\n",
      "    timeout, loop=loop)\n",
      "  File \"/usr/local/lib/python3.6/asyncio/tasks.py\", line 339, in wait_for\n",
      "    return (yield from fut)\n",
      "  File \"/usr/local/lib/python3.6/site-packages/aioredis/stream.py\", line 19, in open_connection\n",
      "    lambda: protocol, host, port, **kwds)\n",
      "  File \"/usr/local/lib/python3.6/asyncio/base_events.py\", line 778, in create_connection\n",
      "    raise exceptions[0]\n",
      "  File \"/usr/local/lib/python3.6/asyncio/base_events.py\", line 765, in create_connection\n",
      "    yield from self.sock_connect(sock, address)\n",
      "  File \"/usr/local/lib/python3.6/asyncio/selector_events.py\", line 450, in sock_connect\n",
      "    return (yield from fut)\n",
      "  File \"/usr/local/lib/python3.6/asyncio/selector_events.py\", line 480, in _sock_connect_cb\n",
      "    raise OSError(err, 'Connect call failed %s' % (address,))\n",
      "ConnectionRefusedError: [Errno 111] Connect call failed ('192.168.130.119', 6379)\n",
      "Error subscribing to redis changes. Waiting before trying again\n",
      "Traceback (most recent call last):\n",
      "  File \"/usr/local/lib/python3.6/site-packages/guillotina_rediscache/utility.py\", line 34, in initialize\n",
      "    res = await self._redis.subscribe(settings['updates_channel'])\n",
      "  File \"/usr/local/lib/python3.6/site-packages/aioredis/commands/pubsub.py\", line 107, in wait_return_channels\n",
      "    res = await fut\n",
      "  File \"/usr/local/lib/python3.6/site-packages/aioredis/pool.py\", line 276, in _wait_execute_pubsub\n",
      "    conn = await self._create_new_connection(address)\n",
      "  File \"/usr/local/lib/python3.6/site-packages/aioredis/connection.py\", line 108, in create_connection\n",
      "    timeout, loop=loop)\n",
      "  File \"/usr/local/lib/python3.6/asyncio/tasks.py\", line 339, in wait_for\n",
      "    return (yield from fut)\n",
      "  File \"/usr/local/lib/python3.6/site-packages/aioredis/stream.py\", line 19, in open_connection\n",
      "    lambda: protocol, host, port, **kwds)\n",
      "  File \"/usr/local/lib/python3.6/asyncio/base_events.py\", line 778, in create_connection\n",
      "    raise exceptions[0]\n",
      "  File \"/usr/local/lib/python3.6/asyncio/base_events.py\", line 765, in create_connection\n",
      "    yield from self.sock_connect(sock, address)\n",
      "  File \"/usr/local/lib/python3.6/asyncio/selector_events.py\", line 450, in sock_connect\n",
      "    return (yield from fut)\n",
      "  File \"/usr/local/lib/python3.6/asyncio/selector_events.py\", line 480, in _sock_connect_cb\n",
      "    raise OSError(err, 'Connect call failed %s' % (address,))\n",
      "ConnectionRefusedError: [Errno 111] Connect call failed ('192.168.130.119', 6379)\n"
     ]
    },
    {
     "name": "stderr",
     "output_type": "stream",
     "text": [
      "Error subscribing to redis changes. Waiting before trying again\n",
      "Traceback (most recent call last):\n",
      "  File \"/usr/local/lib/python3.6/site-packages/guillotina_rediscache/utility.py\", line 34, in initialize\n",
      "    res = await self._redis.subscribe(settings['updates_channel'])\n",
      "  File \"/usr/local/lib/python3.6/site-packages/aioredis/commands/pubsub.py\", line 107, in wait_return_channels\n",
      "    res = await fut\n",
      "  File \"/usr/local/lib/python3.6/site-packages/aioredis/pool.py\", line 276, in _wait_execute_pubsub\n",
      "    conn = await self._create_new_connection(address)\n",
      "  File \"/usr/local/lib/python3.6/site-packages/aioredis/connection.py\", line 108, in create_connection\n",
      "    timeout, loop=loop)\n",
      "  File \"/usr/local/lib/python3.6/asyncio/tasks.py\", line 339, in wait_for\n",
      "    return (yield from fut)\n",
      "  File \"/usr/local/lib/python3.6/site-packages/aioredis/stream.py\", line 19, in open_connection\n",
      "    lambda: protocol, host, port, **kwds)\n",
      "  File \"/usr/local/lib/python3.6/asyncio/base_events.py\", line 778, in create_connection\n",
      "    raise exceptions[0]\n",
      "  File \"/usr/local/lib/python3.6/asyncio/base_events.py\", line 765, in create_connection\n",
      "    yield from self.sock_connect(sock, address)\n",
      "  File \"/usr/local/lib/python3.6/asyncio/selector_events.py\", line 450, in sock_connect\n",
      "    return (yield from fut)\n",
      "  File \"/usr/local/lib/python3.6/asyncio/selector_events.py\", line 480, in _sock_connect_cb\n",
      "    raise OSError(err, 'Connect call failed %s' % (address,))\n",
      "ConnectionRefusedError: [Errno 111] Connect call failed ('192.168.130.119', 6379)\n",
      "Error subscribing to redis changes. Waiting before trying again\n",
      "Traceback (most recent call last):\n",
      "  File \"/usr/local/lib/python3.6/site-packages/guillotina_rediscache/utility.py\", line 34, in initialize\n",
      "    res = await self._redis.subscribe(settings['updates_channel'])\n",
      "  File \"/usr/local/lib/python3.6/site-packages/aioredis/commands/pubsub.py\", line 107, in wait_return_channels\n",
      "    res = await fut\n",
      "  File \"/usr/local/lib/python3.6/site-packages/aioredis/pool.py\", line 276, in _wait_execute_pubsub\n",
      "    conn = await self._create_new_connection(address)\n",
      "  File \"/usr/local/lib/python3.6/site-packages/aioredis/connection.py\", line 108, in create_connection\n",
      "    timeout, loop=loop)\n",
      "  File \"/usr/local/lib/python3.6/asyncio/tasks.py\", line 339, in wait_for\n",
      "    return (yield from fut)\n",
      "  File \"/usr/local/lib/python3.6/site-packages/aioredis/stream.py\", line 19, in open_connection\n",
      "    lambda: protocol, host, port, **kwds)\n",
      "  File \"/usr/local/lib/python3.6/asyncio/base_events.py\", line 778, in create_connection\n",
      "    raise exceptions[0]\n",
      "  File \"/usr/local/lib/python3.6/asyncio/base_events.py\", line 765, in create_connection\n",
      "    yield from self.sock_connect(sock, address)\n",
      "  File \"/usr/local/lib/python3.6/asyncio/selector_events.py\", line 450, in sock_connect\n",
      "    return (yield from fut)\n",
      "  File \"/usr/local/lib/python3.6/asyncio/selector_events.py\", line 480, in _sock_connect_cb\n",
      "    raise OSError(err, 'Connect call failed %s' % (address,))\n",
      "ConnectionRefusedError: [Errno 111] Connect call failed ('192.168.130.119', 6379)\n",
      "Error subscribing to redis changes. Waiting before trying again\n",
      "Traceback (most recent call last):\n",
      "  File \"/usr/local/lib/python3.6/site-packages/guillotina_rediscache/utility.py\", line 34, in initialize\n",
      "    res = await self._redis.subscribe(settings['updates_channel'])\n",
      "  File \"/usr/local/lib/python3.6/site-packages/aioredis/commands/pubsub.py\", line 107, in wait_return_channels\n",
      "    res = await fut\n",
      "  File \"/usr/local/lib/python3.6/site-packages/aioredis/pool.py\", line 276, in _wait_execute_pubsub\n",
      "    conn = await self._create_new_connection(address)\n",
      "  File \"/usr/local/lib/python3.6/site-packages/aioredis/connection.py\", line 108, in create_connection\n",
      "    timeout, loop=loop)\n",
      "  File \"/usr/local/lib/python3.6/asyncio/tasks.py\", line 339, in wait_for\n",
      "    return (yield from fut)\n",
      "  File \"/usr/local/lib/python3.6/site-packages/aioredis/stream.py\", line 19, in open_connection\n",
      "    lambda: protocol, host, port, **kwds)\n",
      "  File \"/usr/local/lib/python3.6/asyncio/base_events.py\", line 778, in create_connection\n",
      "    raise exceptions[0]\n",
      "  File \"/usr/local/lib/python3.6/asyncio/base_events.py\", line 765, in create_connection\n",
      "    yield from self.sock_connect(sock, address)\n",
      "  File \"/usr/local/lib/python3.6/asyncio/selector_events.py\", line 450, in sock_connect\n",
      "    return (yield from fut)\n",
      "  File \"/usr/local/lib/python3.6/asyncio/selector_events.py\", line 480, in _sock_connect_cb\n",
      "    raise OSError(err, 'Connect call failed %s' % (address,))\n",
      "ConnectionRefusedError: [Errno 111] Connect call failed ('192.168.130.119', 6379)\n",
      "Error subscribing to redis changes. Waiting before trying again\n",
      "Traceback (most recent call last):\n",
      "  File \"/usr/local/lib/python3.6/site-packages/guillotina_rediscache/utility.py\", line 34, in initialize\n",
      "    res = await self._redis.subscribe(settings['updates_channel'])\n",
      "  File \"/usr/local/lib/python3.6/site-packages/aioredis/commands/pubsub.py\", line 107, in wait_return_channels\n",
      "    res = await fut\n",
      "  File \"/usr/local/lib/python3.6/site-packages/aioredis/pool.py\", line 276, in _wait_execute_pubsub\n",
      "    conn = await self._create_new_connection(address)\n",
      "  File \"/usr/local/lib/python3.6/site-packages/aioredis/connection.py\", line 108, in create_connection\n",
      "    timeout, loop=loop)\n",
      "  File \"/usr/local/lib/python3.6/asyncio/tasks.py\", line 339, in wait_for\n",
      "    return (yield from fut)\n",
      "  File \"/usr/local/lib/python3.6/site-packages/aioredis/stream.py\", line 19, in open_connection\n",
      "    lambda: protocol, host, port, **kwds)\n",
      "  File \"/usr/local/lib/python3.6/asyncio/base_events.py\", line 778, in create_connection\n",
      "    raise exceptions[0]\n",
      "  File \"/usr/local/lib/python3.6/asyncio/base_events.py\", line 765, in create_connection\n",
      "    yield from self.sock_connect(sock, address)\n",
      "  File \"/usr/local/lib/python3.6/asyncio/selector_events.py\", line 450, in sock_connect\n",
      "    return (yield from fut)\n",
      "  File \"/usr/local/lib/python3.6/asyncio/selector_events.py\", line 480, in _sock_connect_cb\n",
      "    raise OSError(err, 'Connect call failed %s' % (address,))\n",
      "ConnectionRefusedError: [Errno 111] Connect call failed ('192.168.130.119', 6379)\n",
      "Error subscribing to redis changes. Waiting before trying again\n",
      "Traceback (most recent call last):\n",
      "  File \"/usr/local/lib/python3.6/site-packages/guillotina_rediscache/utility.py\", line 34, in initialize\n",
      "    res = await self._redis.subscribe(settings['updates_channel'])\n",
      "  File \"/usr/local/lib/python3.6/site-packages/aioredis/commands/pubsub.py\", line 107, in wait_return_channels\n",
      "    res = await fut\n",
      "  File \"/usr/local/lib/python3.6/site-packages/aioredis/pool.py\", line 276, in _wait_execute_pubsub\n",
      "    conn = await self._create_new_connection(address)\n",
      "  File \"/usr/local/lib/python3.6/site-packages/aioredis/connection.py\", line 108, in create_connection\n",
      "    timeout, loop=loop)\n",
      "  File \"/usr/local/lib/python3.6/asyncio/tasks.py\", line 339, in wait_for\n",
      "    return (yield from fut)\n",
      "  File \"/usr/local/lib/python3.6/site-packages/aioredis/stream.py\", line 19, in open_connection\n",
      "    lambda: protocol, host, port, **kwds)\n",
      "  File \"/usr/local/lib/python3.6/asyncio/base_events.py\", line 778, in create_connection\n",
      "    raise exceptions[0]\n",
      "  File \"/usr/local/lib/python3.6/asyncio/base_events.py\", line 765, in create_connection\n",
      "    yield from self.sock_connect(sock, address)\n",
      "  File \"/usr/local/lib/python3.6/asyncio/selector_events.py\", line 450, in sock_connect\n",
      "    return (yield from fut)\n",
      "  File \"/usr/local/lib/python3.6/asyncio/selector_events.py\", line 480, in _sock_connect_cb\n",
      "    raise OSError(err, 'Connect call failed %s' % (address,))\n",
      "ConnectionRefusedError: [Errno 111] Connect call failed ('192.168.130.119', 6379)\n",
      "Error subscribing to redis changes. Waiting before trying again\n",
      "Traceback (most recent call last):\n",
      "  File \"/usr/local/lib/python3.6/site-packages/guillotina_rediscache/utility.py\", line 34, in initialize\n",
      "    res = await self._redis.subscribe(settings['updates_channel'])\n",
      "  File \"/usr/local/lib/python3.6/site-packages/aioredis/commands/pubsub.py\", line 107, in wait_return_channels\n",
      "    res = await fut\n",
      "  File \"/usr/local/lib/python3.6/site-packages/aioredis/pool.py\", line 276, in _wait_execute_pubsub\n",
      "    conn = await self._create_new_connection(address)\n",
      "  File \"/usr/local/lib/python3.6/site-packages/aioredis/connection.py\", line 108, in create_connection\n",
      "    timeout, loop=loop)\n",
      "  File \"/usr/local/lib/python3.6/asyncio/tasks.py\", line 339, in wait_for\n",
      "    return (yield from fut)\n",
      "  File \"/usr/local/lib/python3.6/site-packages/aioredis/stream.py\", line 19, in open_connection\n",
      "    lambda: protocol, host, port, **kwds)\n",
      "  File \"/usr/local/lib/python3.6/asyncio/base_events.py\", line 778, in create_connection\n",
      "    raise exceptions[0]\n",
      "  File \"/usr/local/lib/python3.6/asyncio/base_events.py\", line 765, in create_connection\n",
      "    yield from self.sock_connect(sock, address)\n",
      "  File \"/usr/local/lib/python3.6/asyncio/selector_events.py\", line 450, in sock_connect\n",
      "    return (yield from fut)\n",
      "  File \"/usr/local/lib/python3.6/asyncio/selector_events.py\", line 480, in _sock_connect_cb\n",
      "    raise OSError(err, 'Connect call failed %s' % (address,))\n",
      "ConnectionRefusedError: [Errno 111] Connect call failed ('192.168.130.119', 6379)\n"
     ]
    },
    {
     "name": "stderr",
     "output_type": "stream",
     "text": [
      "Error subscribing to redis changes. Waiting before trying again\n",
      "Traceback (most recent call last):\n",
      "  File \"/usr/local/lib/python3.6/site-packages/guillotina_rediscache/utility.py\", line 34, in initialize\n",
      "    res = await self._redis.subscribe(settings['updates_channel'])\n",
      "  File \"/usr/local/lib/python3.6/site-packages/aioredis/commands/pubsub.py\", line 107, in wait_return_channels\n",
      "    res = await fut\n",
      "  File \"/usr/local/lib/python3.6/site-packages/aioredis/pool.py\", line 276, in _wait_execute_pubsub\n",
      "    conn = await self._create_new_connection(address)\n",
      "  File \"/usr/local/lib/python3.6/site-packages/aioredis/connection.py\", line 108, in create_connection\n",
      "    timeout, loop=loop)\n",
      "  File \"/usr/local/lib/python3.6/asyncio/tasks.py\", line 339, in wait_for\n",
      "    return (yield from fut)\n",
      "  File \"/usr/local/lib/python3.6/site-packages/aioredis/stream.py\", line 19, in open_connection\n",
      "    lambda: protocol, host, port, **kwds)\n",
      "  File \"/usr/local/lib/python3.6/asyncio/base_events.py\", line 778, in create_connection\n",
      "    raise exceptions[0]\n",
      "  File \"/usr/local/lib/python3.6/asyncio/base_events.py\", line 765, in create_connection\n",
      "    yield from self.sock_connect(sock, address)\n",
      "  File \"/usr/local/lib/python3.6/asyncio/selector_events.py\", line 450, in sock_connect\n",
      "    return (yield from fut)\n",
      "  File \"/usr/local/lib/python3.6/asyncio/selector_events.py\", line 480, in _sock_connect_cb\n",
      "    raise OSError(err, 'Connect call failed %s' % (address,))\n",
      "ConnectionRefusedError: [Errno 111] Connect call failed ('192.168.130.119', 6379)\n",
      "Error subscribing to redis changes. Waiting before trying again\n",
      "Traceback (most recent call last):\n",
      "  File \"/usr/local/lib/python3.6/site-packages/guillotina_rediscache/utility.py\", line 34, in initialize\n",
      "    res = await self._redis.subscribe(settings['updates_channel'])\n",
      "  File \"/usr/local/lib/python3.6/site-packages/aioredis/commands/pubsub.py\", line 107, in wait_return_channels\n",
      "    res = await fut\n",
      "  File \"/usr/local/lib/python3.6/site-packages/aioredis/pool.py\", line 276, in _wait_execute_pubsub\n",
      "    conn = await self._create_new_connection(address)\n",
      "  File \"/usr/local/lib/python3.6/site-packages/aioredis/connection.py\", line 108, in create_connection\n",
      "    timeout, loop=loop)\n",
      "  File \"/usr/local/lib/python3.6/asyncio/tasks.py\", line 339, in wait_for\n",
      "    return (yield from fut)\n",
      "  File \"/usr/local/lib/python3.6/site-packages/aioredis/stream.py\", line 19, in open_connection\n",
      "    lambda: protocol, host, port, **kwds)\n",
      "  File \"/usr/local/lib/python3.6/asyncio/base_events.py\", line 778, in create_connection\n",
      "    raise exceptions[0]\n",
      "  File \"/usr/local/lib/python3.6/asyncio/base_events.py\", line 765, in create_connection\n",
      "    yield from self.sock_connect(sock, address)\n",
      "  File \"/usr/local/lib/python3.6/asyncio/selector_events.py\", line 450, in sock_connect\n",
      "    return (yield from fut)\n",
      "  File \"/usr/local/lib/python3.6/asyncio/selector_events.py\", line 480, in _sock_connect_cb\n",
      "    raise OSError(err, 'Connect call failed %s' % (address,))\n",
      "ConnectionRefusedError: [Errno 111] Connect call failed ('192.168.130.119', 6379)\n",
      "Error subscribing to redis changes. Waiting before trying again\n",
      "Traceback (most recent call last):\n",
      "  File \"/usr/local/lib/python3.6/site-packages/guillotina_rediscache/utility.py\", line 34, in initialize\n",
      "    res = await self._redis.subscribe(settings['updates_channel'])\n",
      "  File \"/usr/local/lib/python3.6/site-packages/aioredis/commands/pubsub.py\", line 107, in wait_return_channels\n",
      "    res = await fut\n",
      "  File \"/usr/local/lib/python3.6/site-packages/aioredis/pool.py\", line 276, in _wait_execute_pubsub\n",
      "    conn = await self._create_new_connection(address)\n",
      "  File \"/usr/local/lib/python3.6/site-packages/aioredis/connection.py\", line 108, in create_connection\n",
      "    timeout, loop=loop)\n",
      "  File \"/usr/local/lib/python3.6/asyncio/tasks.py\", line 339, in wait_for\n",
      "    return (yield from fut)\n",
      "  File \"/usr/local/lib/python3.6/site-packages/aioredis/stream.py\", line 19, in open_connection\n",
      "    lambda: protocol, host, port, **kwds)\n",
      "  File \"/usr/local/lib/python3.6/asyncio/base_events.py\", line 778, in create_connection\n",
      "    raise exceptions[0]\n",
      "  File \"/usr/local/lib/python3.6/asyncio/base_events.py\", line 765, in create_connection\n",
      "    yield from self.sock_connect(sock, address)\n",
      "  File \"/usr/local/lib/python3.6/asyncio/selector_events.py\", line 450, in sock_connect\n",
      "    return (yield from fut)\n",
      "  File \"/usr/local/lib/python3.6/asyncio/selector_events.py\", line 480, in _sock_connect_cb\n",
      "    raise OSError(err, 'Connect call failed %s' % (address,))\n",
      "ConnectionRefusedError: [Errno 111] Connect call failed ('192.168.130.119', 6379)\n",
      "Error subscribing to redis changes. Waiting before trying again\n",
      "Traceback (most recent call last):\n",
      "  File \"/usr/local/lib/python3.6/site-packages/guillotina_rediscache/utility.py\", line 34, in initialize\n",
      "    res = await self._redis.subscribe(settings['updates_channel'])\n",
      "  File \"/usr/local/lib/python3.6/site-packages/aioredis/commands/pubsub.py\", line 107, in wait_return_channels\n",
      "    res = await fut\n",
      "  File \"/usr/local/lib/python3.6/site-packages/aioredis/pool.py\", line 276, in _wait_execute_pubsub\n",
      "    conn = await self._create_new_connection(address)\n",
      "  File \"/usr/local/lib/python3.6/site-packages/aioredis/connection.py\", line 108, in create_connection\n",
      "    timeout, loop=loop)\n",
      "  File \"/usr/local/lib/python3.6/asyncio/tasks.py\", line 339, in wait_for\n",
      "    return (yield from fut)\n",
      "  File \"/usr/local/lib/python3.6/site-packages/aioredis/stream.py\", line 19, in open_connection\n",
      "    lambda: protocol, host, port, **kwds)\n",
      "  File \"/usr/local/lib/python3.6/asyncio/base_events.py\", line 778, in create_connection\n",
      "    raise exceptions[0]\n",
      "  File \"/usr/local/lib/python3.6/asyncio/base_events.py\", line 765, in create_connection\n",
      "    yield from self.sock_connect(sock, address)\n",
      "  File \"/usr/local/lib/python3.6/asyncio/selector_events.py\", line 450, in sock_connect\n",
      "    return (yield from fut)\n",
      "  File \"/usr/local/lib/python3.6/asyncio/selector_events.py\", line 480, in _sock_connect_cb\n",
      "    raise OSError(err, 'Connect call failed %s' % (address,))\n",
      "ConnectionRefusedError: [Errno 111] Connect call failed ('192.168.130.119', 6379)\n",
      "Error subscribing to redis changes. Waiting before trying again\n",
      "Traceback (most recent call last):\n",
      "  File \"/usr/local/lib/python3.6/site-packages/guillotina_rediscache/utility.py\", line 34, in initialize\n",
      "    res = await self._redis.subscribe(settings['updates_channel'])\n",
      "  File \"/usr/local/lib/python3.6/site-packages/aioredis/commands/pubsub.py\", line 107, in wait_return_channels\n",
      "    res = await fut\n",
      "  File \"/usr/local/lib/python3.6/site-packages/aioredis/pool.py\", line 276, in _wait_execute_pubsub\n",
      "    conn = await self._create_new_connection(address)\n",
      "  File \"/usr/local/lib/python3.6/site-packages/aioredis/connection.py\", line 108, in create_connection\n",
      "    timeout, loop=loop)\n",
      "  File \"/usr/local/lib/python3.6/asyncio/tasks.py\", line 339, in wait_for\n",
      "    return (yield from fut)\n",
      "  File \"/usr/local/lib/python3.6/site-packages/aioredis/stream.py\", line 19, in open_connection\n",
      "    lambda: protocol, host, port, **kwds)\n",
      "  File \"/usr/local/lib/python3.6/asyncio/base_events.py\", line 778, in create_connection\n",
      "    raise exceptions[0]\n",
      "  File \"/usr/local/lib/python3.6/asyncio/base_events.py\", line 765, in create_connection\n",
      "    yield from self.sock_connect(sock, address)\n",
      "  File \"/usr/local/lib/python3.6/asyncio/selector_events.py\", line 450, in sock_connect\n",
      "    return (yield from fut)\n",
      "  File \"/usr/local/lib/python3.6/asyncio/selector_events.py\", line 480, in _sock_connect_cb\n",
      "    raise OSError(err, 'Connect call failed %s' % (address,))\n",
      "ConnectionRefusedError: [Errno 111] Connect call failed ('192.168.130.119', 6379)\n",
      "Error subscribing to redis changes. Waiting before trying again\n",
      "Traceback (most recent call last):\n",
      "  File \"/usr/local/lib/python3.6/site-packages/guillotina_rediscache/utility.py\", line 34, in initialize\n",
      "    res = await self._redis.subscribe(settings['updates_channel'])\n",
      "  File \"/usr/local/lib/python3.6/site-packages/aioredis/commands/pubsub.py\", line 107, in wait_return_channels\n",
      "    res = await fut\n",
      "  File \"/usr/local/lib/python3.6/site-packages/aioredis/pool.py\", line 276, in _wait_execute_pubsub\n",
      "    conn = await self._create_new_connection(address)\n",
      "  File \"/usr/local/lib/python3.6/site-packages/aioredis/connection.py\", line 108, in create_connection\n",
      "    timeout, loop=loop)\n",
      "  File \"/usr/local/lib/python3.6/asyncio/tasks.py\", line 339, in wait_for\n",
      "    return (yield from fut)\n",
      "  File \"/usr/local/lib/python3.6/site-packages/aioredis/stream.py\", line 19, in open_connection\n",
      "    lambda: protocol, host, port, **kwds)\n",
      "  File \"/usr/local/lib/python3.6/asyncio/base_events.py\", line 778, in create_connection\n",
      "    raise exceptions[0]\n",
      "  File \"/usr/local/lib/python3.6/asyncio/base_events.py\", line 765, in create_connection\n",
      "    yield from self.sock_connect(sock, address)\n",
      "  File \"/usr/local/lib/python3.6/asyncio/selector_events.py\", line 450, in sock_connect\n",
      "    return (yield from fut)\n",
      "  File \"/usr/local/lib/python3.6/asyncio/selector_events.py\", line 480, in _sock_connect_cb\n",
      "    raise OSError(err, 'Connect call failed %s' % (address,))\n",
      "ConnectionRefusedError: [Errno 111] Connect call failed ('192.168.130.119', 6379)\n"
     ]
    },
    {
     "name": "stderr",
     "output_type": "stream",
     "text": [
      "Error subscribing to redis changes. Waiting before trying again\n",
      "Traceback (most recent call last):\n",
      "  File \"/usr/local/lib/python3.6/site-packages/guillotina_rediscache/utility.py\", line 34, in initialize\n",
      "    res = await self._redis.subscribe(settings['updates_channel'])\n",
      "  File \"/usr/local/lib/python3.6/site-packages/aioredis/commands/pubsub.py\", line 107, in wait_return_channels\n",
      "    res = await fut\n",
      "  File \"/usr/local/lib/python3.6/site-packages/aioredis/pool.py\", line 276, in _wait_execute_pubsub\n",
      "    conn = await self._create_new_connection(address)\n",
      "  File \"/usr/local/lib/python3.6/site-packages/aioredis/connection.py\", line 108, in create_connection\n",
      "    timeout, loop=loop)\n",
      "  File \"/usr/local/lib/python3.6/asyncio/tasks.py\", line 339, in wait_for\n",
      "    return (yield from fut)\n",
      "  File \"/usr/local/lib/python3.6/site-packages/aioredis/stream.py\", line 19, in open_connection\n",
      "    lambda: protocol, host, port, **kwds)\n",
      "  File \"/usr/local/lib/python3.6/asyncio/base_events.py\", line 778, in create_connection\n",
      "    raise exceptions[0]\n",
      "  File \"/usr/local/lib/python3.6/asyncio/base_events.py\", line 765, in create_connection\n",
      "    yield from self.sock_connect(sock, address)\n",
      "  File \"/usr/local/lib/python3.6/asyncio/selector_events.py\", line 450, in sock_connect\n",
      "    return (yield from fut)\n",
      "  File \"/usr/local/lib/python3.6/asyncio/selector_events.py\", line 480, in _sock_connect_cb\n",
      "    raise OSError(err, 'Connect call failed %s' % (address,))\n",
      "ConnectionRefusedError: [Errno 111] Connect call failed ('192.168.130.119', 6379)\n",
      "Error subscribing to redis changes. Waiting before trying again\n",
      "Traceback (most recent call last):\n",
      "  File \"/usr/local/lib/python3.6/site-packages/guillotina_rediscache/utility.py\", line 34, in initialize\n",
      "    res = await self._redis.subscribe(settings['updates_channel'])\n",
      "  File \"/usr/local/lib/python3.6/site-packages/aioredis/commands/pubsub.py\", line 107, in wait_return_channels\n",
      "    res = await fut\n",
      "  File \"/usr/local/lib/python3.6/site-packages/aioredis/pool.py\", line 276, in _wait_execute_pubsub\n",
      "    conn = await self._create_new_connection(address)\n",
      "  File \"/usr/local/lib/python3.6/site-packages/aioredis/connection.py\", line 108, in create_connection\n",
      "    timeout, loop=loop)\n",
      "  File \"/usr/local/lib/python3.6/asyncio/tasks.py\", line 339, in wait_for\n",
      "    return (yield from fut)\n",
      "  File \"/usr/local/lib/python3.6/site-packages/aioredis/stream.py\", line 19, in open_connection\n",
      "    lambda: protocol, host, port, **kwds)\n",
      "  File \"/usr/local/lib/python3.6/asyncio/base_events.py\", line 778, in create_connection\n",
      "    raise exceptions[0]\n",
      "  File \"/usr/local/lib/python3.6/asyncio/base_events.py\", line 765, in create_connection\n",
      "    yield from self.sock_connect(sock, address)\n",
      "  File \"/usr/local/lib/python3.6/asyncio/selector_events.py\", line 450, in sock_connect\n",
      "    return (yield from fut)\n",
      "  File \"/usr/local/lib/python3.6/asyncio/selector_events.py\", line 480, in _sock_connect_cb\n",
      "    raise OSError(err, 'Connect call failed %s' % (address,))\n",
      "ConnectionRefusedError: [Errno 111] Connect call failed ('192.168.130.119', 6379)\n",
      "Error subscribing to redis changes. Waiting before trying again\n",
      "Traceback (most recent call last):\n",
      "  File \"/usr/local/lib/python3.6/site-packages/guillotina_rediscache/utility.py\", line 34, in initialize\n",
      "    res = await self._redis.subscribe(settings['updates_channel'])\n",
      "  File \"/usr/local/lib/python3.6/site-packages/aioredis/commands/pubsub.py\", line 107, in wait_return_channels\n",
      "    res = await fut\n",
      "  File \"/usr/local/lib/python3.6/site-packages/aioredis/pool.py\", line 276, in _wait_execute_pubsub\n",
      "    conn = await self._create_new_connection(address)\n",
      "  File \"/usr/local/lib/python3.6/site-packages/aioredis/connection.py\", line 108, in create_connection\n",
      "    timeout, loop=loop)\n",
      "  File \"/usr/local/lib/python3.6/asyncio/tasks.py\", line 339, in wait_for\n",
      "    return (yield from fut)\n",
      "  File \"/usr/local/lib/python3.6/site-packages/aioredis/stream.py\", line 19, in open_connection\n",
      "    lambda: protocol, host, port, **kwds)\n",
      "  File \"/usr/local/lib/python3.6/asyncio/base_events.py\", line 778, in create_connection\n",
      "    raise exceptions[0]\n",
      "  File \"/usr/local/lib/python3.6/asyncio/base_events.py\", line 765, in create_connection\n",
      "    yield from self.sock_connect(sock, address)\n",
      "  File \"/usr/local/lib/python3.6/asyncio/selector_events.py\", line 450, in sock_connect\n",
      "    return (yield from fut)\n",
      "  File \"/usr/local/lib/python3.6/asyncio/selector_events.py\", line 480, in _sock_connect_cb\n",
      "    raise OSError(err, 'Connect call failed %s' % (address,))\n",
      "ConnectionRefusedError: [Errno 111] Connect call failed ('192.168.130.119', 6379)\n",
      "Error subscribing to redis changes. Waiting before trying again\n",
      "Traceback (most recent call last):\n",
      "  File \"/usr/local/lib/python3.6/site-packages/guillotina_rediscache/utility.py\", line 34, in initialize\n",
      "    res = await self._redis.subscribe(settings['updates_channel'])\n",
      "  File \"/usr/local/lib/python3.6/site-packages/aioredis/commands/pubsub.py\", line 107, in wait_return_channels\n",
      "    res = await fut\n",
      "  File \"/usr/local/lib/python3.6/site-packages/aioredis/pool.py\", line 276, in _wait_execute_pubsub\n",
      "    conn = await self._create_new_connection(address)\n",
      "  File \"/usr/local/lib/python3.6/site-packages/aioredis/connection.py\", line 108, in create_connection\n",
      "    timeout, loop=loop)\n",
      "  File \"/usr/local/lib/python3.6/asyncio/tasks.py\", line 339, in wait_for\n",
      "    return (yield from fut)\n",
      "  File \"/usr/local/lib/python3.6/site-packages/aioredis/stream.py\", line 19, in open_connection\n",
      "    lambda: protocol, host, port, **kwds)\n",
      "  File \"/usr/local/lib/python3.6/asyncio/base_events.py\", line 778, in create_connection\n",
      "    raise exceptions[0]\n",
      "  File \"/usr/local/lib/python3.6/asyncio/base_events.py\", line 765, in create_connection\n",
      "    yield from self.sock_connect(sock, address)\n",
      "  File \"/usr/local/lib/python3.6/asyncio/selector_events.py\", line 450, in sock_connect\n",
      "    return (yield from fut)\n",
      "  File \"/usr/local/lib/python3.6/asyncio/selector_events.py\", line 480, in _sock_connect_cb\n",
      "    raise OSError(err, 'Connect call failed %s' % (address,))\n",
      "ConnectionRefusedError: [Errno 111] Connect call failed ('192.168.130.119', 6379)\n",
      "Error subscribing to redis changes. Waiting before trying again\n",
      "Traceback (most recent call last):\n",
      "  File \"/usr/local/lib/python3.6/site-packages/guillotina_rediscache/utility.py\", line 34, in initialize\n",
      "    res = await self._redis.subscribe(settings['updates_channel'])\n",
      "  File \"/usr/local/lib/python3.6/site-packages/aioredis/commands/pubsub.py\", line 107, in wait_return_channels\n",
      "    res = await fut\n",
      "  File \"/usr/local/lib/python3.6/site-packages/aioredis/pool.py\", line 276, in _wait_execute_pubsub\n",
      "    conn = await self._create_new_connection(address)\n",
      "  File \"/usr/local/lib/python3.6/site-packages/aioredis/connection.py\", line 108, in create_connection\n",
      "    timeout, loop=loop)\n",
      "  File \"/usr/local/lib/python3.6/asyncio/tasks.py\", line 339, in wait_for\n",
      "    return (yield from fut)\n",
      "  File \"/usr/local/lib/python3.6/site-packages/aioredis/stream.py\", line 19, in open_connection\n",
      "    lambda: protocol, host, port, **kwds)\n",
      "  File \"/usr/local/lib/python3.6/asyncio/base_events.py\", line 778, in create_connection\n",
      "    raise exceptions[0]\n",
      "  File \"/usr/local/lib/python3.6/asyncio/base_events.py\", line 765, in create_connection\n",
      "    yield from self.sock_connect(sock, address)\n",
      "  File \"/usr/local/lib/python3.6/asyncio/selector_events.py\", line 450, in sock_connect\n",
      "    return (yield from fut)\n",
      "  File \"/usr/local/lib/python3.6/asyncio/selector_events.py\", line 480, in _sock_connect_cb\n",
      "    raise OSError(err, 'Connect call failed %s' % (address,))\n",
      "ConnectionRefusedError: [Errno 111] Connect call failed ('192.168.130.119', 6379)\n",
      "Error subscribing to redis changes. Waiting before trying again\n",
      "Traceback (most recent call last):\n",
      "  File \"/usr/local/lib/python3.6/site-packages/guillotina_rediscache/utility.py\", line 34, in initialize\n",
      "    res = await self._redis.subscribe(settings['updates_channel'])\n",
      "  File \"/usr/local/lib/python3.6/site-packages/aioredis/commands/pubsub.py\", line 107, in wait_return_channels\n",
      "    res = await fut\n",
      "  File \"/usr/local/lib/python3.6/site-packages/aioredis/pool.py\", line 276, in _wait_execute_pubsub\n",
      "    conn = await self._create_new_connection(address)\n",
      "  File \"/usr/local/lib/python3.6/site-packages/aioredis/connection.py\", line 108, in create_connection\n",
      "    timeout, loop=loop)\n",
      "  File \"/usr/local/lib/python3.6/asyncio/tasks.py\", line 339, in wait_for\n",
      "    return (yield from fut)\n",
      "  File \"/usr/local/lib/python3.6/site-packages/aioredis/stream.py\", line 19, in open_connection\n",
      "    lambda: protocol, host, port, **kwds)\n",
      "  File \"/usr/local/lib/python3.6/asyncio/base_events.py\", line 778, in create_connection\n",
      "    raise exceptions[0]\n",
      "  File \"/usr/local/lib/python3.6/asyncio/base_events.py\", line 765, in create_connection\n",
      "    yield from self.sock_connect(sock, address)\n",
      "  File \"/usr/local/lib/python3.6/asyncio/selector_events.py\", line 450, in sock_connect\n",
      "    return (yield from fut)\n",
      "  File \"/usr/local/lib/python3.6/asyncio/selector_events.py\", line 480, in _sock_connect_cb\n",
      "    raise OSError(err, 'Connect call failed %s' % (address,))\n",
      "ConnectionRefusedError: [Errno 111] Connect call failed ('192.168.130.119', 6379)\n"
     ]
    },
    {
     "name": "stderr",
     "output_type": "stream",
     "text": [
      "Error subscribing to redis changes. Waiting before trying again\n",
      "Traceback (most recent call last):\n",
      "  File \"/usr/local/lib/python3.6/site-packages/guillotina_rediscache/utility.py\", line 34, in initialize\n",
      "    res = await self._redis.subscribe(settings['updates_channel'])\n",
      "  File \"/usr/local/lib/python3.6/site-packages/aioredis/commands/pubsub.py\", line 107, in wait_return_channels\n",
      "    res = await fut\n",
      "  File \"/usr/local/lib/python3.6/site-packages/aioredis/pool.py\", line 276, in _wait_execute_pubsub\n",
      "    conn = await self._create_new_connection(address)\n",
      "  File \"/usr/local/lib/python3.6/site-packages/aioredis/connection.py\", line 108, in create_connection\n",
      "    timeout, loop=loop)\n",
      "  File \"/usr/local/lib/python3.6/asyncio/tasks.py\", line 339, in wait_for\n",
      "    return (yield from fut)\n",
      "  File \"/usr/local/lib/python3.6/site-packages/aioredis/stream.py\", line 19, in open_connection\n",
      "    lambda: protocol, host, port, **kwds)\n",
      "  File \"/usr/local/lib/python3.6/asyncio/base_events.py\", line 778, in create_connection\n",
      "    raise exceptions[0]\n",
      "  File \"/usr/local/lib/python3.6/asyncio/base_events.py\", line 765, in create_connection\n",
      "    yield from self.sock_connect(sock, address)\n",
      "  File \"/usr/local/lib/python3.6/asyncio/selector_events.py\", line 450, in sock_connect\n",
      "    return (yield from fut)\n",
      "  File \"/usr/local/lib/python3.6/asyncio/selector_events.py\", line 480, in _sock_connect_cb\n",
      "    raise OSError(err, 'Connect call failed %s' % (address,))\n",
      "ConnectionRefusedError: [Errno 111] Connect call failed ('192.168.130.119', 6379)\n",
      "Error subscribing to redis changes. Waiting before trying again\n",
      "Traceback (most recent call last):\n",
      "  File \"/usr/local/lib/python3.6/site-packages/guillotina_rediscache/utility.py\", line 34, in initialize\n",
      "    res = await self._redis.subscribe(settings['updates_channel'])\n",
      "  File \"/usr/local/lib/python3.6/site-packages/aioredis/commands/pubsub.py\", line 107, in wait_return_channels\n",
      "    res = await fut\n",
      "  File \"/usr/local/lib/python3.6/site-packages/aioredis/pool.py\", line 276, in _wait_execute_pubsub\n",
      "    conn = await self._create_new_connection(address)\n",
      "  File \"/usr/local/lib/python3.6/site-packages/aioredis/connection.py\", line 108, in create_connection\n",
      "    timeout, loop=loop)\n",
      "  File \"/usr/local/lib/python3.6/asyncio/tasks.py\", line 339, in wait_for\n",
      "    return (yield from fut)\n",
      "  File \"/usr/local/lib/python3.6/site-packages/aioredis/stream.py\", line 19, in open_connection\n",
      "    lambda: protocol, host, port, **kwds)\n",
      "  File \"/usr/local/lib/python3.6/asyncio/base_events.py\", line 778, in create_connection\n",
      "    raise exceptions[0]\n",
      "  File \"/usr/local/lib/python3.6/asyncio/base_events.py\", line 765, in create_connection\n",
      "    yield from self.sock_connect(sock, address)\n",
      "  File \"/usr/local/lib/python3.6/asyncio/selector_events.py\", line 450, in sock_connect\n",
      "    return (yield from fut)\n",
      "  File \"/usr/local/lib/python3.6/asyncio/selector_events.py\", line 480, in _sock_connect_cb\n",
      "    raise OSError(err, 'Connect call failed %s' % (address,))\n",
      "ConnectionRefusedError: [Errno 111] Connect call failed ('192.168.130.119', 6379)\n",
      "Error subscribing to redis changes. Waiting before trying again\n",
      "Traceback (most recent call last):\n",
      "  File \"/usr/local/lib/python3.6/site-packages/guillotina_rediscache/utility.py\", line 34, in initialize\n",
      "    res = await self._redis.subscribe(settings['updates_channel'])\n",
      "  File \"/usr/local/lib/python3.6/site-packages/aioredis/commands/pubsub.py\", line 107, in wait_return_channels\n",
      "    res = await fut\n",
      "  File \"/usr/local/lib/python3.6/site-packages/aioredis/pool.py\", line 276, in _wait_execute_pubsub\n",
      "    conn = await self._create_new_connection(address)\n",
      "  File \"/usr/local/lib/python3.6/site-packages/aioredis/connection.py\", line 108, in create_connection\n",
      "    timeout, loop=loop)\n",
      "  File \"/usr/local/lib/python3.6/asyncio/tasks.py\", line 339, in wait_for\n",
      "    return (yield from fut)\n",
      "  File \"/usr/local/lib/python3.6/site-packages/aioredis/stream.py\", line 19, in open_connection\n",
      "    lambda: protocol, host, port, **kwds)\n",
      "  File \"/usr/local/lib/python3.6/asyncio/base_events.py\", line 778, in create_connection\n",
      "    raise exceptions[0]\n",
      "  File \"/usr/local/lib/python3.6/asyncio/base_events.py\", line 765, in create_connection\n",
      "    yield from self.sock_connect(sock, address)\n",
      "  File \"/usr/local/lib/python3.6/asyncio/selector_events.py\", line 450, in sock_connect\n",
      "    return (yield from fut)\n",
      "  File \"/usr/local/lib/python3.6/asyncio/selector_events.py\", line 480, in _sock_connect_cb\n",
      "    raise OSError(err, 'Connect call failed %s' % (address,))\n",
      "ConnectionRefusedError: [Errno 111] Connect call failed ('192.168.130.119', 6379)\n",
      "Error subscribing to redis changes. Waiting before trying again\n",
      "Traceback (most recent call last):\n",
      "  File \"/usr/local/lib/python3.6/site-packages/guillotina_rediscache/utility.py\", line 34, in initialize\n",
      "    res = await self._redis.subscribe(settings['updates_channel'])\n",
      "  File \"/usr/local/lib/python3.6/site-packages/aioredis/commands/pubsub.py\", line 107, in wait_return_channels\n",
      "    res = await fut\n",
      "  File \"/usr/local/lib/python3.6/site-packages/aioredis/pool.py\", line 276, in _wait_execute_pubsub\n",
      "    conn = await self._create_new_connection(address)\n",
      "  File \"/usr/local/lib/python3.6/site-packages/aioredis/connection.py\", line 108, in create_connection\n",
      "    timeout, loop=loop)\n",
      "  File \"/usr/local/lib/python3.6/asyncio/tasks.py\", line 339, in wait_for\n",
      "    return (yield from fut)\n",
      "  File \"/usr/local/lib/python3.6/site-packages/aioredis/stream.py\", line 19, in open_connection\n",
      "    lambda: protocol, host, port, **kwds)\n",
      "  File \"/usr/local/lib/python3.6/asyncio/base_events.py\", line 778, in create_connection\n",
      "    raise exceptions[0]\n",
      "  File \"/usr/local/lib/python3.6/asyncio/base_events.py\", line 765, in create_connection\n",
      "    yield from self.sock_connect(sock, address)\n",
      "  File \"/usr/local/lib/python3.6/asyncio/selector_events.py\", line 450, in sock_connect\n",
      "    return (yield from fut)\n",
      "  File \"/usr/local/lib/python3.6/asyncio/selector_events.py\", line 480, in _sock_connect_cb\n",
      "    raise OSError(err, 'Connect call failed %s' % (address,))\n",
      "ConnectionRefusedError: [Errno 111] Connect call failed ('192.168.130.119', 6379)\n",
      "Error subscribing to redis changes. Waiting before trying again\n",
      "Traceback (most recent call last):\n",
      "  File \"/usr/local/lib/python3.6/site-packages/guillotina_rediscache/utility.py\", line 34, in initialize\n",
      "    res = await self._redis.subscribe(settings['updates_channel'])\n",
      "  File \"/usr/local/lib/python3.6/site-packages/aioredis/commands/pubsub.py\", line 107, in wait_return_channels\n",
      "    res = await fut\n",
      "  File \"/usr/local/lib/python3.6/site-packages/aioredis/pool.py\", line 276, in _wait_execute_pubsub\n",
      "    conn = await self._create_new_connection(address)\n",
      "  File \"/usr/local/lib/python3.6/site-packages/aioredis/connection.py\", line 108, in create_connection\n",
      "    timeout, loop=loop)\n",
      "  File \"/usr/local/lib/python3.6/asyncio/tasks.py\", line 339, in wait_for\n",
      "    return (yield from fut)\n",
      "  File \"/usr/local/lib/python3.6/site-packages/aioredis/stream.py\", line 19, in open_connection\n",
      "    lambda: protocol, host, port, **kwds)\n",
      "  File \"/usr/local/lib/python3.6/asyncio/base_events.py\", line 778, in create_connection\n",
      "    raise exceptions[0]\n",
      "  File \"/usr/local/lib/python3.6/asyncio/base_events.py\", line 765, in create_connection\n",
      "    yield from self.sock_connect(sock, address)\n",
      "  File \"/usr/local/lib/python3.6/asyncio/selector_events.py\", line 450, in sock_connect\n",
      "    return (yield from fut)\n",
      "  File \"/usr/local/lib/python3.6/asyncio/selector_events.py\", line 480, in _sock_connect_cb\n",
      "    raise OSError(err, 'Connect call failed %s' % (address,))\n",
      "ConnectionRefusedError: [Errno 111] Connect call failed ('192.168.130.119', 6379)\n",
      "Error subscribing to redis changes. Waiting before trying again\n",
      "Traceback (most recent call last):\n",
      "  File \"/usr/local/lib/python3.6/site-packages/guillotina_rediscache/utility.py\", line 34, in initialize\n",
      "    res = await self._redis.subscribe(settings['updates_channel'])\n",
      "  File \"/usr/local/lib/python3.6/site-packages/aioredis/commands/pubsub.py\", line 107, in wait_return_channels\n",
      "    res = await fut\n",
      "  File \"/usr/local/lib/python3.6/site-packages/aioredis/pool.py\", line 276, in _wait_execute_pubsub\n",
      "    conn = await self._create_new_connection(address)\n",
      "  File \"/usr/local/lib/python3.6/site-packages/aioredis/connection.py\", line 108, in create_connection\n",
      "    timeout, loop=loop)\n",
      "  File \"/usr/local/lib/python3.6/asyncio/tasks.py\", line 339, in wait_for\n",
      "    return (yield from fut)\n",
      "  File \"/usr/local/lib/python3.6/site-packages/aioredis/stream.py\", line 19, in open_connection\n",
      "    lambda: protocol, host, port, **kwds)\n",
      "  File \"/usr/local/lib/python3.6/asyncio/base_events.py\", line 778, in create_connection\n",
      "    raise exceptions[0]\n",
      "  File \"/usr/local/lib/python3.6/asyncio/base_events.py\", line 765, in create_connection\n",
      "    yield from self.sock_connect(sock, address)\n",
      "  File \"/usr/local/lib/python3.6/asyncio/selector_events.py\", line 450, in sock_connect\n",
      "    return (yield from fut)\n",
      "  File \"/usr/local/lib/python3.6/asyncio/selector_events.py\", line 480, in _sock_connect_cb\n",
      "    raise OSError(err, 'Connect call failed %s' % (address,))\n",
      "ConnectionRefusedError: [Errno 111] Connect call failed ('192.168.130.119', 6379)\n"
     ]
    },
    {
     "name": "stderr",
     "output_type": "stream",
     "text": [
      "Error subscribing to redis changes. Waiting before trying again\n",
      "Traceback (most recent call last):\n",
      "  File \"/usr/local/lib/python3.6/site-packages/guillotina_rediscache/utility.py\", line 34, in initialize\n",
      "    res = await self._redis.subscribe(settings['updates_channel'])\n",
      "  File \"/usr/local/lib/python3.6/site-packages/aioredis/commands/pubsub.py\", line 107, in wait_return_channels\n",
      "    res = await fut\n",
      "  File \"/usr/local/lib/python3.6/site-packages/aioredis/pool.py\", line 276, in _wait_execute_pubsub\n",
      "    conn = await self._create_new_connection(address)\n",
      "  File \"/usr/local/lib/python3.6/site-packages/aioredis/connection.py\", line 108, in create_connection\n",
      "    timeout, loop=loop)\n",
      "  File \"/usr/local/lib/python3.6/asyncio/tasks.py\", line 339, in wait_for\n",
      "    return (yield from fut)\n",
      "  File \"/usr/local/lib/python3.6/site-packages/aioredis/stream.py\", line 19, in open_connection\n",
      "    lambda: protocol, host, port, **kwds)\n",
      "  File \"/usr/local/lib/python3.6/asyncio/base_events.py\", line 778, in create_connection\n",
      "    raise exceptions[0]\n",
      "  File \"/usr/local/lib/python3.6/asyncio/base_events.py\", line 765, in create_connection\n",
      "    yield from self.sock_connect(sock, address)\n",
      "  File \"/usr/local/lib/python3.6/asyncio/selector_events.py\", line 450, in sock_connect\n",
      "    return (yield from fut)\n",
      "  File \"/usr/local/lib/python3.6/asyncio/selector_events.py\", line 480, in _sock_connect_cb\n",
      "    raise OSError(err, 'Connect call failed %s' % (address,))\n",
      "ConnectionRefusedError: [Errno 111] Connect call failed ('192.168.130.119', 6379)\n",
      "Error subscribing to redis changes. Waiting before trying again\n",
      "Traceback (most recent call last):\n",
      "  File \"/usr/local/lib/python3.6/site-packages/guillotina_rediscache/utility.py\", line 34, in initialize\n",
      "    res = await self._redis.subscribe(settings['updates_channel'])\n",
      "  File \"/usr/local/lib/python3.6/site-packages/aioredis/commands/pubsub.py\", line 107, in wait_return_channels\n",
      "    res = await fut\n",
      "  File \"/usr/local/lib/python3.6/site-packages/aioredis/pool.py\", line 276, in _wait_execute_pubsub\n",
      "    conn = await self._create_new_connection(address)\n",
      "  File \"/usr/local/lib/python3.6/site-packages/aioredis/connection.py\", line 108, in create_connection\n",
      "    timeout, loop=loop)\n",
      "  File \"/usr/local/lib/python3.6/asyncio/tasks.py\", line 339, in wait_for\n",
      "    return (yield from fut)\n",
      "  File \"/usr/local/lib/python3.6/site-packages/aioredis/stream.py\", line 19, in open_connection\n",
      "    lambda: protocol, host, port, **kwds)\n",
      "  File \"/usr/local/lib/python3.6/asyncio/base_events.py\", line 778, in create_connection\n",
      "    raise exceptions[0]\n",
      "  File \"/usr/local/lib/python3.6/asyncio/base_events.py\", line 765, in create_connection\n",
      "    yield from self.sock_connect(sock, address)\n",
      "  File \"/usr/local/lib/python3.6/asyncio/selector_events.py\", line 450, in sock_connect\n",
      "    return (yield from fut)\n",
      "  File \"/usr/local/lib/python3.6/asyncio/selector_events.py\", line 480, in _sock_connect_cb\n",
      "    raise OSError(err, 'Connect call failed %s' % (address,))\n",
      "ConnectionRefusedError: [Errno 111] Connect call failed ('192.168.130.119', 6379)\n",
      "Error subscribing to redis changes. Waiting before trying again\n",
      "Traceback (most recent call last):\n",
      "  File \"/usr/local/lib/python3.6/site-packages/guillotina_rediscache/utility.py\", line 34, in initialize\n",
      "    res = await self._redis.subscribe(settings['updates_channel'])\n",
      "  File \"/usr/local/lib/python3.6/site-packages/aioredis/commands/pubsub.py\", line 107, in wait_return_channels\n",
      "    res = await fut\n",
      "  File \"/usr/local/lib/python3.6/site-packages/aioredis/pool.py\", line 276, in _wait_execute_pubsub\n",
      "    conn = await self._create_new_connection(address)\n",
      "  File \"/usr/local/lib/python3.6/site-packages/aioredis/connection.py\", line 108, in create_connection\n",
      "    timeout, loop=loop)\n",
      "  File \"/usr/local/lib/python3.6/asyncio/tasks.py\", line 339, in wait_for\n",
      "    return (yield from fut)\n",
      "  File \"/usr/local/lib/python3.6/site-packages/aioredis/stream.py\", line 19, in open_connection\n",
      "    lambda: protocol, host, port, **kwds)\n",
      "  File \"/usr/local/lib/python3.6/asyncio/base_events.py\", line 778, in create_connection\n",
      "    raise exceptions[0]\n",
      "  File \"/usr/local/lib/python3.6/asyncio/base_events.py\", line 765, in create_connection\n",
      "    yield from self.sock_connect(sock, address)\n",
      "  File \"/usr/local/lib/python3.6/asyncio/selector_events.py\", line 450, in sock_connect\n",
      "    return (yield from fut)\n",
      "  File \"/usr/local/lib/python3.6/asyncio/selector_events.py\", line 480, in _sock_connect_cb\n",
      "    raise OSError(err, 'Connect call failed %s' % (address,))\n",
      "ConnectionRefusedError: [Errno 111] Connect call failed ('192.168.130.119', 6379)\n",
      "Error subscribing to redis changes. Waiting before trying again\n",
      "Traceback (most recent call last):\n",
      "  File \"/usr/local/lib/python3.6/site-packages/guillotina_rediscache/utility.py\", line 34, in initialize\n",
      "    res = await self._redis.subscribe(settings['updates_channel'])\n",
      "  File \"/usr/local/lib/python3.6/site-packages/aioredis/commands/pubsub.py\", line 107, in wait_return_channels\n",
      "    res = await fut\n",
      "  File \"/usr/local/lib/python3.6/site-packages/aioredis/pool.py\", line 276, in _wait_execute_pubsub\n",
      "    conn = await self._create_new_connection(address)\n",
      "  File \"/usr/local/lib/python3.6/site-packages/aioredis/connection.py\", line 108, in create_connection\n",
      "    timeout, loop=loop)\n",
      "  File \"/usr/local/lib/python3.6/asyncio/tasks.py\", line 339, in wait_for\n",
      "    return (yield from fut)\n",
      "  File \"/usr/local/lib/python3.6/site-packages/aioredis/stream.py\", line 19, in open_connection\n",
      "    lambda: protocol, host, port, **kwds)\n",
      "  File \"/usr/local/lib/python3.6/asyncio/base_events.py\", line 778, in create_connection\n",
      "    raise exceptions[0]\n",
      "  File \"/usr/local/lib/python3.6/asyncio/base_events.py\", line 765, in create_connection\n",
      "    yield from self.sock_connect(sock, address)\n",
      "  File \"/usr/local/lib/python3.6/asyncio/selector_events.py\", line 450, in sock_connect\n",
      "    return (yield from fut)\n",
      "  File \"/usr/local/lib/python3.6/asyncio/selector_events.py\", line 480, in _sock_connect_cb\n",
      "    raise OSError(err, 'Connect call failed %s' % (address,))\n",
      "ConnectionRefusedError: [Errno 111] Connect call failed ('192.168.130.119', 6379)\n",
      "Error subscribing to redis changes. Waiting before trying again\n",
      "Traceback (most recent call last):\n",
      "  File \"/usr/local/lib/python3.6/site-packages/guillotina_rediscache/utility.py\", line 34, in initialize\n",
      "    res = await self._redis.subscribe(settings['updates_channel'])\n",
      "  File \"/usr/local/lib/python3.6/site-packages/aioredis/commands/pubsub.py\", line 107, in wait_return_channels\n",
      "    res = await fut\n",
      "  File \"/usr/local/lib/python3.6/site-packages/aioredis/pool.py\", line 276, in _wait_execute_pubsub\n",
      "    conn = await self._create_new_connection(address)\n",
      "  File \"/usr/local/lib/python3.6/site-packages/aioredis/connection.py\", line 108, in create_connection\n",
      "    timeout, loop=loop)\n",
      "  File \"/usr/local/lib/python3.6/asyncio/tasks.py\", line 339, in wait_for\n",
      "    return (yield from fut)\n",
      "  File \"/usr/local/lib/python3.6/site-packages/aioredis/stream.py\", line 19, in open_connection\n",
      "    lambda: protocol, host, port, **kwds)\n",
      "  File \"/usr/local/lib/python3.6/asyncio/base_events.py\", line 778, in create_connection\n",
      "    raise exceptions[0]\n",
      "  File \"/usr/local/lib/python3.6/asyncio/base_events.py\", line 765, in create_connection\n",
      "    yield from self.sock_connect(sock, address)\n",
      "  File \"/usr/local/lib/python3.6/asyncio/selector_events.py\", line 450, in sock_connect\n",
      "    return (yield from fut)\n",
      "  File \"/usr/local/lib/python3.6/asyncio/selector_events.py\", line 480, in _sock_connect_cb\n",
      "    raise OSError(err, 'Connect call failed %s' % (address,))\n",
      "ConnectionRefusedError: [Errno 111] Connect call failed ('192.168.130.119', 6379)\n",
      "Error subscribing to redis changes. Waiting before trying again\n",
      "Traceback (most recent call last):\n",
      "  File \"/usr/local/lib/python3.6/site-packages/guillotina_rediscache/utility.py\", line 34, in initialize\n",
      "    res = await self._redis.subscribe(settings['updates_channel'])\n",
      "  File \"/usr/local/lib/python3.6/site-packages/aioredis/commands/pubsub.py\", line 107, in wait_return_channels\n",
      "    res = await fut\n",
      "  File \"/usr/local/lib/python3.6/site-packages/aioredis/pool.py\", line 276, in _wait_execute_pubsub\n",
      "    conn = await self._create_new_connection(address)\n",
      "  File \"/usr/local/lib/python3.6/site-packages/aioredis/connection.py\", line 108, in create_connection\n",
      "    timeout, loop=loop)\n",
      "  File \"/usr/local/lib/python3.6/asyncio/tasks.py\", line 339, in wait_for\n",
      "    return (yield from fut)\n",
      "  File \"/usr/local/lib/python3.6/site-packages/aioredis/stream.py\", line 19, in open_connection\n",
      "    lambda: protocol, host, port, **kwds)\n",
      "  File \"/usr/local/lib/python3.6/asyncio/base_events.py\", line 778, in create_connection\n",
      "    raise exceptions[0]\n",
      "  File \"/usr/local/lib/python3.6/asyncio/base_events.py\", line 765, in create_connection\n",
      "    yield from self.sock_connect(sock, address)\n",
      "  File \"/usr/local/lib/python3.6/asyncio/selector_events.py\", line 450, in sock_connect\n",
      "    return (yield from fut)\n",
      "  File \"/usr/local/lib/python3.6/asyncio/selector_events.py\", line 480, in _sock_connect_cb\n",
      "    raise OSError(err, 'Connect call failed %s' % (address,))\n",
      "ConnectionRefusedError: [Errno 111] Connect call failed ('192.168.130.119', 6379)\n"
     ]
    },
    {
     "name": "stderr",
     "output_type": "stream",
     "text": [
      "Error subscribing to redis changes. Waiting before trying again\n",
      "Traceback (most recent call last):\n",
      "  File \"/usr/local/lib/python3.6/site-packages/guillotina_rediscache/utility.py\", line 34, in initialize\n",
      "    res = await self._redis.subscribe(settings['updates_channel'])\n",
      "  File \"/usr/local/lib/python3.6/site-packages/aioredis/commands/pubsub.py\", line 107, in wait_return_channels\n",
      "    res = await fut\n",
      "  File \"/usr/local/lib/python3.6/site-packages/aioredis/pool.py\", line 276, in _wait_execute_pubsub\n",
      "    conn = await self._create_new_connection(address)\n",
      "  File \"/usr/local/lib/python3.6/site-packages/aioredis/connection.py\", line 108, in create_connection\n",
      "    timeout, loop=loop)\n",
      "  File \"/usr/local/lib/python3.6/asyncio/tasks.py\", line 339, in wait_for\n",
      "    return (yield from fut)\n",
      "  File \"/usr/local/lib/python3.6/site-packages/aioredis/stream.py\", line 19, in open_connection\n",
      "    lambda: protocol, host, port, **kwds)\n",
      "  File \"/usr/local/lib/python3.6/asyncio/base_events.py\", line 778, in create_connection\n",
      "    raise exceptions[0]\n",
      "  File \"/usr/local/lib/python3.6/asyncio/base_events.py\", line 765, in create_connection\n",
      "    yield from self.sock_connect(sock, address)\n",
      "  File \"/usr/local/lib/python3.6/asyncio/selector_events.py\", line 450, in sock_connect\n",
      "    return (yield from fut)\n",
      "  File \"/usr/local/lib/python3.6/asyncio/selector_events.py\", line 480, in _sock_connect_cb\n",
      "    raise OSError(err, 'Connect call failed %s' % (address,))\n",
      "ConnectionRefusedError: [Errno 111] Connect call failed ('192.168.130.119', 6379)\n",
      "Error subscribing to redis changes. Waiting before trying again\n",
      "Traceback (most recent call last):\n",
      "  File \"/usr/local/lib/python3.6/site-packages/guillotina_rediscache/utility.py\", line 34, in initialize\n",
      "    res = await self._redis.subscribe(settings['updates_channel'])\n",
      "  File \"/usr/local/lib/python3.6/site-packages/aioredis/commands/pubsub.py\", line 107, in wait_return_channels\n",
      "    res = await fut\n",
      "  File \"/usr/local/lib/python3.6/site-packages/aioredis/pool.py\", line 276, in _wait_execute_pubsub\n",
      "    conn = await self._create_new_connection(address)\n",
      "  File \"/usr/local/lib/python3.6/site-packages/aioredis/connection.py\", line 108, in create_connection\n",
      "    timeout, loop=loop)\n",
      "  File \"/usr/local/lib/python3.6/asyncio/tasks.py\", line 339, in wait_for\n",
      "    return (yield from fut)\n",
      "  File \"/usr/local/lib/python3.6/site-packages/aioredis/stream.py\", line 19, in open_connection\n",
      "    lambda: protocol, host, port, **kwds)\n",
      "  File \"/usr/local/lib/python3.6/asyncio/base_events.py\", line 778, in create_connection\n",
      "    raise exceptions[0]\n",
      "  File \"/usr/local/lib/python3.6/asyncio/base_events.py\", line 765, in create_connection\n",
      "    yield from self.sock_connect(sock, address)\n",
      "  File \"/usr/local/lib/python3.6/asyncio/selector_events.py\", line 450, in sock_connect\n",
      "    return (yield from fut)\n",
      "  File \"/usr/local/lib/python3.6/asyncio/selector_events.py\", line 480, in _sock_connect_cb\n",
      "    raise OSError(err, 'Connect call failed %s' % (address,))\n",
      "ConnectionRefusedError: [Errno 111] Connect call failed ('192.168.130.119', 6379)\n",
      "Error subscribing to redis changes. Waiting before trying again\n",
      "Traceback (most recent call last):\n",
      "  File \"/usr/local/lib/python3.6/site-packages/guillotina_rediscache/utility.py\", line 34, in initialize\n",
      "    res = await self._redis.subscribe(settings['updates_channel'])\n",
      "  File \"/usr/local/lib/python3.6/site-packages/aioredis/commands/pubsub.py\", line 107, in wait_return_channels\n",
      "    res = await fut\n",
      "  File \"/usr/local/lib/python3.6/site-packages/aioredis/pool.py\", line 276, in _wait_execute_pubsub\n",
      "    conn = await self._create_new_connection(address)\n",
      "  File \"/usr/local/lib/python3.6/site-packages/aioredis/connection.py\", line 108, in create_connection\n",
      "    timeout, loop=loop)\n",
      "  File \"/usr/local/lib/python3.6/asyncio/tasks.py\", line 339, in wait_for\n",
      "    return (yield from fut)\n",
      "  File \"/usr/local/lib/python3.6/site-packages/aioredis/stream.py\", line 19, in open_connection\n",
      "    lambda: protocol, host, port, **kwds)\n",
      "  File \"/usr/local/lib/python3.6/asyncio/base_events.py\", line 778, in create_connection\n",
      "    raise exceptions[0]\n",
      "  File \"/usr/local/lib/python3.6/asyncio/base_events.py\", line 765, in create_connection\n",
      "    yield from self.sock_connect(sock, address)\n",
      "  File \"/usr/local/lib/python3.6/asyncio/selector_events.py\", line 450, in sock_connect\n",
      "    return (yield from fut)\n",
      "  File \"/usr/local/lib/python3.6/asyncio/selector_events.py\", line 480, in _sock_connect_cb\n",
      "    raise OSError(err, 'Connect call failed %s' % (address,))\n",
      "ConnectionRefusedError: [Errno 111] Connect call failed ('192.168.130.119', 6379)\n",
      "Error subscribing to redis changes. Waiting before trying again\n",
      "Traceback (most recent call last):\n",
      "  File \"/usr/local/lib/python3.6/site-packages/guillotina_rediscache/utility.py\", line 34, in initialize\n",
      "    res = await self._redis.subscribe(settings['updates_channel'])\n",
      "  File \"/usr/local/lib/python3.6/site-packages/aioredis/commands/pubsub.py\", line 107, in wait_return_channels\n",
      "    res = await fut\n",
      "  File \"/usr/local/lib/python3.6/site-packages/aioredis/pool.py\", line 276, in _wait_execute_pubsub\n",
      "    conn = await self._create_new_connection(address)\n",
      "  File \"/usr/local/lib/python3.6/site-packages/aioredis/connection.py\", line 108, in create_connection\n",
      "    timeout, loop=loop)\n",
      "  File \"/usr/local/lib/python3.6/asyncio/tasks.py\", line 339, in wait_for\n",
      "    return (yield from fut)\n",
      "  File \"/usr/local/lib/python3.6/site-packages/aioredis/stream.py\", line 19, in open_connection\n",
      "    lambda: protocol, host, port, **kwds)\n",
      "  File \"/usr/local/lib/python3.6/asyncio/base_events.py\", line 778, in create_connection\n",
      "    raise exceptions[0]\n",
      "  File \"/usr/local/lib/python3.6/asyncio/base_events.py\", line 765, in create_connection\n",
      "    yield from self.sock_connect(sock, address)\n",
      "  File \"/usr/local/lib/python3.6/asyncio/selector_events.py\", line 450, in sock_connect\n",
      "    return (yield from fut)\n",
      "  File \"/usr/local/lib/python3.6/asyncio/selector_events.py\", line 480, in _sock_connect_cb\n",
      "    raise OSError(err, 'Connect call failed %s' % (address,))\n",
      "ConnectionRefusedError: [Errno 111] Connect call failed ('192.168.130.119', 6379)\n",
      "Error subscribing to redis changes. Waiting before trying again\n",
      "Traceback (most recent call last):\n",
      "  File \"/usr/local/lib/python3.6/site-packages/guillotina_rediscache/utility.py\", line 34, in initialize\n",
      "    res = await self._redis.subscribe(settings['updates_channel'])\n",
      "  File \"/usr/local/lib/python3.6/site-packages/aioredis/commands/pubsub.py\", line 107, in wait_return_channels\n",
      "    res = await fut\n",
      "  File \"/usr/local/lib/python3.6/site-packages/aioredis/pool.py\", line 276, in _wait_execute_pubsub\n",
      "    conn = await self._create_new_connection(address)\n",
      "  File \"/usr/local/lib/python3.6/site-packages/aioredis/connection.py\", line 108, in create_connection\n",
      "    timeout, loop=loop)\n",
      "  File \"/usr/local/lib/python3.6/asyncio/tasks.py\", line 339, in wait_for\n",
      "    return (yield from fut)\n",
      "  File \"/usr/local/lib/python3.6/site-packages/aioredis/stream.py\", line 19, in open_connection\n",
      "    lambda: protocol, host, port, **kwds)\n",
      "  File \"/usr/local/lib/python3.6/asyncio/base_events.py\", line 778, in create_connection\n",
      "    raise exceptions[0]\n",
      "  File \"/usr/local/lib/python3.6/asyncio/base_events.py\", line 765, in create_connection\n",
      "    yield from self.sock_connect(sock, address)\n",
      "  File \"/usr/local/lib/python3.6/asyncio/selector_events.py\", line 450, in sock_connect\n",
      "    return (yield from fut)\n",
      "  File \"/usr/local/lib/python3.6/asyncio/selector_events.py\", line 480, in _sock_connect_cb\n",
      "    raise OSError(err, 'Connect call failed %s' % (address,))\n",
      "ConnectionRefusedError: [Errno 111] Connect call failed ('192.168.130.119', 6379)\n",
      "Error subscribing to redis changes. Waiting before trying again\n",
      "Traceback (most recent call last):\n",
      "  File \"/usr/local/lib/python3.6/site-packages/guillotina_rediscache/utility.py\", line 34, in initialize\n",
      "    res = await self._redis.subscribe(settings['updates_channel'])\n",
      "  File \"/usr/local/lib/python3.6/site-packages/aioredis/commands/pubsub.py\", line 107, in wait_return_channels\n",
      "    res = await fut\n",
      "  File \"/usr/local/lib/python3.6/site-packages/aioredis/pool.py\", line 276, in _wait_execute_pubsub\n",
      "    conn = await self._create_new_connection(address)\n",
      "  File \"/usr/local/lib/python3.6/site-packages/aioredis/connection.py\", line 108, in create_connection\n",
      "    timeout, loop=loop)\n",
      "  File \"/usr/local/lib/python3.6/asyncio/tasks.py\", line 339, in wait_for\n",
      "    return (yield from fut)\n",
      "  File \"/usr/local/lib/python3.6/site-packages/aioredis/stream.py\", line 19, in open_connection\n",
      "    lambda: protocol, host, port, **kwds)\n",
      "  File \"/usr/local/lib/python3.6/asyncio/base_events.py\", line 778, in create_connection\n",
      "    raise exceptions[0]\n",
      "  File \"/usr/local/lib/python3.6/asyncio/base_events.py\", line 765, in create_connection\n",
      "    yield from self.sock_connect(sock, address)\n",
      "  File \"/usr/local/lib/python3.6/asyncio/selector_events.py\", line 450, in sock_connect\n",
      "    return (yield from fut)\n",
      "  File \"/usr/local/lib/python3.6/asyncio/selector_events.py\", line 480, in _sock_connect_cb\n",
      "    raise OSError(err, 'Connect call failed %s' % (address,))\n",
      "ConnectionRefusedError: [Errno 111] Connect call failed ('192.168.130.119', 6379)\n"
     ]
    },
    {
     "name": "stderr",
     "output_type": "stream",
     "text": [
      "Error subscribing to redis changes. Waiting before trying again\n",
      "Traceback (most recent call last):\n",
      "  File \"/usr/local/lib/python3.6/site-packages/guillotina_rediscache/utility.py\", line 34, in initialize\n",
      "    res = await self._redis.subscribe(settings['updates_channel'])\n",
      "  File \"/usr/local/lib/python3.6/site-packages/aioredis/commands/pubsub.py\", line 107, in wait_return_channels\n",
      "    res = await fut\n",
      "  File \"/usr/local/lib/python3.6/site-packages/aioredis/pool.py\", line 276, in _wait_execute_pubsub\n",
      "    conn = await self._create_new_connection(address)\n",
      "  File \"/usr/local/lib/python3.6/site-packages/aioredis/connection.py\", line 108, in create_connection\n",
      "    timeout, loop=loop)\n",
      "  File \"/usr/local/lib/python3.6/asyncio/tasks.py\", line 339, in wait_for\n",
      "    return (yield from fut)\n",
      "  File \"/usr/local/lib/python3.6/site-packages/aioredis/stream.py\", line 19, in open_connection\n",
      "    lambda: protocol, host, port, **kwds)\n",
      "  File \"/usr/local/lib/python3.6/asyncio/base_events.py\", line 778, in create_connection\n",
      "    raise exceptions[0]\n",
      "  File \"/usr/local/lib/python3.6/asyncio/base_events.py\", line 765, in create_connection\n",
      "    yield from self.sock_connect(sock, address)\n",
      "  File \"/usr/local/lib/python3.6/asyncio/selector_events.py\", line 450, in sock_connect\n",
      "    return (yield from fut)\n",
      "  File \"/usr/local/lib/python3.6/asyncio/selector_events.py\", line 480, in _sock_connect_cb\n",
      "    raise OSError(err, 'Connect call failed %s' % (address,))\n",
      "ConnectionRefusedError: [Errno 111] Connect call failed ('192.168.130.119', 6379)\n",
      "Error subscribing to redis changes. Waiting before trying again\n",
      "Traceback (most recent call last):\n",
      "  File \"/usr/local/lib/python3.6/site-packages/guillotina_rediscache/utility.py\", line 34, in initialize\n",
      "    res = await self._redis.subscribe(settings['updates_channel'])\n",
      "  File \"/usr/local/lib/python3.6/site-packages/aioredis/commands/pubsub.py\", line 107, in wait_return_channels\n",
      "    res = await fut\n",
      "  File \"/usr/local/lib/python3.6/site-packages/aioredis/pool.py\", line 276, in _wait_execute_pubsub\n",
      "    conn = await self._create_new_connection(address)\n",
      "  File \"/usr/local/lib/python3.6/site-packages/aioredis/connection.py\", line 108, in create_connection\n",
      "    timeout, loop=loop)\n",
      "  File \"/usr/local/lib/python3.6/asyncio/tasks.py\", line 339, in wait_for\n",
      "    return (yield from fut)\n",
      "  File \"/usr/local/lib/python3.6/site-packages/aioredis/stream.py\", line 19, in open_connection\n",
      "    lambda: protocol, host, port, **kwds)\n",
      "  File \"/usr/local/lib/python3.6/asyncio/base_events.py\", line 778, in create_connection\n",
      "    raise exceptions[0]\n",
      "  File \"/usr/local/lib/python3.6/asyncio/base_events.py\", line 765, in create_connection\n",
      "    yield from self.sock_connect(sock, address)\n",
      "  File \"/usr/local/lib/python3.6/asyncio/selector_events.py\", line 450, in sock_connect\n",
      "    return (yield from fut)\n",
      "  File \"/usr/local/lib/python3.6/asyncio/selector_events.py\", line 480, in _sock_connect_cb\n",
      "    raise OSError(err, 'Connect call failed %s' % (address,))\n",
      "ConnectionRefusedError: [Errno 111] Connect call failed ('192.168.130.119', 6379)\n",
      "Error subscribing to redis changes. Waiting before trying again\n",
      "Traceback (most recent call last):\n",
      "  File \"/usr/local/lib/python3.6/site-packages/guillotina_rediscache/utility.py\", line 34, in initialize\n",
      "    res = await self._redis.subscribe(settings['updates_channel'])\n",
      "  File \"/usr/local/lib/python3.6/site-packages/aioredis/commands/pubsub.py\", line 107, in wait_return_channels\n",
      "    res = await fut\n",
      "  File \"/usr/local/lib/python3.6/site-packages/aioredis/pool.py\", line 276, in _wait_execute_pubsub\n",
      "    conn = await self._create_new_connection(address)\n",
      "  File \"/usr/local/lib/python3.6/site-packages/aioredis/connection.py\", line 108, in create_connection\n",
      "    timeout, loop=loop)\n",
      "  File \"/usr/local/lib/python3.6/asyncio/tasks.py\", line 339, in wait_for\n",
      "    return (yield from fut)\n",
      "  File \"/usr/local/lib/python3.6/site-packages/aioredis/stream.py\", line 19, in open_connection\n",
      "    lambda: protocol, host, port, **kwds)\n",
      "  File \"/usr/local/lib/python3.6/asyncio/base_events.py\", line 778, in create_connection\n",
      "    raise exceptions[0]\n",
      "  File \"/usr/local/lib/python3.6/asyncio/base_events.py\", line 765, in create_connection\n",
      "    yield from self.sock_connect(sock, address)\n",
      "  File \"/usr/local/lib/python3.6/asyncio/selector_events.py\", line 450, in sock_connect\n",
      "    return (yield from fut)\n",
      "  File \"/usr/local/lib/python3.6/asyncio/selector_events.py\", line 480, in _sock_connect_cb\n",
      "    raise OSError(err, 'Connect call failed %s' % (address,))\n",
      "ConnectionRefusedError: [Errno 111] Connect call failed ('192.168.130.119', 6379)\n",
      "Error subscribing to redis changes. Waiting before trying again\n",
      "Traceback (most recent call last):\n",
      "  File \"/usr/local/lib/python3.6/site-packages/guillotina_rediscache/utility.py\", line 34, in initialize\n",
      "    res = await self._redis.subscribe(settings['updates_channel'])\n",
      "  File \"/usr/local/lib/python3.6/site-packages/aioredis/commands/pubsub.py\", line 107, in wait_return_channels\n",
      "    res = await fut\n",
      "  File \"/usr/local/lib/python3.6/site-packages/aioredis/pool.py\", line 276, in _wait_execute_pubsub\n",
      "    conn = await self._create_new_connection(address)\n",
      "  File \"/usr/local/lib/python3.6/site-packages/aioredis/connection.py\", line 108, in create_connection\n",
      "    timeout, loop=loop)\n",
      "  File \"/usr/local/lib/python3.6/asyncio/tasks.py\", line 339, in wait_for\n",
      "    return (yield from fut)\n",
      "  File \"/usr/local/lib/python3.6/site-packages/aioredis/stream.py\", line 19, in open_connection\n",
      "    lambda: protocol, host, port, **kwds)\n",
      "  File \"/usr/local/lib/python3.6/asyncio/base_events.py\", line 778, in create_connection\n",
      "    raise exceptions[0]\n",
      "  File \"/usr/local/lib/python3.6/asyncio/base_events.py\", line 765, in create_connection\n",
      "    yield from self.sock_connect(sock, address)\n",
      "  File \"/usr/local/lib/python3.6/asyncio/selector_events.py\", line 450, in sock_connect\n",
      "    return (yield from fut)\n",
      "  File \"/usr/local/lib/python3.6/asyncio/selector_events.py\", line 480, in _sock_connect_cb\n",
      "    raise OSError(err, 'Connect call failed %s' % (address,))\n",
      "ConnectionRefusedError: [Errno 111] Connect call failed ('192.168.130.119', 6379)\n",
      "Error subscribing to redis changes. Waiting before trying again\n",
      "Traceback (most recent call last):\n",
      "  File \"/usr/local/lib/python3.6/site-packages/guillotina_rediscache/utility.py\", line 34, in initialize\n",
      "    res = await self._redis.subscribe(settings['updates_channel'])\n",
      "  File \"/usr/local/lib/python3.6/site-packages/aioredis/commands/pubsub.py\", line 107, in wait_return_channels\n",
      "    res = await fut\n",
      "  File \"/usr/local/lib/python3.6/site-packages/aioredis/pool.py\", line 276, in _wait_execute_pubsub\n",
      "    conn = await self._create_new_connection(address)\n",
      "  File \"/usr/local/lib/python3.6/site-packages/aioredis/connection.py\", line 108, in create_connection\n",
      "    timeout, loop=loop)\n",
      "  File \"/usr/local/lib/python3.6/asyncio/tasks.py\", line 339, in wait_for\n",
      "    return (yield from fut)\n",
      "  File \"/usr/local/lib/python3.6/site-packages/aioredis/stream.py\", line 19, in open_connection\n",
      "    lambda: protocol, host, port, **kwds)\n",
      "  File \"/usr/local/lib/python3.6/asyncio/base_events.py\", line 778, in create_connection\n",
      "    raise exceptions[0]\n",
      "  File \"/usr/local/lib/python3.6/asyncio/base_events.py\", line 765, in create_connection\n",
      "    yield from self.sock_connect(sock, address)\n",
      "  File \"/usr/local/lib/python3.6/asyncio/selector_events.py\", line 450, in sock_connect\n",
      "    return (yield from fut)\n",
      "  File \"/usr/local/lib/python3.6/asyncio/selector_events.py\", line 480, in _sock_connect_cb\n",
      "    raise OSError(err, 'Connect call failed %s' % (address,))\n",
      "ConnectionRefusedError: [Errno 111] Connect call failed ('192.168.130.119', 6379)\n",
      "Error subscribing to redis changes. Waiting before trying again\n",
      "Traceback (most recent call last):\n",
      "  File \"/usr/local/lib/python3.6/site-packages/guillotina_rediscache/utility.py\", line 34, in initialize\n",
      "    res = await self._redis.subscribe(settings['updates_channel'])\n",
      "  File \"/usr/local/lib/python3.6/site-packages/aioredis/commands/pubsub.py\", line 107, in wait_return_channels\n",
      "    res = await fut\n",
      "  File \"/usr/local/lib/python3.6/site-packages/aioredis/pool.py\", line 276, in _wait_execute_pubsub\n",
      "    conn = await self._create_new_connection(address)\n",
      "  File \"/usr/local/lib/python3.6/site-packages/aioredis/connection.py\", line 108, in create_connection\n",
      "    timeout, loop=loop)\n",
      "  File \"/usr/local/lib/python3.6/asyncio/tasks.py\", line 339, in wait_for\n",
      "    return (yield from fut)\n",
      "  File \"/usr/local/lib/python3.6/site-packages/aioredis/stream.py\", line 19, in open_connection\n",
      "    lambda: protocol, host, port, **kwds)\n",
      "  File \"/usr/local/lib/python3.6/asyncio/base_events.py\", line 778, in create_connection\n",
      "    raise exceptions[0]\n",
      "  File \"/usr/local/lib/python3.6/asyncio/base_events.py\", line 765, in create_connection\n",
      "    yield from self.sock_connect(sock, address)\n",
      "  File \"/usr/local/lib/python3.6/asyncio/selector_events.py\", line 450, in sock_connect\n",
      "    return (yield from fut)\n",
      "  File \"/usr/local/lib/python3.6/asyncio/selector_events.py\", line 480, in _sock_connect_cb\n",
      "    raise OSError(err, 'Connect call failed %s' % (address,))\n",
      "ConnectionRefusedError: [Errno 111] Connect call failed ('192.168.130.119', 6379)\n"
     ]
    },
    {
     "name": "stderr",
     "output_type": "stream",
     "text": [
      "Error subscribing to redis changes. Waiting before trying again\n",
      "Traceback (most recent call last):\n",
      "  File \"/usr/local/lib/python3.6/site-packages/guillotina_rediscache/utility.py\", line 34, in initialize\n",
      "    res = await self._redis.subscribe(settings['updates_channel'])\n",
      "  File \"/usr/local/lib/python3.6/site-packages/aioredis/commands/pubsub.py\", line 107, in wait_return_channels\n",
      "    res = await fut\n",
      "  File \"/usr/local/lib/python3.6/site-packages/aioredis/pool.py\", line 276, in _wait_execute_pubsub\n",
      "    conn = await self._create_new_connection(address)\n",
      "  File \"/usr/local/lib/python3.6/site-packages/aioredis/connection.py\", line 108, in create_connection\n",
      "    timeout, loop=loop)\n",
      "  File \"/usr/local/lib/python3.6/asyncio/tasks.py\", line 339, in wait_for\n",
      "    return (yield from fut)\n",
      "  File \"/usr/local/lib/python3.6/site-packages/aioredis/stream.py\", line 19, in open_connection\n",
      "    lambda: protocol, host, port, **kwds)\n",
      "  File \"/usr/local/lib/python3.6/asyncio/base_events.py\", line 778, in create_connection\n",
      "    raise exceptions[0]\n",
      "  File \"/usr/local/lib/python3.6/asyncio/base_events.py\", line 765, in create_connection\n",
      "    yield from self.sock_connect(sock, address)\n",
      "  File \"/usr/local/lib/python3.6/asyncio/selector_events.py\", line 450, in sock_connect\n",
      "    return (yield from fut)\n",
      "  File \"/usr/local/lib/python3.6/asyncio/selector_events.py\", line 480, in _sock_connect_cb\n",
      "    raise OSError(err, 'Connect call failed %s' % (address,))\n",
      "ConnectionRefusedError: [Errno 111] Connect call failed ('192.168.130.119', 6379)\n",
      "Error subscribing to redis changes. Waiting before trying again\n",
      "Traceback (most recent call last):\n",
      "  File \"/usr/local/lib/python3.6/site-packages/guillotina_rediscache/utility.py\", line 34, in initialize\n",
      "    res = await self._redis.subscribe(settings['updates_channel'])\n",
      "  File \"/usr/local/lib/python3.6/site-packages/aioredis/commands/pubsub.py\", line 107, in wait_return_channels\n",
      "    res = await fut\n",
      "  File \"/usr/local/lib/python3.6/site-packages/aioredis/pool.py\", line 276, in _wait_execute_pubsub\n",
      "    conn = await self._create_new_connection(address)\n",
      "  File \"/usr/local/lib/python3.6/site-packages/aioredis/connection.py\", line 108, in create_connection\n",
      "    timeout, loop=loop)\n",
      "  File \"/usr/local/lib/python3.6/asyncio/tasks.py\", line 339, in wait_for\n",
      "    return (yield from fut)\n",
      "  File \"/usr/local/lib/python3.6/site-packages/aioredis/stream.py\", line 19, in open_connection\n",
      "    lambda: protocol, host, port, **kwds)\n",
      "  File \"/usr/local/lib/python3.6/asyncio/base_events.py\", line 778, in create_connection\n",
      "    raise exceptions[0]\n",
      "  File \"/usr/local/lib/python3.6/asyncio/base_events.py\", line 765, in create_connection\n",
      "    yield from self.sock_connect(sock, address)\n",
      "  File \"/usr/local/lib/python3.6/asyncio/selector_events.py\", line 450, in sock_connect\n",
      "    return (yield from fut)\n",
      "  File \"/usr/local/lib/python3.6/asyncio/selector_events.py\", line 480, in _sock_connect_cb\n",
      "    raise OSError(err, 'Connect call failed %s' % (address,))\n",
      "ConnectionRefusedError: [Errno 111] Connect call failed ('192.168.130.119', 6379)\n",
      "Error subscribing to redis changes. Waiting before trying again\n",
      "Traceback (most recent call last):\n",
      "  File \"/usr/local/lib/python3.6/site-packages/guillotina_rediscache/utility.py\", line 34, in initialize\n",
      "    res = await self._redis.subscribe(settings['updates_channel'])\n",
      "  File \"/usr/local/lib/python3.6/site-packages/aioredis/commands/pubsub.py\", line 107, in wait_return_channels\n",
      "    res = await fut\n",
      "  File \"/usr/local/lib/python3.6/site-packages/aioredis/pool.py\", line 276, in _wait_execute_pubsub\n",
      "    conn = await self._create_new_connection(address)\n",
      "  File \"/usr/local/lib/python3.6/site-packages/aioredis/connection.py\", line 108, in create_connection\n",
      "    timeout, loop=loop)\n",
      "  File \"/usr/local/lib/python3.6/asyncio/tasks.py\", line 339, in wait_for\n",
      "    return (yield from fut)\n",
      "  File \"/usr/local/lib/python3.6/site-packages/aioredis/stream.py\", line 19, in open_connection\n",
      "    lambda: protocol, host, port, **kwds)\n",
      "  File \"/usr/local/lib/python3.6/asyncio/base_events.py\", line 778, in create_connection\n",
      "    raise exceptions[0]\n",
      "  File \"/usr/local/lib/python3.6/asyncio/base_events.py\", line 765, in create_connection\n",
      "    yield from self.sock_connect(sock, address)\n",
      "  File \"/usr/local/lib/python3.6/asyncio/selector_events.py\", line 450, in sock_connect\n",
      "    return (yield from fut)\n",
      "  File \"/usr/local/lib/python3.6/asyncio/selector_events.py\", line 480, in _sock_connect_cb\n",
      "    raise OSError(err, 'Connect call failed %s' % (address,))\n",
      "ConnectionRefusedError: [Errno 111] Connect call failed ('192.168.130.119', 6379)\n",
      "Error subscribing to redis changes. Waiting before trying again\n",
      "Traceback (most recent call last):\n",
      "  File \"/usr/local/lib/python3.6/site-packages/guillotina_rediscache/utility.py\", line 34, in initialize\n",
      "    res = await self._redis.subscribe(settings['updates_channel'])\n",
      "  File \"/usr/local/lib/python3.6/site-packages/aioredis/commands/pubsub.py\", line 107, in wait_return_channels\n",
      "    res = await fut\n",
      "  File \"/usr/local/lib/python3.6/site-packages/aioredis/pool.py\", line 276, in _wait_execute_pubsub\n",
      "    conn = await self._create_new_connection(address)\n",
      "  File \"/usr/local/lib/python3.6/site-packages/aioredis/connection.py\", line 108, in create_connection\n",
      "    timeout, loop=loop)\n",
      "  File \"/usr/local/lib/python3.6/asyncio/tasks.py\", line 339, in wait_for\n",
      "    return (yield from fut)\n",
      "  File \"/usr/local/lib/python3.6/site-packages/aioredis/stream.py\", line 19, in open_connection\n",
      "    lambda: protocol, host, port, **kwds)\n",
      "  File \"/usr/local/lib/python3.6/asyncio/base_events.py\", line 778, in create_connection\n",
      "    raise exceptions[0]\n",
      "  File \"/usr/local/lib/python3.6/asyncio/base_events.py\", line 765, in create_connection\n",
      "    yield from self.sock_connect(sock, address)\n",
      "  File \"/usr/local/lib/python3.6/asyncio/selector_events.py\", line 450, in sock_connect\n",
      "    return (yield from fut)\n",
      "  File \"/usr/local/lib/python3.6/asyncio/selector_events.py\", line 480, in _sock_connect_cb\n",
      "    raise OSError(err, 'Connect call failed %s' % (address,))\n",
      "ConnectionRefusedError: [Errno 111] Connect call failed ('192.168.130.119', 6379)\n",
      "Error subscribing to redis changes. Waiting before trying again\n",
      "Traceback (most recent call last):\n",
      "  File \"/usr/local/lib/python3.6/site-packages/guillotina_rediscache/utility.py\", line 34, in initialize\n",
      "    res = await self._redis.subscribe(settings['updates_channel'])\n",
      "  File \"/usr/local/lib/python3.6/site-packages/aioredis/commands/pubsub.py\", line 107, in wait_return_channels\n",
      "    res = await fut\n",
      "  File \"/usr/local/lib/python3.6/site-packages/aioredis/pool.py\", line 276, in _wait_execute_pubsub\n",
      "    conn = await self._create_new_connection(address)\n",
      "  File \"/usr/local/lib/python3.6/site-packages/aioredis/connection.py\", line 108, in create_connection\n",
      "    timeout, loop=loop)\n",
      "  File \"/usr/local/lib/python3.6/asyncio/tasks.py\", line 339, in wait_for\n",
      "    return (yield from fut)\n",
      "  File \"/usr/local/lib/python3.6/site-packages/aioredis/stream.py\", line 19, in open_connection\n",
      "    lambda: protocol, host, port, **kwds)\n",
      "  File \"/usr/local/lib/python3.6/asyncio/base_events.py\", line 778, in create_connection\n",
      "    raise exceptions[0]\n",
      "  File \"/usr/local/lib/python3.6/asyncio/base_events.py\", line 765, in create_connection\n",
      "    yield from self.sock_connect(sock, address)\n",
      "  File \"/usr/local/lib/python3.6/asyncio/selector_events.py\", line 450, in sock_connect\n",
      "    return (yield from fut)\n",
      "  File \"/usr/local/lib/python3.6/asyncio/selector_events.py\", line 480, in _sock_connect_cb\n",
      "    raise OSError(err, 'Connect call failed %s' % (address,))\n",
      "ConnectionRefusedError: [Errno 111] Connect call failed ('192.168.130.119', 6379)\n"
     ]
    }
   ],
   "source": [
    "from guillotina_processing.utils import cleanup_text\n",
    "vector = [vocabulary.dictionary.get(word,2) for word in cleanup_text(sports_content)]\n",
    "vector2 = [vocabulary.dictionary.get(word,2) for word in cleanup_text(news_content)]\n",
    "vector3 = [vocabulary.dictionary.get(word,0) for word in cleanup_text(news2_content)]\n",
    "\n",
    "prediction = model.predict(np.array(vector))\n",
    "print('sports_content is: %s' % labels[np.argmax(prediction[0])])\n",
    "\n",
    "prediction = model.predict(np.array(vector2))\n",
    "print('news_content is: %s' % labels[np.argmax(prediction[0])])\n",
    "\n",
    "prediction = model.predict(np.array(vector3))\n",
    "print('news2_content is: %s' % labels[np.argmax(prediction[0])])\n"
   ]
  },
  {
   "cell_type": "code",
   "execution_count": null,
   "metadata": {},
   "outputs": [],
   "source": []
  }
 ],
 "metadata": {
  "kernelspec": {
   "display_name": "Python 3",
   "language": "python",
   "name": "python3"
  },
  "language_info": {
   "codemirror_mode": {
    "name": "ipython",
    "version": 3
   },
   "file_extension": ".py",
   "mimetype": "text/x-python",
   "name": "python",
   "nbconvert_exporter": "python",
   "pygments_lexer": "ipython3",
   "version": "3.6.6"
  }
 },
 "nbformat": 4,
 "nbformat_minor": 2
}
